Workbook

Sheet Выход ТС
A1: Префикс | B1: Название типа | C1: План | D1: Факт | E1: Откл | F1: Всего день | G1: Всего ночь | H1: ЦДН-1 | J1: ЦДН-2 | L1: ЦДН-3 | N1: ЦППН | P1: ЦППД | R1: ЭЦ | T1: ОКС | V1: РСЦ | X1: ЦИТС | Z1: ПРЦЭО | AB1: ГЦ | AD1: ЦПП | AF1: БМТС | AH1: ЦПКРС-1 | AJ1: ЦПКРС-2 | AL1: Гараж-1 | AN1: ЦНИПР | AP1: ОБиПКРС | AR1: ЦАП | AT1: ГООС | AV1: Бурение | AX1: ЦТВС | AZ1: ТБ | BB1: ОТДН | BD1: БД | BF1: ОГиР | BH1: ГСРиВК | BJ1: ЛД | BL1: Отделкадр | BN1: УЖЭО | BP1: ГАПиИТ | BR1: ОМ | BT1: ПСО | BV1: ЦТТ | BX1: ЧАКУР мед | BZ1: СМУ УТТ | CB1: СБ | CD1: УПТОК | CF1: БПО | CH1: ГУ | CJ1: МГС | CL1: РМУ | CN1: IR | CP1: ПЧ
H2: День | I2: Ночь | J2: День | K2: Ночь | L2: День | M2: Ночь | N2: День | O2: Ночь | P2: День | Q2: Ночь | R2: День | S2: Ночь | T2: День | U2: Ночь | V2: День | W2: Ночь | X2: День | Y2: Ночь | Z2: День | AA2: Ночь | AB2: День | AC2: Ночь | AD2: День | AE2: Ночь | AF2: День | AG2: Ночь | AH2: День | AI2: Ночь | AJ2: День | AK2: Ночь | AL2: День | AM2: Ночь | AN2: День | AO2: Ночь | AP2: День | AQ2: Ночь | AR2: День | AS2: Ночь | AT2: День | AU2: Ночь | AV2: День | AW2: Ночь | AX2: День | AY2: Ночь | AZ2: День | BA2: Ночь | BB2: День | BC2: Ночь | BD2: День | BE2: Ночь | BF2: День | BG2: Ночь | BH2: День | BI2: Ночь | BJ2: День | BK2: Ночь | BL2: День | BM2: Ночь | BN2: День | BO2: Ночь | BP2: День | BQ2: Ночь | BR2: День | BS2: Ночь | BT2: День | BU2: Ночь | BV2: День | BW2: Ночь | BX2: День | BY2: Ночь | BZ2: День | CA2: Ночь | CB2: День | CC2: Ночь | CD2: День | CE2: Ночь | CF2: День | CG2: Ночь | CH2: День | CI2: Ночь | CJ2: День | CK2: Ночь | CL2: День | CM2: Ночь | CN2: День | CO2: Ночь | CP2: День | CQ2: Ночь
A3: 34 | B3: ППУА | C3: 29 | D3: =F3+G3 -> 25 | E3: =D3-C3 -> -4 | F3: =SUMIFS($H3:$CQ3,$H$2:$CQ$2,"День") -> 18 | G3: =SUMIFS($H3:$CQ3,$H$2:$CQ$2,"Ночь") -> 7 | H3: =SUMIFS('Исходные данные'!$I$2:$I$966,'Исходные данные'!$D$2:$D$966,H$1,'Исходные данные'!$F$2:$F$966,$A3) -> 3 | I3: =SUMIFS('Исходные данные'!$J$2:$J$966,'Исходные данные'!$D$2:$D$966,H$1,'Исходные данные'!$F$2:$F$966,$A3) -> 1 | J3: =SUMIFS('Исходные данные'!$I$2:$I$966,'Исходные данные'!$D$2:$D$966,J$1,'Исходные данные'!$F$2:$F$966,$A3) -> 3 | K3: =SUMIFS('Исходные данные'!$J$2:$J$966,'Исходные данные'!$D$2:$D$966,J$1,'Исходные данные'!$F$2:$F$966,$A3) -> 0 | L3: =SUMIFS('Исходные данные'!$I$2:$I$966,'Исходные данные'!$D$2:$D$966,L$1,'Исходные данные'!$F$2:$F$966,$A3) -> 3 | M3: =SUMIFS('Исходные данные'!$J$2:$J$966,'Исходные данные'!$D$2:$D$966,L$1,'Исходные данные'!$F$2:$F$966,$A3) -> 0 | N3: =SUMIFS('Исходные данные'!$I$2:$I$966,'Исходные данные'!$D$2:$D$966,N$1,'Исходные данные'!$F$2:$F$966,$A3) -> 0 | O3: =SUMIFS('Исходные данные'!$J$2:$J$966,'Исходные данные'!$D$2:$D$966,N$1,'Исходные данные'!$F$2:$F$966,$A3) -> 0 | P3: =SUMIFS('Исходные данные'!$I$2:$I$966,'Исходные данные'!$D$2:$D$966,P$1,'Исходные данные'!$F$2:$F$966,$A3) -> 0 | Q3: =SUMIFS('Исходные данные'!$J$2:$J$966,'Исходные данные'!$D$2:$D$966,P$1,'Исходные данные'!$F$2:$F$966,$A3) -> 0 | R3: =SUMIFS('Исходные данные'!$I$2:$I$966,'Исходные данные'!$D$2:$D$966,R$1,'Исходные данные'!$F$2:$F$966,$A3) -> 0 | S3: =SUMIFS('Исходные данные'!$J$2:$J$966,'Исходные данные'!$D$2:$D$966,R$1,'Исходные данные'!$F$2:$F$966,$A3) -> 0 | T3: =SUMIFS('Исходные данные'!$I$2:$I$966,'Исходные данные'!$D$2:$D$966,T$1,'Исходные данные'!$F$2:$F$966,$A3) -> 0 | U3: =SUMIFS('Исходные данные'!$J$2:$J$966,'Исходные данные'!$D$2:$D$966,T$1,'Исходные данные'!$F$2:$F$966,$A3) -> 0 | V3: =SUMIFS('Исходные данные'!$I$2:$I$966,'Исходные данные'!$D$2:$D$966,V$1,'Исходные данные'!$F$2:$F$966,$A3) -> 0 | W3: =SUMIFS('Исходные данные'!$J$2:$J$966,'Исходные данные'!$D$2:$D$966,V$1,'Исходные данные'!$F$2:$F$966,$A3) -> 0 | X3: =SUMIFS('Исходные данные'!$I$2:$I$966,'Исходные данные'!$D$2:$D$966,X$1,'Исходные данные'!$F$2:$F$966,$A3) -> 0 | Y3: =SUMIFS('Исходные данные'!$J$2:$J$966,'Исходные данные'!$D$2:$D$966,X$1,'Исходные данные'!$F$2:$F$966,$A3) -> 0 | Z3: =SUMIFS('Исходные данные'!$I$2:$I$966,'Исходные данные'!$D$2:$D$966,Z$1,'Исходные данные'!$F$2:$F$966,$A3) -> 0 | AA3: =SUMIFS('Исходные данные'!$J$2:$J$966,'Исходные данные'!$D$2:$D$966,Z$1,'Исходные данные'!$F$2:$F$966,$A3) -> 0 | AB3: =SUMIFS('Исходные данные'!$I$2:$I$966,'Исходные данные'!$D$2:$D$966,AB$1,'Исходные данные'!$F$2:$F$966,$A3) -> 0 | AC3: =SUMIFS('Исходные данные'!$J$2:$J$966,'Исходные данные'!$D$2:$D$966,AB$1,'Исходные данные'!$F$2:$F$966,$A3) -> 0 | AD3: =SUMIFS('Исходные данные'!$I$2:$I$966,'Исходные данные'!$D$2:$D$966,AD$1,'Исходные данные'!$F$2:$F$966,$A3) -> 0 | AE3: =SUMIFS('Исходные данные'!$J$2:$J$966,'Исходные данные'!$D$2:$D$966,AD$1,'Исходные данные'!$F$2:$F$966,$A3) -> 0 | AF3: =SUMIFS('Исходные данные'!$I$2:$I$966,'Исходные данные'!$D$2:$D$966,AF$1,'Исходные данные'!$F$2:$F$966,$A3) -> 0 | AG3: =SUMIFS('Исходные данные'!$J$2:$J$966,'Исходные данные'!$D$2:$D$966,AF$1,'Исходные данные'!$F$2:$F$966,$A3) -> 0 | AH3: =SUMIFS('Исходные данные'!$I$2:$I$966,'Исходные данные'!$D$2:$D$966,AH$1,'Исходные данные'!$F$2:$F$966,$A3) -> 5 | AI3: =SUMIFS('Исходные данные'!$J$2:$J$966,'Исходные данные'!$D$2:$D$966,AH$1,'Исходные данные'!$F$2:$F$966,$A3) -> 3 | AJ3: =SUMIFS('Исходные данные'!$I$2:$I$966,'Исходные данные'!$D$2:$D$966,AJ$1,'Исходные данные'!$F$2:$F$966,$A3) -> 4 | AK3: =SUMIFS('Исходные данные'!$J$2:$J$966,'Исходные данные'!$D$2:$D$966,AJ$1,'Исходные данные'!$F$2:$F$966,$A3) -> 3 | AL3: =SUMIFS('Исходные данные'!$I$2:$I$966,'Исходные данные'!$D$2:$D$966,AL$1,'Исходные данные'!$F$2:$F$966,$A3) -> 0 | AM3: =SUMIFS('Исходные данные'!$J$2:$J$966,'Исходные данные'!$D$2:$D$966,AL$1,'Исходные данные'!$F$2:$F$966,$A3) -> 0 | AN3: =SUMIFS('Исходные данные'!$I$2:$I$966,'Исходные данные'!$D$2:$D$966,AN$1,'Исходные данные'!$F$2:$F$966,$A3) -> 0 | AO3: =SUMIFS('Исходные данные'!$J$2:$J$966,'Исходные данные'!$D$2:$D$966,AN$1,'Исходные данные'!$F$2:$F$966,$A3) -> 0 | AP3: =SUMIFS('Исходные данные'!$I$2:$I$966,'Исходные данные'!$D$2:$D$966,AP$1,'Исходные данные'!$F$2:$F$966,$A3) -> 0 | AQ3: =SUMIFS('Исходные данные'!$J$2:$J$966,'Исходные данные'!$D$2:$D$966,AP$1,'Исходные данные'!$F$2:$F$966,$A3) -> 0 | AR3: =SUMIFS('Исходные данные'!$I$2:$I$966,'Исходные данные'!$D$2:$D$966,AR$1,'Исходные данные'!$F$2:$F$966,$A3) -> 0 | AS3: =SUMIFS('Исходные данные'!$J$2:$J$966,'Исходные данные'!$D$2:$D$966,AR$1,'Исходные данные'!$F$2:$F$966,$A3) -> 0 | AT3: =SUMIFS('Исходные данные'!$I$2:$I$966,'Исходные данные'!$D$2:$D$966,AT$1,'Исходные данные'!$F$2:$F$966,$A3) -> 0 | AU3: =SUMIFS('Исходные данные'!$J$2:$J$966,'Исходные данные'!$D$2:$D$966,AT$1,'Исходные данные'!$F$2:$F$966,$A3) -> 0 | AV3: =SUMIFS('Исходные данные'!$I$2:$I$966,'Исходные данные'!$D$2:$D$966,AV$1,'Исходные данные'!$F$2:$F$966,$A3) -> 0 | AW3: =SUMIFS('Исходные данные'!$J$2:$J$966,'Исходные данные'!$D$2:$D$966,AV$1,'Исходные данные'!$F$2:$F$966,$A3) -> 0 | AX3: =SUMIFS('Исходные данные'!$I$2:$I$966,'Исходные данные'!$D$2:$D$966,AX$1,'Исходные данные'!$F$2:$F$966,$A3) -> 0 | AY3: =SUMIFS('Исходные данные'!$J$2:$J$966,'Исходные данные'!$D$2:$D$966,AX$1,'Исходные данные'!$F$2:$F$966,$A3) -> 0 | AZ3: =SUMIFS('Исходные данные'!$I$2:$I$966,'Исходные данные'!$D$2:$D$966,AZ$1,'Исходные данные'!$F$2:$F$966,$A3) -> 0 | BA3: =SUMIFS('Исходные данные'!$J$2:$J$966,'Исходные данные'!$D$2:$D$966,AZ$1,'Исходные данные'!$F$2:$F$966,$A3) -> 0 | BB3: =SUMIFS('Исходные данные'!$I$2:$I$966,'Исходные данные'!$D$2:$D$966,BB$1,'Исходные данные'!$F$2:$F$966,$A3) -> 0 | BC3: =SUMIFS('Исходные данные'!$J$2:$J$966,'Исходные данные'!$D$2:$D$966,BB$1,'Исходные данные'!$F$2:$F$966,$A3) -> 0 | BD3: =SUMIFS('Исходные данные'!$I$2:$I$966,'Исходные данные'!$D$2:$D$966,BD$1,'Исходные данные'!$F$2:$F$966,$A3) -> 0 | BE3: =SUMIFS('Исходные данные'!$J$2:$J$966,'Исходные данные'!$D$2:$D$966,BD$1,'Исходные данные'!$F$2:$F$966,$A3) -> 0 | BF3: =SUMIFS('Исходные данные'!$I$2:$I$966,'Исходные данные'!$D$2:$D$966,BF$1,'Исходные данные'!$F$2:$F$966,$A3) -> 0 | BG3: =SUMIFS('Исходные данные'!$J$2:$J$966,'Исходные данные'!$D$2:$D$966,BF$1,'Исходные данные'!$F$2:$F$966,$A3) -> 0 | BH3: =SUMIFS('Исходные данные'!$I$2:$I$966,'Исходные данные'!$D$2:$D$966,BH$1,'Исходные данные'!$F$2:$F$966,$A3) -> 0 | BI3: =SUMIFS('Исходные данные'!$J$2:$J$966,'Исходные данные'!$D$2:$D$966,BH$1,'Исходные данные'!$F$2:$F$966,$A3) -> 0 | BJ3: =SUMIFS('Исходные данные'!$I$2:$I$966,'Исходные данные'!$D$2:$D$966,BJ$1,'Исходные данные'!$F$2:$F$966,$A3) -> 0 | BK3: =SUMIFS('Исходные данные'!$J$2:$J$966,'Исходные данные'!$D$2:$D$966,BJ$1,'Исходные данные'!$F$2:$F$966,$A3) -> 0 | BL3: =SUMIFS('Исходные данные'!$I$2:$I$966,'Исходные данные'!$D$2:$D$966,BL$1,'Исходные данные'!$F$2:$F$966,$A3) -> 0 | BM3: =SUMIFS('Исходные данные'!$J$2:$J$966,'Исходные данные'!$D$2:$D$966,BL$1,'Исходные данные'!$F$2:$F$966,$A3) -> 0 | BN3: =SUMIFS('Исходные данные'!$I$2:$I$966,'Исходные данные'!$D$2:$D$966,BN$1,'Исходные данные'!$F$2:$F$966,$A3) -> 0 | BO3: =SUMIFS('Исходные данные'!$J$2:$J$966,'Исходные данные'!$D$2:$D$966,BN$1,'Исходные данные'!$F$2:$F$966,$A3) -> 0 | BP3: =SUMIFS('Исходные данные'!$I$2:$I$966,'Исходные данные'!$D$2:$D$966,BP$1,'Исходные данные'!$F$2:$F$966,$A3) -> 0 | BQ3: =SUMIFS('Исходные данные'!$J$2:$J$966,'Исходные данные'!$D$2:$D$966,BP$1,'Исходные данные'!$F$2:$F$966,$A3) -> 0 | BR3: =SUMIFS('Исходные данные'!$I$2:$I$966,'Исходные данные'!$D$2:$D$966,BR$1,'Исходные данные'!$F$2:$F$966,$A3) -> 0 | BS3: =SUMIFS('Исходные данные'!$J$2:$J$966,'Исходные данные'!$D$2:$D$966,BR$1,'Исходные данные'!$F$2:$F$966,$A3) -> 0 | BT3: =SUMIFS('Исходные данные'!$I$2:$I$966,'Исходные данные'!$D$2:$D$966,BT$1,'Исходные данные'!$F$2:$F$966,$A3) -> 0 | BU3: =SUMIFS('Исходные данные'!$J$2:$J$966,'Исходные данные'!$D$2:$D$966,BT$1,'Исходные данные'!$F$2:$F$966,$A3) -> 0 | BV3: =SUMIFS('Исходные данные'!$I$2:$I$966,'Исходные данные'!$D$2:$D$966,BV$1,'Исходные данные'!$F$2:$F$966,$A3) -> 0 | BW3: =SUMIFS('Исходные данные'!$J$2:$J$966,'Исходные данные'!$D$2:$D$966,BV$1,'Исходные данные'!$F$2:$F$966,$A3) -> 0 | BX3: =SUMIFS('Исходные данные'!$I$2:$I$966,'Исходные данные'!$D$2:$D$966,BX$1,'Исходные данные'!$F$2:$F$966,$A3) -> 0 | BY3: =SUMIFS('Исходные данные'!$J$2:$J$966,'Исходные данные'!$D$2:$D$966,BX$1,'Исходные данные'!$F$2:$F$966,$A3) -> 0 | BZ3: =SUMIFS('Исходные данные'!$I$2:$I$966,'Исходные данные'!$D$2:$D$966,BZ$1,'Исходные данные'!$F$2:$F$966,$A3) -> 0 | CA3: =SUMIFS('Исходные данные'!$J$2:$J$966,'Исходные данные'!$D$2:$D$966,BZ$1,'Исходные данные'!$F$2:$F$966,$A3) -> 0 | CB3: =SUMIFS('Исходные данные'!$I$2:$I$966,'Исходные данные'!$D$2:$D$966,CB$1,'Исходные данные'!$F$2:$F$966,$A3) -> 0 | CC3: =SUMIFS('Исходные данные'!$J$2:$J$966,'Исходные данные'!$D$2:$D$966,CB$1,'Исходные данные'!$F$2:$F$966,$A3) -> 0 | CD3: =SUMIFS('Исходные данные'!$I$2:$I$966,'Исходные данные'!$D$2:$D$966,CD$1,'Исходные данные'!$F$2:$F$966,$A3) -> 0 | CE3: =SUMIFS('Исходные данные'!$J$2:$J$966,'Исходные данные'!$D$2:$D$966,CD$1,'Исходные данные'!$F$2:$F$966,$A3) -> 0 | CF3: =SUMIFS('Исходные данные'!$I$2:$I$966,'Исходные данные'!$D$2:$D$966,CF$1,'Исходные данные'!$F$2:$F$966,$A3) -> 0 | CG3: =SUMIFS('Исходные данные'!$J$2:$J$966,'Исходные данные'!$D$2:$D$966,CF$1,'Исходные данные'!$F$2:$F$966,$A3) -> 0 | CH3: =SUMIFS('Исходные данные'!$I$2:$I$966,'Исходные данные'!$D$2:$D$966,CH$1,'Исходные данные'!$F$2:$F$966,$A3) -> 0 | CI3: =SUMIFS('Исходные данные'!$J$2:$J$966,'Исходные данные'!$D$2:$D$966,CH$1,'Исходные данные'!$F$2:$F$966,$A3) -> 0 | CJ3: =SUMIFS('Исходные данные'!$I$2:$I$966,'Исходные данные'!$D$2:$D$966,CJ$1,'Исходные данные'!$F$2:$F$966,$A3) -> 0 | CK3: =SUMIFS('Исходные данные'!$J$2:$J$966,'Исходные данные'!$D$2:$D$966,CJ$1,'Исходные данные'!$F$2:$F$966,$A3) -> 0 | CL3: =SUMIFS('Исходные данные'!$I$2:$I$966,'Исходные данные'!$D$2:$D$966,CL$1,'Исходные данные'!$F$2:$F$966,$A3) -> 0 | CM3: =SUMIFS('Исходные данные'!$J$2:$J$966,'Исходные данные'!$D$2:$D$966,CL$1,'Исходные данные'!$F$2:$F$966,$A3) -> 0 | CN3: =SUMIFS('Исходные данные'!$I$2:$I$966,'Исходные данные'!$D$2:$D$966,CN$1,'Исходные данные'!$F$2:$F$966,$A3) -> 0 | CO3: =SUMIFS('Исходные данные'!$J$2:$J$966,'Исходные данные'!$D$2:$D$966,CN$1,'Исходные данные'!$F$2:$F$966,$A3) -> 0 | CP3: =SUMIFS('Исходные данные'!$I$2:$I$966,'Исходные данные'!$D$2:$D$966,CP$1,'Исходные данные'!$F$2:$F$966,$A3) -> 0 | CQ3: =SUMIFS('Исходные данные'!$J$2:$J$966,'Исходные данные'!$D$2:$D$966,CP$1,'Исходные данные'!$F$2:$F$966,$A3) -> 0
A4: 47 | B4: Тракторный экскаватор | C4: 10 | D4: =F4+G4 -> 9 | E4: =D4-C4 -> -1 | F4: =SUMIFS($H4:$CQ4,$H$2:$CQ$2,"День") -> 9 | G4: =SUMIFS($H4:$CQ4,$H$2:$CQ$2,"Ночь") -> 0 | H4: =SUMIFS('Исходные данные'!$I$2:$I$966,'Исходные данные'!$D$2:$D$966,H$1,'Исходные данные'!$F$2:$F$966,$A4) -> 1 | I4: =SUMIFS('Исходные данные'!$J$2:$J$966,'Исходные данные'!$D$2:$D$966,H$1,'Исходные данные'!$F$2:$F$966,$A4) -> 0 | J4: =SUMIFS('Исходные данные'!$I$2:$I$966,'Исходные данные'!$D$2:$D$966,J$1,'Исходные данные'!$F$2:$F$966,$A4) -> 1 | K4: =SUMIFS('Исходные данные'!$J$2:$J$966,'Исходные данные'!$D$2:$D$966,J$1,'Исходные данные'!$F$2:$F$966,$A4) -> 0 | L4: =SUMIFS('Исходные данные'!$I$2:$I$966,'Исходные данные'!$D$2:$D$966,L$1,'Исходные данные'!$F$2:$F$966,$A4) -> 2 | M4: =SUMIFS('Исходные данные'!$J$2:$J$966,'Исходные данные'!$D$2:$D$966,L$1,'Исходные данные'!$F$2:$F$966,$A4) -> 0 | N4: =SUMIFS('Исходные данные'!$I$2:$I$966,'Исходные данные'!$D$2:$D$966,N$1,'Исходные данные'!$F$2:$F$966,$A4) -> 0 | O4: =SUMIFS('Исходные данные'!$J$2:$J$966,'Исходные данные'!$D$2:$D$966,N$1,'Исходные данные'!$F$2:$F$966,$A4) -> 0 | P4: =SUMIFS('Исходные данные'!$I$2:$I$966,'Исходные данные'!$D$2:$D$966,P$1,'Исходные данные'!$F$2:$F$966,$A4) -> 1 | Q4: =SUMIFS('Исходные данные'!$J$2:$J$966,'Исходные данные'!$D$2:$D$966,P$1,'Исходные данные'!$F$2:$F$966,$A4) -> 0 | R4: =SUMIFS('Исходные данные'!$I$2:$I$966,'Исходные данные'!$D$2:$D$966,R$1,'Исходные данные'!$F$2:$F$966,$A4) -> 0 | S4: =SUMIFS('Исходные данные'!$J$2:$J$966,'Исходные данные'!$D$2:$D$966,R$1,'Исходные данные'!$F$2:$F$966,$A4) -> 0 | T4: =SUMIFS('Исходные данные'!$I$2:$I$966,'Исходные данные'!$D$2:$D$966,T$1,'Исходные данные'!$F$2:$F$966,$A4) -> 3 | U4: =SUMIFS('Исходные данные'!$J$2:$J$966,'Исходные данные'!$D$2:$D$966,T$1,'Исходные данные'!$F$2:$F$966,$A4) -> 0 | V4: =SUMIFS('Исходные данные'!$I$2:$I$966,'Исходные данные'!$D$2:$D$966,V$1,'Исходные данные'!$F$2:$F$966,$A4) -> 1 | W4: =SUMIFS('Исходные данные'!$J$2:$J$966,'Исходные данные'!$D$2:$D$966,V$1,'Исходные данные'!$F$2:$F$966,$A4) -> 0 | X4: =SUMIFS('Исходные данные'!$I$2:$I$966,'Исходные данные'!$D$2:$D$966,X$1,'Исходные данные'!$F$2:$F$966,$A4) -> 0 | Y4: =SUMIFS('Исходные данные'!$J$2:$J$966,'Исходные данные'!$D$2:$D$966,X$1,'Исходные данные'!$F$2:$F$966,$A4) -> 0 | Z4: =SUMIFS('Исходные данные'!$I$2:$I$966,'Исходные данные'!$D$2:$D$966,Z$1,'Исходные данные'!$F$2:$F$966,$A4) -> 0 | AA4: =SUMIFS('Исходные данные'!$J$2:$J$966,'Исходные данные'!$D$2:$D$966,Z$1,'Исходные данные'!$F$2:$F$966,$A4) -> 0 | AB4: =SUMIFS('Исходные данные'!$I$2:$I$966,'Исходные данные'!$D$2:$D$966,AB$1,'Исходные данные'!$F$2:$F$966,$A4) -> 0 | AC4: =SUMIFS('Исходные данные'!$J$2:$J$966,'Исходные данные'!$D$2:$D$966,AB$1,'Исходные данные'!$F$2:$F$966,$A4) -> 0 | AD4: =SUMIFS('Исходные данные'!$I$2:$I$966,'Исходные данные'!$D$2:$D$966,AD$1,'Исходные данные'!$F$2:$F$966,$A4) -> 0 | AE4: =SUMIFS('Исходные данные'!$J$2:$J$966,'Исходные данные'!$D$2:$D$966,AD$1,'Исходные данные'!$F$2:$F$966,$A4) -> 0 | AF4: =SUMIFS('Исходные данные'!$I$2:$I$966,'Исходные данные'!$D$2:$D$966,AF$1,'Исходные данные'!$F$2:$F$966,$A4) -> 0 | AG4: =SUMIFS('Исходные данные'!$J$2:$J$966,'Исходные данные'!$D$2:$D$966,AF$1,'Исходные данные'!$F$2:$F$966,$A4) -> 0 | AH4: =SUMIFS('Исходные данные'!$I$2:$I$966,'Исходные данные'!$D$2:$D$966,AH$1,'Исходные данные'!$F$2:$F$966,$A4) -> 0 | AI4: =SUMIFS('Исходные данные'!$J$2:$J$966,'Исходные данные'!$D$2:$D$966,AH$1,'Исходные данные'!$F$2:$F$966,$A4) -> 0 | AJ4: =SUMIFS('Исходные данные'!$I$2:$I$966,'Исходные данные'!$D$2:$D$966,AJ$1,'Исходные данные'!$F$2:$F$966,$A4) -> 0 | AK4: =SUMIFS('Исходные данные'!$J$2:$J$966,'Исходные данные'!$D$2:$D$966,AJ$1,'Исходные данные'!$F$2:$F$966,$A4) -> 0 | AL4: =SUMIFS('Исходные данные'!$I$2:$I$966,'Исходные данные'!$D$2:$D$966,AL$1,'Исходные данные'!$F$2:$F$966,$A4) -> 0 | AM4: =SUMIFS('Исходные данные'!$J$2:$J$966,'Исходные данные'!$D$2:$D$966,AL$1,'Исходные данные'!$F$2:$F$966,$A4) -> 0 | AN4: =SUMIFS('Исходные данные'!$I$2:$I$966,'Исходные данные'!$D$2:$D$966,AN$1,'Исходные данные'!$F$2:$F$966,$A4) -> 0 | AO4: =SUMIFS('Исходные данные'!$J$2:$J$966,'Исходные данные'!$D$2:$D$966,AN$1,'Исходные данные'!$F$2:$F$966,$A4) -> 0 | AP4: =SUMIFS('Исходные данные'!$I$2:$I$966,'Исходные данные'!$D$2:$D$966,AP$1,'Исходные данные'!$F$2:$F$966,$A4) -> 0 | AQ4: =SUMIFS('Исходные данные'!$J$2:$J$966,'Исходные данные'!$D$2:$D$966,AP$1,'Исходные данные'!$F$2:$F$966,$A4) -> 0 | AR4: =SUMIFS('Исходные данные'!$I$2:$I$966,'Исходные данные'!$D$2:$D$966,AR$1,'Исходные данные'!$F$2:$F$966,$A4) -> 0 | AS4: =SUMIFS('Исходные данные'!$J$2:$J$966,'Исходные данные'!$D$2:$D$966,AR$1,'Исходные данные'!$F$2:$F$966,$A4) -> 0 | AT4: =SUMIFS('Исходные данные'!$I$2:$I$966,'Исходные данные'!$D$2:$D$966,AT$1,'Исходные данные'!$F$2:$F$966,$A4) -> 0 | AU4: =SUMIFS('Исходные данные'!$J$2:$J$966,'Исходные данные'!$D$2:$D$966,AT$1,'Исходные данные'!$F$2:$F$966,$A4) -> 0 | AV4: =SUMIFS('Исходные данные'!$I$2:$I$966,'Исходные данные'!$D$2:$D$966,AV$1,'Исходные данные'!$F$2:$F$966,$A4) -> 0 | AW4: =SUMIFS('Исходные данные'!$J$2:$J$966,'Исходные данные'!$D$2:$D$966,AV$1,'Исходные данные'!$F$2:$F$966,$A4) -> 0 | AX4: =SUMIFS('Исходные данные'!$I$2:$I$966,'Исходные данные'!$D$2:$D$966,AX$1,'Исходные данные'!$F$2:$F$966,$A4) -> 0 | AY4: =SUMIFS('Исходные данные'!$J$2:$J$966,'Исходные данные'!$D$2:$D$966,AX$1,'Исходные данные'!$F$2:$F$966,$A4) -> 0 | AZ4: =SUMIFS('Исходные данные'!$I$2:$I$966,'Исходные данные'!$D$2:$D$966,AZ$1,'Исходные данные'!$F$2:$F$966,$A4) -> 0 | BA4: =SUMIFS('Исходные данные'!$J$2:$J$966,'Исходные данные'!$D$2:$D$966,AZ$1,'Исходные данные'!$F$2:$F$966,$A4) -> 0 | BB4: =SUMIFS('Исходные данные'!$I$2:$I$966,'Исходные данные'!$D$2:$D$966,BB$1,'Исходные данные'!$F$2:$F$966,$A4) -> 0 | BC4: =SUMIFS('Исходные данные'!$J$2:$J$966,'Исходные данные'!$D$2:$D$966,BB$1,'Исходные данные'!$F$2:$F$966,$A4) -> 0 | BD4: =SUMIFS('Исходные данные'!$I$2:$I$966,'Исходные данные'!$D$2:$D$966,BD$1,'Исходные данные'!$F$2:$F$966,$A4) -> 0 | BE4: =SUMIFS('Исходные данные'!$J$2:$J$966,'Исходные данные'!$D$2:$D$966,BD$1,'Исходные данные'!$F$2:$F$966,$A4) -> 0 | BF4: =SUMIFS('Исходные данные'!$I$2:$I$966,'Исходные данные'!$D$2:$D$966,BF$1,'Исходные данные'!$F$2:$F$966,$A4) -> 0 | BG4: =SUMIFS('Исходные данные'!$J$2:$J$966,'Исходные данные'!$D$2:$D$966,BF$1,'Исходные данные'!$F$2:$F$966,$A4) -> 0 | BH4: =SUMIFS('Исходные данные'!$I$2:$I$966,'Исходные данные'!$D$2:$D$966,BH$1,'Исходные данные'!$F$2:$F$966,$A4) -> 0 | BI4: =SUMIFS('Исходные данные'!$J$2:$J$966,'Исходные данные'!$D$2:$D$966,BH$1,'Исходные данные'!$F$2:$F$966,$A4) -> 0 | BJ4: =SUMIFS('Исходные данные'!$I$2:$I$966,'Исходные данные'!$D$2:$D$966,BJ$1,'Исходные данные'!$F$2:$F$966,$A4) -> 0 | BK4: =SUMIFS('Исходные данные'!$J$2:$J$966,'Исходные данные'!$D$2:$D$966,BJ$1,'Исходные данные'!$F$2:$F$966,$A4) -> 0 | BL4: =SUMIFS('Исходные данные'!$I$2:$I$966,'Исходные данные'!$D$2:$D$966,BL$1,'Исходные данные'!$F$2:$F$966,$A4) -> 0 | BM4: =SUMIFS('Исходные данные'!$J$2:$J$966,'Исходные данные'!$D$2:$D$966,BL$1,'Исходные данные'!$F$2:$F$966,$A4) -> 0 | BN4: =SUMIFS('Исходные данные'!$I$2:$I$966,'Исходные данные'!$D$2:$D$966,BN$1,'Исходные данные'!$F$2:$F$966,$A4) -> 0 | BO4: =SUMIFS('Исходные данные'!$J$2:$J$966,'Исходные данные'!$D$2:$D$966,BN$1,'Исходные данные'!$F$2:$F$966,$A4) -> 0 | BP4: =SUMIFS('Исходные данные'!$I$2:$I$966,'Исходные данные'!$D$2:$D$966,BP$1,'Исходные данные'!$F$2:$F$966,$A4) -> 0 | BQ4: =SUMIFS('Исходные данные'!$J$2:$J$966,'Исходные данные'!$D$2:$D$966,BP$1,'Исходные данные'!$F$2:$F$966,$A4) -> 0 | BR4: =SUMIFS('Исходные данные'!$I$2:$I$966,'Исходные данные'!$D$2:$D$966,BR$1,'Исходные данные'!$F$2:$F$966,$A4) -> 0 | BS4: =SUMIFS('Исходные данные'!$J$2:$J$966,'Исходные данные'!$D$2:$D$966,BR$1,'Исходные данные'!$F$2:$F$966,$A4) -> 0 | BT4: =SUMIFS('Исходные данные'!$I$2:$I$966,'Исходные данные'!$D$2:$D$966,BT$1,'Исходные данные'!$F$2:$F$966,$A4) -> 0 | BU4: =SUMIFS('Исходные данные'!$J$2:$J$966,'Исходные данные'!$D$2:$D$966,BT$1,'Исходные данные'!$F$2:$F$966,$A4) -> 0 | BV4: =SUMIFS('Исходные данные'!$I$2:$I$966,'Исходные данные'!$D$2:$D$966,BV$1,'Исходные данные'!$F$2:$F$966,$A4) -> 0 | BW4: =SUMIFS('Исходные данные'!$J$2:$J$966,'Исходные данные'!$D$2:$D$966,BV$1,'Исходные данные'!$F$2:$F$966,$A4) -> 0 | BX4: =SUMIFS('Исходные данные'!$I$2:$I$966,'Исходные данные'!$D$2:$D$966,BX$1,'Исходные данные'!$F$2:$F$966,$A4) -> 0 | BY4: =SUMIFS('Исходные данные'!$J$2:$J$966,'Исходные данные'!$D$2:$D$966,BX$1,'Исходные данные'!$F$2:$F$966,$A4) -> 0 | BZ4: =SUMIFS('Исходные данные'!$I$2:$I$966,'Исходные данные'!$D$2:$D$966,BZ$1,'Исходные данные'!$F$2:$F$966,$A4) -> 0 | CA4: =SUMIFS('Исходные данные'!$J$2:$J$966,'Исходные данные'!$D$2:$D$966,BZ$1,'Исходные данные'!$F$2:$F$966,$A4) -> 0 | CB4: =SUMIFS('Исходные данные'!$I$2:$I$966,'Исходные данные'!$D$2:$D$966,CB$1,'Исходные данные'!$F$2:$F$966,$A4) -> 0 | CC4: =SUMIFS('Исходные данные'!$J$2:$J$966,'Исходные данные'!$D$2:$D$966,CB$1,'Исходные данные'!$F$2:$F$966,$A4) -> 0 | CD4: =SUMIFS('Исходные данные'!$I$2:$I$966,'Исходные данные'!$D$2:$D$966,CD$1,'Исходные данные'!$F$2:$F$966,$A4) -> 0 | CE4: =SUMIFS('Исходные данные'!$J$2:$J$966,'Исходные данные'!$D$2:$D$966,CD$1,'Исходные данные'!$F$2:$F$966,$A4) -> 0 | CF4: =SUMIFS('Исходные данные'!$I$2:$I$966,'Исходные данные'!$D$2:$D$966,CF$1,'Исходные данные'!$F$2:$F$966,$A4) -> 0 | CG4: =SUMIFS('Исходные данные'!$J$2:$J$966,'Исходные данные'!$D$2:$D$966,CF$1,'Исходные данные'!$F$2:$F$966,$A4) -> 0 | CH4: =SUMIFS('Исходные данные'!$I$2:$I$966,'Исходные данные'!$D$2:$D$966,CH$1,'Исходные данные'!$F$2:$F$966,$A4) -> 0 | CI4: =SUMIFS('Исходные данные'!$J$2:$J$966,'Исходные данные'!$D$2:$D$966,CH$1,'Исходные данные'!$F$2:$F$966,$A4) -> 0 | CJ4: =SUMIFS('Исходные данные'!$I$2:$I$966,'Исходные данные'!$D$2:$D$966,CJ$1,'Исходные данные'!$F$2:$F$966,$A4) -> 0 | CK4: =SUMIFS('Исходные данные'!$J$2:$J$966,'Исходные данные'!$D$2:$D$966,CJ$1,'Исходные данные'!$F$2:$F$966,$A4) -> 0 | CL4: =SUMIFS('Исходные данные'!$I$2:$I$966,'Исходные данные'!$D$2:$D$966,CL$1,'Исходные данные'!$F$2:$F$966,$A4) -> 0 | CM4: =SUMIFS('Исходные данные'!$J$2:$J$966,'Исходные данные'!$D$2:$D$966,CL$1,'Исходные данные'!$F$2:$F$966,$A4) -> 0 | CN4: =SUMIFS('Исходные данные'!$I$2:$I$966,'Исходные данные'!$D$2:$D$966,CN$1,'Исходные данные'!$F$2:$F$966,$A4) -> 0 | CO4: =SUMIFS('Исходные данные'!$J$2:$J$966,'Исходные данные'!$D$2:$D$966,CN$1,'Исходные данные'!$F$2:$F$966,$A4) -> 0 | CP4: =SUMIFS('Исходные данные'!$I$2:$I$966,'Исходные данные'!$D$2:$D$966,CP$1,'Исходные данные'!$F$2:$F$966,$A4) -> 0 | CQ4: =SUMIFS('Исходные данные'!$J$2:$J$966,'Исходные данные'!$D$2:$D$966,CP$1,'Исходные данные'!$F$2:$F$966,$A4) -> 0
A5: 49 | B5: Вакуумная установка | C5: 15 | D5: =F5+G5 -> 15 | E5: =D5-C5 -> 0 | F5: =SUMIFS($H5:$CQ5,$H$2:$CQ$2,"День") -> 9 | G5: =SUMIFS($H5:$CQ5,$H$2:$CQ$2,"Ночь") -> 6 | H5: =SUMIFS('Исходные данные'!$I$2:$I$966,'Исходные данные'!$D$2:$D$966,H$1,'Исходные данные'!$F$2:$F$966,$A5) -> 2 | I5: =SUMIFS('Исходные данные'!$J$2:$J$966,'Исходные данные'!$D$2:$D$966,H$1,'Исходные данные'!$F$2:$F$966,$A5) -> 2 | J5: =SUMIFS('Исходные данные'!$I$2:$I$966,'Исходные данные'!$D$2:$D$966,J$1,'Исходные данные'!$F$2:$F$966,$A5) -> 1 | K5: =SUMIFS('Исходные данные'!$J$2:$J$966,'Исходные данные'!$D$2:$D$966,J$1,'Исходные данные'!$F$2:$F$966,$A5) -> 0 | L5: =SUMIFS('Исходные данные'!$I$2:$I$966,'Исходные данные'!$D$2:$D$966,L$1,'Исходные данные'!$F$2:$F$966,$A5) -> 2 | M5: =SUMIFS('Исходные данные'!$J$2:$J$966,'Исходные данные'!$D$2:$D$966,L$1,'Исходные данные'!$F$2:$F$966,$A5) -> 1 | N5: =SUMIFS('Исходные данные'!$I$2:$I$966,'Исходные данные'!$D$2:$D$966,N$1,'Исходные данные'!$F$2:$F$966,$A5) -> 1 | O5: =SUMIFS('Исходные данные'!$J$2:$J$966,'Исходные данные'!$D$2:$D$966,N$1,'Исходные данные'!$F$2:$F$966,$A5) -> 0 | P5: =SUMIFS('Исходные данные'!$I$2:$I$966,'Исходные данные'!$D$2:$D$966,P$1,'Исходные данные'!$F$2:$F$966,$A5) -> 0 | Q5: =SUMIFS('Исходные данные'!$J$2:$J$966,'Исходные данные'!$D$2:$D$966,P$1,'Исходные данные'!$F$2:$F$966,$A5) -> 0 | R5: =SUMIFS('Исходные данные'!$I$2:$I$966,'Исходные данные'!$D$2:$D$966,R$1,'Исходные данные'!$F$2:$F$966,$A5) -> 0 | S5: =SUMIFS('Исходные данные'!$J$2:$J$966,'Исходные данные'!$D$2:$D$966,R$1,'Исходные данные'!$F$2:$F$966,$A5) -> 0 | T5: =SUMIFS('Исходные данные'!$I$2:$I$966,'Исходные данные'!$D$2:$D$966,T$1,'Исходные данные'!$F$2:$F$966,$A5) -> 0 | U5: =SUMIFS('Исходные данные'!$J$2:$J$966,'Исходные данные'!$D$2:$D$966,T$1,'Исходные данные'!$F$2:$F$966,$A5) -> 0 | V5: =SUMIFS('Исходные данные'!$I$2:$I$966,'Исходные данные'!$D$2:$D$966,V$1,'Исходные данные'!$F$2:$F$966,$A5) -> 0 | W5: =SUMIFS('Исходные данные'!$J$2:$J$966,'Исходные данные'!$D$2:$D$966,V$1,'Исходные данные'!$F$2:$F$966,$A5) -> 0 | X5: =SUMIFS('Исходные данные'!$I$2:$I$966,'Исходные данные'!$D$2:$D$966,X$1,'Исходные данные'!$F$2:$F$966,$A5) -> 0 | Y5: =SUMIFS('Исходные данные'!$J$2:$J$966,'Исходные данные'!$D$2:$D$966,X$1,'Исходные данные'!$F$2:$F$966,$A5) -> 0 | Z5: =SUMIFS('Исходные данные'!$I$2:$I$966,'Исходные данные'!$D$2:$D$966,Z$1,'Исходные данные'!$F$2:$F$966,$A5) -> 0 | AA5: =SUMIFS('Исходные данные'!$J$2:$J$966,'Исходные данные'!$D$2:$D$966,Z$1,'Исходные данные'!$F$2:$F$966,$A5) -> 0 | AB5: =SUMIFS('Исходные данные'!$I$2:$I$966,'Исходные данные'!$D$2:$D$966,AB$1,'Исходные данные'!$F$2:$F$966,$A5) -> 0 | AC5: =SUMIFS('Исходные данные'!$J$2:$J$966,'Исходные данные'!$D$2:$D$966,AB$1,'Исходные данные'!$F$2:$F$966,$A5) -> 0 | AD5: =SUMIFS('Исходные данные'!$I$2:$I$966,'Исходные данные'!$D$2:$D$966,AD$1,'Исходные данные'!$F$2:$F$966,$A5) -> 0 | AE5: =SUMIFS('Исходные данные'!$J$2:$J$966,'Исходные данные'!$D$2:$D$966,AD$1,'Исходные данные'!$F$2:$F$966,$A5) -> 0 | AF5: =SUMIFS('Исходные данные'!$I$2:$I$966,'Исходные данные'!$D$2:$D$966,AF$1,'Исходные данные'!$F$2:$F$966,$A5) -> 0 | AG5: =SUMIFS('Исходные данные'!$J$2:$J$966,'Исходные данные'!$D$2:$D$966,AF$1,'Исходные данные'!$F$2:$F$966,$A5) -> 0 | AH5: =SUMIFS('Исходные данные'!$I$2:$I$966,'Исходные данные'!$D$2:$D$966,AH$1,'Исходные данные'!$F$2:$F$966,$A5) -> 2 | AI5: =SUMIFS('Исходные данные'!$J$2:$J$966,'Исходные данные'!$D$2:$D$966,AH$1,'Исходные данные'!$F$2:$F$966,$A5) -> 2 | AJ5: =SUMIFS('Исходные данные'!$I$2:$I$966,'Исходные данные'!$D$2:$D$966,AJ$1,'Исходные данные'!$F$2:$F$966,$A5) -> 1 | AK5: =SUMIFS('Исходные данные'!$J$2:$J$966,'Исходные данные'!$D$2:$D$966,AJ$1,'Исходные данные'!$F$2:$F$966,$A5) -> 1 | AL5: =SUMIFS('Исходные данные'!$I$2:$I$966,'Исходные данные'!$D$2:$D$966,AL$1,'Исходные данные'!$F$2:$F$966,$A5) -> 0 | AM5: =SUMIFS('Исходные данные'!$J$2:$J$966,'Исходные данные'!$D$2:$D$966,AL$1,'Исходные данные'!$F$2:$F$966,$A5) -> 0 | AN5: =SUMIFS('Исходные данные'!$I$2:$I$966,'Исходные данные'!$D$2:$D$966,AN$1,'Исходные данные'!$F$2:$F$966,$A5) -> 0 | AO5: =SUMIFS('Исходные данные'!$J$2:$J$966,'Исходные данные'!$D$2:$D$966,AN$1,'Исходные данные'!$F$2:$F$966,$A5) -> 0 | AP5: =SUMIFS('Исходные данные'!$I$2:$I$966,'Исходные данные'!$D$2:$D$966,AP$1,'Исходные данные'!$F$2:$F$966,$A5) -> 0 | AQ5: =SUMIFS('Исходные данные'!$J$2:$J$966,'Исходные данные'!$D$2:$D$966,AP$1,'Исходные данные'!$F$2:$F$966,$A5) -> 0 | AR5: =SUMIFS('Исходные данные'!$I$2:$I$966,'Исходные данные'!$D$2:$D$966,AR$1,'Исходные данные'!$F$2:$F$966,$A5) -> 0 | AS5: =SUMIFS('Исходные данные'!$J$2:$J$966,'Исходные данные'!$D$2:$D$966,AR$1,'Исходные данные'!$F$2:$F$966,$A5) -> 0 | AT5: =SUMIFS('Исходные данные'!$I$2:$I$966,'Исходные данные'!$D$2:$D$966,AT$1,'Исходные данные'!$F$2:$F$966,$A5) -> 0 | AU5: =SUMIFS('Исходные данные'!$J$2:$J$966,'Исходные данные'!$D$2:$D$966,AT$1,'Исходные данные'!$F$2:$F$966,$A5) -> 0 | AV5: =SUMIFS('Исходные данные'!$I$2:$I$966,'Исходные данные'!$D$2:$D$966,AV$1,'Исходные данные'!$F$2:$F$966,$A5) -> 0 | AW5: =SUMIFS('Исходные данные'!$J$2:$J$966,'Исходные данные'!$D$2:$D$966,AV$1,'Исходные данные'!$F$2:$F$966,$A5) -> 0 | AX5: =SUMIFS('Исходные данные'!$I$2:$I$966,'Исходные данные'!$D$2:$D$966,AX$1,'Исходные данные'!$F$2:$F$966,$A5) -> 0 | AY5: =SUMIFS('Исходные данные'!$J$2:$J$966,'Исходные данные'!$D$2:$D$966,AX$1,'Исходные данные'!$F$2:$F$966,$A5) -> 0 | AZ5: =SUMIFS('Исходные данные'!$I$2:$I$966,'Исходные данные'!$D$2:$D$966,AZ$1,'Исходные данные'!$F$2:$F$966,$A5) -> 0 | BA5: =SUMIFS('Исходные данные'!$J$2:$J$966,'Исходные данные'!$D$2:$D$966,AZ$1,'Исходные данные'!$F$2:$F$966,$A5) -> 0 | BB5: =SUMIFS('Исходные данные'!$I$2:$I$966,'Исходные данные'!$D$2:$D$966,BB$1,'Исходные данные'!$F$2:$F$966,$A5) -> 0 | BC5: =SUMIFS('Исходные данные'!$J$2:$J$966,'Исходные данные'!$D$2:$D$966,BB$1,'Исходные данные'!$F$2:$F$966,$A5) -> 0 | BD5: =SUMIFS('Исходные данные'!$I$2:$I$966,'Исходные данные'!$D$2:$D$966,BD$1,'Исходные данные'!$F$2:$F$966,$A5) -> 0 | BE5: =SUMIFS('Исходные данные'!$J$2:$J$966,'Исходные данные'!$D$2:$D$966,BD$1,'Исходные данные'!$F$2:$F$966,$A5) -> 0 | BF5: =SUMIFS('Исходные данные'!$I$2:$I$966,'Исходные данные'!$D$2:$D$966,BF$1,'Исходные данные'!$F$2:$F$966,$A5) -> 0 | BG5: =SUMIFS('Исходные данные'!$J$2:$J$966,'Исходные данные'!$D$2:$D$966,BF$1,'Исходные данные'!$F$2:$F$966,$A5) -> 0 | BH5: =SUMIFS('Исходные данные'!$I$2:$I$966,'Исходные данные'!$D$2:$D$966,BH$1,'Исходные данные'!$F$2:$F$966,$A5) -> 0 | BI5: =SUMIFS('Исходные данные'!$J$2:$J$966,'Исходные данные'!$D$2:$D$966,BH$1,'Исходные данные'!$F$2:$F$966,$A5) -> 0 | BJ5: =SUMIFS('Исходные данные'!$I$2:$I$966,'Исходные данные'!$D$2:$D$966,BJ$1,'Исходные данные'!$F$2:$F$966,$A5) -> 0 | BK5: =SUMIFS('Исходные данные'!$J$2:$J$966,'Исходные данные'!$D$2:$D$966,BJ$1,'Исходные данные'!$F$2:$F$966,$A5) -> 0 | BL5: =SUMIFS('Исходные данные'!$I$2:$I$966,'Исходные данные'!$D$2:$D$966,BL$1,'Исходные данные'!$F$2:$F$966,$A5) -> 0 | BM5: =SUMIFS('Исходные данные'!$J$2:$J$966,'Исходные данные'!$D$2:$D$966,BL$1,'Исходные данные'!$F$2:$F$966,$A5) -> 0 | BN5: =SUMIFS('Исходные данные'!$I$2:$I$966,'Исходные данные'!$D$2:$D$966,BN$1,'Исходные данные'!$F$2:$F$966,$A5) -> 0 | BO5: =SUMIFS('Исходные данные'!$J$2:$J$966,'Исходные данные'!$D$2:$D$966,BN$1,'Исходные данные'!$F$2:$F$966,$A5) -> 0 | BP5: =SUMIFS('Исходные данные'!$I$2:$I$966,'Исходные данные'!$D$2:$D$966,BP$1,'Исходные данные'!$F$2:$F$966,$A5) -> 0 | BQ5: =SUMIFS('Исходные данные'!$J$2:$J$966,'Исходные данные'!$D$2:$D$966,BP$1,'Исходные данные'!$F$2:$F$966,$A5) -> 0 | BR5: =SUMIFS('Исходные данные'!$I$2:$I$966,'Исходные данные'!$D$2:$D$966,BR$1,'Исходные данные'!$F$2:$F$966,$A5) -> 0 | BS5: =SUMIFS('Исходные данные'!$J$2:$J$966,'Исходные данные'!$D$2:$D$966,BR$1,'Исходные данные'!$F$2:$F$966,$A5) -> 0 | BT5: =SUMIFS('Исходные данные'!$I$2:$I$966,'Исходные данные'!$D$2:$D$966,BT$1,'Исходные данные'!$F$2:$F$966,$A5) -> 0 | BU5: =SUMIFS('Исходные данные'!$J$2:$J$966,'Исходные данные'!$D$2:$D$966,BT$1,'Исходные данные'!$F$2:$F$966,$A5) -> 0 | BV5: =SUMIFS('Исходные данные'!$I$2:$I$966,'Исходные данные'!$D$2:$D$966,BV$1,'Исходные данные'!$F$2:$F$966,$A5) -> 0 | BW5: =SUMIFS('Исходные данные'!$J$2:$J$966,'Исходные данные'!$D$2:$D$966,BV$1,'Исходные данные'!$F$2:$F$966,$A5) -> 0 | BX5: =SUMIFS('Исходные данные'!$I$2:$I$966,'Исходные данные'!$D$2:$D$966,BX$1,'Исходные данные'!$F$2:$F$966,$A5) -> 0 | BY5: =SUMIFS('Исходные данные'!$J$2:$J$966,'Исходные данные'!$D$2:$D$966,BX$1,'Исходные данные'!$F$2:$F$966,$A5) -> 0 | BZ5: =SUMIFS('Исходные данные'!$I$2:$I$966,'Исходные данные'!$D$2:$D$966,BZ$1,'Исходные данные'!$F$2:$F$966,$A5) -> 0 | CA5: =SUMIFS('Исходные данные'!$J$2:$J$966,'Исходные данные'!$D$2:$D$966,BZ$1,'Исходные данные'!$F$2:$F$966,$A5) -> 0 | CB5: =SUMIFS('Исходные данные'!$I$2:$I$966,'Исходные данные'!$D$2:$D$966,CB$1,'Исходные данные'!$F$2:$F$966,$A5) -> 0 | CC5: =SUMIFS('Исходные данные'!$J$2:$J$966,'Исходные данные'!$D$2:$D$966,CB$1,'Исходные данные'!$F$2:$F$966,$A5) -> 0 | CD5: =SUMIFS('Исходные данные'!$I$2:$I$966,'Исходные данные'!$D$2:$D$966,CD$1,'Исходные данные'!$F$2:$F$966,$A5) -> 0 | CE5: =SUMIFS('Исходные данные'!$J$2:$J$966,'Исходные данные'!$D$2:$D$966,CD$1,'Исходные данные'!$F$2:$F$966,$A5) -> 0 | CF5: =SUMIFS('Исходные данные'!$I$2:$I$966,'Исходные данные'!$D$2:$D$966,CF$1,'Исходные данные'!$F$2:$F$966,$A5) -> 0 | CG5: =SUMIFS('Исходные данные'!$J$2:$J$966,'Исходные данные'!$D$2:$D$966,CF$1,'Исходные данные'!$F$2:$F$966,$A5) -> 0 | CH5: =SUMIFS('Исходные данные'!$I$2:$I$966,'Исходные данные'!$D$2:$D$966,CH$1,'Исходные данные'!$F$2:$F$966,$A5) -> 0 | CI5: =SUMIFS('Исходные данные'!$J$2:$J$966,'Исходные данные'!$D$2:$D$966,CH$1,'Исходные данные'!$F$2:$F$966,$A5) -> 0 | CJ5: =SUMIFS('Исходные данные'!$I$2:$I$966,'Исходные данные'!$D$2:$D$966,CJ$1,'Исходные данные'!$F$2:$F$966,$A5) -> 0 | CK5: =SUMIFS('Исходные данные'!$J$2:$J$966,'Исходные данные'!$D$2:$D$966,CJ$1,'Исходные данные'!$F$2:$F$966,$A5) -> 0 | CL5: =SUMIFS('Исходные данные'!$I$2:$I$966,'Исходные данные'!$D$2:$D$966,CL$1,'Исходные данные'!$F$2:$F$966,$A5) -> 0 | CM5: =SUMIFS('Исходные данные'!$J$2:$J$966,'Исходные данные'!$D$2:$D$966,CL$1,'Исходные данные'!$F$2:$F$966,$A5) -> 0 | CN5: =SUMIFS('Исходные данные'!$I$2:$I$966,'Исходные данные'!$D$2:$D$966,CN$1,'Исходные данные'!$F$2:$F$966,$A5) -> 0 | CO5: =SUMIFS('Исходные данные'!$J$2:$J$966,'Исходные данные'!$D$2:$D$966,CN$1,'Исходные данные'!$F$2:$F$966,$A5) -> 0 | CP5: =SUMIFS('Исходные данные'!$I$2:$I$966,'Исходные данные'!$D$2:$D$966,CP$1,'Исходные данные'!$F$2:$F$966,$A5) -> 0 | CQ5: =SUMIFS('Исходные данные'!$J$2:$J$966,'Исходные данные'!$D$2:$D$966,CP$1,'Исходные данные'!$F$2:$F$966,$A5) -> 0
A6: 28 | B6: Кран 16-20т | C6: 25 | D6: =F6+G6 -> 24 | E6: =D6-C6 -> -1 | F6: =SUMIFS($H6:$CQ6,$H$2:$CQ$2,"День") -> 16 | G6: =SUMIFS($H6:$CQ6,$H$2:$CQ$2,"Ночь") -> 8 | H6: =SUMIFS('Исходные данные'!$I$2:$I$966,'Исходные данные'!$D$2:$D$966,H$1,'Исходные данные'!$F$2:$F$966,$A6) -> 1 | I6: =SUMIFS('Исходные данные'!$J$2:$J$966,'Исходные данные'!$D$2:$D$966,H$1,'Исходные данные'!$F$2:$F$966,$A6) -> 0 | J6: =SUMIFS('Исходные данные'!$I$2:$I$966,'Исходные данные'!$D$2:$D$966,J$1,'Исходные данные'!$F$2:$F$966,$A6) -> 1 | K6: =SUMIFS('Исходные данные'!$J$2:$J$966,'Исходные данные'!$D$2:$D$966,J$1,'Исходные данные'!$F$2:$F$966,$A6) -> 0 | L6: =SUMIFS('Исходные данные'!$I$2:$I$966,'Исходные данные'!$D$2:$D$966,L$1,'Исходные данные'!$F$2:$F$966,$A6) -> 2 | M6: =SUMIFS('Исходные данные'!$J$2:$J$966,'Исходные данные'!$D$2:$D$966,L$1,'Исходные данные'!$F$2:$F$966,$A6) -> 0 | N6: =SUMIFS('Исходные данные'!$I$2:$I$966,'Исходные данные'!$D$2:$D$966,N$1,'Исходные данные'!$F$2:$F$966,$A6) -> 0 | O6: =SUMIFS('Исходные данные'!$J$2:$J$966,'Исходные данные'!$D$2:$D$966,N$1,'Исходные данные'!$F$2:$F$966,$A6) -> 0 | P6: =SUMIFS('Исходные данные'!$I$2:$I$966,'Исходные данные'!$D$2:$D$966,P$1,'Исходные данные'!$F$2:$F$966,$A6) -> 0 | Q6: =SUMIFS('Исходные данные'!$J$2:$J$966,'Исходные данные'!$D$2:$D$966,P$1,'Исходные данные'!$F$2:$F$966,$A6) -> 0 | R6: =SUMIFS('Исходные данные'!$I$2:$I$966,'Исходные данные'!$D$2:$D$966,R$1,'Исходные данные'!$F$2:$F$966,$A6) -> 1 | S6: =SUMIFS('Исходные данные'!$J$2:$J$966,'Исходные данные'!$D$2:$D$966,R$1,'Исходные данные'!$F$2:$F$966,$A6) -> 0 | T6: =SUMIFS('Исходные данные'!$I$2:$I$966,'Исходные данные'!$D$2:$D$966,T$1,'Исходные данные'!$F$2:$F$966,$A6) -> 0 | U6: =SUMIFS('Исходные данные'!$J$2:$J$966,'Исходные данные'!$D$2:$D$966,T$1,'Исходные данные'!$F$2:$F$966,$A6) -> 0 | V6: =SUMIFS('Исходные данные'!$I$2:$I$966,'Исходные данные'!$D$2:$D$966,V$1,'Исходные данные'!$F$2:$F$966,$A6) -> 0 | W6: =SUMIFS('Исходные данные'!$J$2:$J$966,'Исходные данные'!$D$2:$D$966,V$1,'Исходные данные'!$F$2:$F$966,$A6) -> 0 | X6: =SUMIFS('Исходные данные'!$I$2:$I$966,'Исходные данные'!$D$2:$D$966,X$1,'Исходные данные'!$F$2:$F$966,$A6) -> 2 | Y6: =SUMIFS('Исходные данные'!$J$2:$J$966,'Исходные данные'!$D$2:$D$966,X$1,'Исходные данные'!$F$2:$F$966,$A6) -> 0 | Z6: =SUMIFS('Исходные данные'!$I$2:$I$966,'Исходные данные'!$D$2:$D$966,Z$1,'Исходные данные'!$F$2:$F$966,$A6) -> 1 | AA6: =SUMIFS('Исходные данные'!$J$2:$J$966,'Исходные данные'!$D$2:$D$966,Z$1,'Исходные данные'!$F$2:$F$966,$A6) -> 0 | AB6: =SUMIFS('Исходные данные'!$I$2:$I$966,'Исходные данные'!$D$2:$D$966,AB$1,'Исходные данные'!$F$2:$F$966,$A6) -> 0 | AC6: =SUMIFS('Исходные данные'!$J$2:$J$966,'Исходные данные'!$D$2:$D$966,AB$1,'Исходные данные'!$F$2:$F$966,$A6) -> 0 | AD6: =SUMIFS('Исходные данные'!$I$2:$I$966,'Исходные данные'!$D$2:$D$966,AD$1,'Исходные данные'!$F$2:$F$966,$A6) -> 0 | AE6: =SUMIFS('Исходные данные'!$J$2:$J$966,'Исходные данные'!$D$2:$D$966,AD$1,'Исходные данные'!$F$2:$F$966,$A6) -> 0 | AF6: =SUMIFS('Исходные данные'!$I$2:$I$966,'Исходные данные'!$D$2:$D$966,AF$1,'Исходные данные'!$F$2:$F$966,$A6) -> 1 | AG6: =SUMIFS('Исходные данные'!$J$2:$J$966,'Исходные данные'!$D$2:$D$966,AF$1,'Исходные данные'!$F$2:$F$966,$A6) -> 0 | AH6: =SUMIFS('Исходные данные'!$I$2:$I$966,'Исходные данные'!$D$2:$D$966,AH$1,'Исходные данные'!$F$2:$F$966,$A6) -> 4 | AI6: =SUMIFS('Исходные данные'!$J$2:$J$966,'Исходные данные'!$D$2:$D$966,AH$1,'Исходные данные'!$F$2:$F$966,$A6) -> 5 | AJ6: =SUMIFS('Исходные данные'!$I$2:$I$966,'Исходные данные'!$D$2:$D$966,AJ$1,'Исходные данные'!$F$2:$F$966,$A6) -> 3 | AK6: =SUMIFS('Исходные данные'!$J$2:$J$966,'Исходные данные'!$D$2:$D$966,AJ$1,'Исходные данные'!$F$2:$F$966,$A6) -> 3 | AL6: =SUMIFS('Исходные данные'!$I$2:$I$966,'Исходные данные'!$D$2:$D$966,AL$1,'Исходные данные'!$F$2:$F$966,$A6) -> 0 | AM6: =SUMIFS('Исходные данные'!$J$2:$J$966,'Исходные данные'!$D$2:$D$966,AL$1,'Исходные данные'!$F$2:$F$966,$A6) -> 0 | AN6: =SUMIFS('Исходные данные'!$I$2:$I$966,'Исходные данные'!$D$2:$D$966,AN$1,'Исходные данные'!$F$2:$F$966,$A6) -> 0 | AO6: =SUMIFS('Исходные данные'!$J$2:$J$966,'Исходные данные'!$D$2:$D$966,AN$1,'Исходные данные'!$F$2:$F$966,$A6) -> 0 | AP6: =SUMIFS('Исходные данные'!$I$2:$I$966,'Исходные данные'!$D$2:$D$966,AP$1,'Исходные данные'!$F$2:$F$966,$A6) -> 0 | AQ6: =SUMIFS('Исходные данные'!$J$2:$J$966,'Исходные данные'!$D$2:$D$966,AP$1,'Исходные данные'!$F$2:$F$966,$A6) -> 0 | AR6: =SUMIFS('Исходные данные'!$I$2:$I$966,'Исходные данные'!$D$2:$D$966,AR$1,'Исходные данные'!$F$2:$F$966,$A6) -> 0 | AS6: =SUMIFS('Исходные данные'!$J$2:$J$966,'Исходные данные'!$D$2:$D$966,AR$1,'Исходные данные'!$F$2:$F$966,$A6) -> 0 | AT6: =SUMIFS('Исходные данные'!$I$2:$I$966,'Исходные данные'!$D$2:$D$966,AT$1,'Исходные данные'!$F$2:$F$966,$A6) -> 0 | AU6: =SUMIFS('Исходные данные'!$J$2:$J$966,'Исходные данные'!$D$2:$D$966,AT$1,'Исходные данные'!$F$2:$F$966,$A6) -> 0 | AV6: =SUMIFS('Исходные данные'!$I$2:$I$966,'Исходные данные'!$D$2:$D$966,AV$1,'Исходные данные'!$F$2:$F$966,$A6) -> 0 | AW6: =SUMIFS('Исходные данные'!$J$2:$J$966,'Исходные данные'!$D$2:$D$966,AV$1,'Исходные данные'!$F$2:$F$966,$A6) -> 0 | AX6: =SUMIFS('Исходные данные'!$I$2:$I$966,'Исходные данные'!$D$2:$D$966,AX$1,'Исходные данные'!$F$2:$F$966,$A6) -> 0 | AY6: =SUMIFS('Исходные данные'!$J$2:$J$966,'Исходные данные'!$D$2:$D$966,AX$1,'Исходные данные'!$F$2:$F$966,$A6) -> 0 | AZ6: =SUMIFS('Исходные данные'!$I$2:$I$966,'Исходные данные'!$D$2:$D$966,AZ$1,'Исходные данные'!$F$2:$F$966,$A6) -> 0 | BA6: =SUMIFS('Исходные данные'!$J$2:$J$966,'Исходные данные'!$D$2:$D$966,AZ$1,'Исходные данные'!$F$2:$F$966,$A6) -> 0 | BB6: =SUMIFS('Исходные данные'!$I$2:$I$966,'Исходные данные'!$D$2:$D$966,BB$1,'Исходные данные'!$F$2:$F$966,$A6) -> 0 | BC6: =SUMIFS('Исходные данные'!$J$2:$J$966,'Исходные данные'!$D$2:$D$966,BB$1,'Исходные данные'!$F$2:$F$966,$A6) -> 0 | BD6: =SUMIFS('Исходные данные'!$I$2:$I$966,'Исходные данные'!$D$2:$D$966,BD$1,'Исходные данные'!$F$2:$F$966,$A6) -> 0 | BE6: =SUMIFS('Исходные данные'!$J$2:$J$966,'Исходные данные'!$D$2:$D$966,BD$1,'Исходные данные'!$F$2:$F$966,$A6) -> 0 | BF6: =SUMIFS('Исходные данные'!$I$2:$I$966,'Исходные данные'!$D$2:$D$966,BF$1,'Исходные данные'!$F$2:$F$966,$A6) -> 0 | BG6: =SUMIFS('Исходные данные'!$J$2:$J$966,'Исходные данные'!$D$2:$D$966,BF$1,'Исходные данные'!$F$2:$F$966,$A6) -> 0 | BH6: =SUMIFS('Исходные данные'!$I$2:$I$966,'Исходные данные'!$D$2:$D$966,BH$1,'Исходные данные'!$F$2:$F$966,$A6) -> 0 | BI6: =SUMIFS('Исходные данные'!$J$2:$J$966,'Исходные данные'!$D$2:$D$966,BH$1,'Исходные данные'!$F$2:$F$966,$A6) -> 0 | BJ6: =SUMIFS('Исходные данные'!$I$2:$I$966,'Исходные данные'!$D$2:$D$966,BJ$1,'Исходные данные'!$F$2:$F$966,$A6) -> 0 | BK6: =SUMIFS('Исходные данные'!$J$2:$J$966,'Исходные данные'!$D$2:$D$966,BJ$1,'Исходные данные'!$F$2:$F$966,$A6) -> 0 | BL6: =SUMIFS('Исходные данные'!$I$2:$I$966,'Исходные данные'!$D$2:$D$966,BL$1,'Исходные данные'!$F$2:$F$966,$A6) -> 0 | BM6: =SUMIFS('Исходные данные'!$J$2:$J$966,'Исходные данные'!$D$2:$D$966,BL$1,'Исходные данные'!$F$2:$F$966,$A6) -> 0 | BN6: =SUMIFS('Исходные данные'!$I$2:$I$966,'Исходные данные'!$D$2:$D$966,BN$1,'Исходные данные'!$F$2:$F$966,$A6) -> 0 | BO6: =SUMIFS('Исходные данные'!$J$2:$J$966,'Исходные данные'!$D$2:$D$966,BN$1,'Исходные данные'!$F$2:$F$966,$A6) -> 0 | BP6: =SUMIFS('Исходные данные'!$I$2:$I$966,'Исходные данные'!$D$2:$D$966,BP$1,'Исходные данные'!$F$2:$F$966,$A6) -> 0 | BQ6: =SUMIFS('Исходные данные'!$J$2:$J$966,'Исходные данные'!$D$2:$D$966,BP$1,'Исходные данные'!$F$2:$F$966,$A6) -> 0 | BR6: =SUMIFS('Исходные данные'!$I$2:$I$966,'Исходные данные'!$D$2:$D$966,BR$1,'Исходные данные'!$F$2:$F$966,$A6) -> 0 | BS6: =SUMIFS('Исходные данные'!$J$2:$J$966,'Исходные данные'!$D$2:$D$966,BR$1,'Исходные данные'!$F$2:$F$966,$A6) -> 0 | BT6: =SUMIFS('Исходные данные'!$I$2:$I$966,'Исходные данные'!$D$2:$D$966,BT$1,'Исходные данные'!$F$2:$F$966,$A6) -> 0 | BU6: =SUMIFS('Исходные данные'!$J$2:$J$966,'Исходные данные'!$D$2:$D$966,BT$1,'Исходные данные'!$F$2:$F$966,$A6) -> 0 | BV6: =SUMIFS('Исходные данные'!$I$2:$I$966,'Исходные данные'!$D$2:$D$966,BV$1,'Исходные данные'!$F$2:$F$966,$A6) -> 0 | BW6: =SUMIFS('Исходные данные'!$J$2:$J$966,'Исходные данные'!$D$2:$D$966,BV$1,'Исходные данные'!$F$2:$F$966,$A6) -> 0 | BX6: =SUMIFS('Исходные данные'!$I$2:$I$966,'Исходные данные'!$D$2:$D$966,BX$1,'Исходные данные'!$F$2:$F$966,$A6) -> 0 | BY6: =SUMIFS('Исходные данные'!$J$2:$J$966,'Исходные данные'!$D$2:$D$966,BX$1,'Исходные данные'!$F$2:$F$966,$A6) -> 0 | BZ6: =SUMIFS('Исходные данные'!$I$2:$I$966,'Исходные данные'!$D$2:$D$966,BZ$1,'Исходные данные'!$F$2:$F$966,$A6) -> 0 | CA6: =SUMIFS('Исходные данные'!$J$2:$J$966,'Исходные данные'!$D$2:$D$966,BZ$1,'Исходные данные'!$F$2:$F$966,$A6) -> 0 | CB6: =SUMIFS('Исходные данные'!$I$2:$I$966,'Исходные данные'!$D$2:$D$966,CB$1,'Исходные данные'!$F$2:$F$966,$A6) -> 0 | CC6: =SUMIFS('Исходные данные'!$J$2:$J$966,'Исходные данные'!$D$2:$D$966,CB$1,'Исходные данные'!$F$2:$F$966,$A6) -> 0 | CD6: =SUMIFS('Исходные данные'!$I$2:$I$966,'Исходные данные'!$D$2:$D$966,CD$1,'Исходные данные'!$F$2:$F$966,$A6) -> 0 | CE6: =SUMIFS('Исходные данные'!$J$2:$J$966,'Исходные данные'!$D$2:$D$966,CD$1,'Исходные данные'!$F$2:$F$966,$A6) -> 0 | CF6: =SUMIFS('Исходные данные'!$I$2:$I$966,'Исходные данные'!$D$2:$D$966,CF$1,'Исходные данные'!$F$2:$F$966,$A6) -> 0 | CG6: =SUMIFS('Исходные данные'!$J$2:$J$966,'Исходные данные'!$D$2:$D$966,CF$1,'Исходные данные'!$F$2:$F$966,$A6) -> 0 | CH6: =SUMIFS('Исходные данные'!$I$2:$I$966,'Исходные данные'!$D$2:$D$966,CH$1,'Исходные данные'!$F$2:$F$966,$A6) -> 0 | CI6: =SUMIFS('Исходные данные'!$J$2:$J$966,'Исходные данные'!$D$2:$D$966,CH$1,'Исходные данные'!$F$2:$F$966,$A6) -> 0 | CJ6: =SUMIFS('Исходные данные'!$I$2:$I$966,'Исходные данные'!$D$2:$D$966,CJ$1,'Исходные данные'!$F$2:$F$966,$A6) -> 0 | CK6: =SUMIFS('Исходные данные'!$J$2:$J$966,'Исходные данные'!$D$2:$D$966,CJ$1,'Исходные данные'!$F$2:$F$966,$A6) -> 0 | CL6: =SUMIFS('Исходные данные'!$I$2:$I$966,'Исходные данные'!$D$2:$D$966,CL$1,'Исходные данные'!$F$2:$F$966,$A6) -> 0 | CM6: =SUMIFS('Исходные данные'!$J$2:$J$966,'Исходные данные'!$D$2:$D$966,CL$1,'Исходные данные'!$F$2:$F$966,$A6) -> 0 | CN6: =SUMIFS('Исходные данные'!$I$2:$I$966,'Исходные данные'!$D$2:$D$966,CN$1,'Исходные данные'!$F$2:$F$966,$A6) -> 0 | CO6: =SUMIFS('Исходные данные'!$J$2:$J$966,'Исходные данные'!$D$2:$D$966,CN$1,'Исходные данные'!$F$2:$F$966,$A6) -> 0 | CP6: =SUMIFS('Исходные данные'!$I$2:$I$966,'Исходные данные'!$D$2:$D$966,CP$1,'Исходные данные'!$F$2:$F$966,$A6) -> 0 | CQ6: =SUMIFS('Исходные данные'!$J$2:$J$966,'Исходные данные'!$D$2:$D$966,CP$1,'Исходные данные'!$F$2:$F$966,$A6) -> 0
A7: 22 | B7: Седельный тягач | C7: 23 | D7: =F7+G7 -> 22 | E7: =D7-C7 -> -1 | F7: =SUMIFS($H7:$CQ7,$H$2:$CQ$2,"День") -> 15 | G7: =SUMIFS($H7:$CQ7,$H$2:$CQ$2,"Ночь") -> 7 | H7: =SUMIFS('Исходные данные'!$I$2:$I$966,'Исходные данные'!$D$2:$D$966,H$1,'Исходные данные'!$F$2:$F$966,$A7) -> 1 | I7: =SUMIFS('Исходные данные'!$J$2:$J$966,'Исходные данные'!$D$2:$D$966,H$1,'Исходные данные'!$F$2:$F$966,$A7) -> 0 | J7: =SUMIFS('Исходные данные'!$I$2:$I$966,'Исходные данные'!$D$2:$D$966,J$1,'Исходные данные'!$F$2:$F$966,$A7) -> 1 | K7: =SUMIFS('Исходные данные'!$J$2:$J$966,'Исходные данные'!$D$2:$D$966,J$1,'Исходные данные'!$F$2:$F$966,$A7) -> 0 | L7: =SUMIFS('Исходные данные'!$I$2:$I$966,'Исходные данные'!$D$2:$D$966,L$1,'Исходные данные'!$F$2:$F$966,$A7) -> 1 | M7: =SUMIFS('Исходные данные'!$J$2:$J$966,'Исходные данные'!$D$2:$D$966,L$1,'Исходные данные'!$F$2:$F$966,$A7) -> 0 | N7: =SUMIFS('Исходные данные'!$I$2:$I$966,'Исходные данные'!$D$2:$D$966,N$1,'Исходные данные'!$F$2:$F$966,$A7) -> 0 | O7: =SUMIFS('Исходные данные'!$J$2:$J$966,'Исходные данные'!$D$2:$D$966,N$1,'Исходные данные'!$F$2:$F$966,$A7) -> 0 | P7: =SUMIFS('Исходные данные'!$I$2:$I$966,'Исходные данные'!$D$2:$D$966,P$1,'Исходные данные'!$F$2:$F$966,$A7) -> 0 | Q7: =SUMIFS('Исходные данные'!$J$2:$J$966,'Исходные данные'!$D$2:$D$966,P$1,'Исходные данные'!$F$2:$F$966,$A7) -> 0 | R7: =SUMIFS('Исходные данные'!$I$2:$I$966,'Исходные данные'!$D$2:$D$966,R$1,'Исходные данные'!$F$2:$F$966,$A7) -> 1 | S7: =SUMIFS('Исходные данные'!$J$2:$J$966,'Исходные данные'!$D$2:$D$966,R$1,'Исходные данные'!$F$2:$F$966,$A7) -> 0 | T7: =SUMIFS('Исходные данные'!$I$2:$I$966,'Исходные данные'!$D$2:$D$966,T$1,'Исходные данные'!$F$2:$F$966,$A7) -> 0 | U7: =SUMIFS('Исходные данные'!$J$2:$J$966,'Исходные данные'!$D$2:$D$966,T$1,'Исходные данные'!$F$2:$F$966,$A7) -> 0 | V7: =SUMIFS('Исходные данные'!$I$2:$I$966,'Исходные данные'!$D$2:$D$966,V$1,'Исходные данные'!$F$2:$F$966,$A7) -> 0 | W7: =SUMIFS('Исходные данные'!$J$2:$J$966,'Исходные данные'!$D$2:$D$966,V$1,'Исходные данные'!$F$2:$F$966,$A7) -> 0 | X7: =SUMIFS('Исходные данные'!$I$2:$I$966,'Исходные данные'!$D$2:$D$966,X$1,'Исходные данные'!$F$2:$F$966,$A7) -> 1 | Y7: =SUMIFS('Исходные данные'!$J$2:$J$966,'Исходные данные'!$D$2:$D$966,X$1,'Исходные данные'!$F$2:$F$966,$A7) -> 0 | Z7: =SUMIFS('Исходные данные'!$I$2:$I$966,'Исходные данные'!$D$2:$D$966,Z$1,'Исходные данные'!$F$2:$F$966,$A7) -> 0 | AA7: =SUMIFS('Исходные данные'!$J$2:$J$966,'Исходные данные'!$D$2:$D$966,Z$1,'Исходные данные'!$F$2:$F$966,$A7) -> 0 | AB7: =SUMIFS('Исходные данные'!$I$2:$I$966,'Исходные данные'!$D$2:$D$966,AB$1,'Исходные данные'!$F$2:$F$966,$A7) -> 0 | AC7: =SUMIFS('Исходные данные'!$J$2:$J$966,'Исходные данные'!$D$2:$D$966,AB$1,'Исходные данные'!$F$2:$F$966,$A7) -> 0 | AD7: =SUMIFS('Исходные данные'!$I$2:$I$966,'Исходные данные'!$D$2:$D$966,AD$1,'Исходные данные'!$F$2:$F$966,$A7) -> 0 | AE7: =SUMIFS('Исходные данные'!$J$2:$J$966,'Исходные данные'!$D$2:$D$966,AD$1,'Исходные данные'!$F$2:$F$966,$A7) -> 0 | AF7: =SUMIFS('Исходные данные'!$I$2:$I$966,'Исходные данные'!$D$2:$D$966,AF$1,'Исходные данные'!$F$2:$F$966,$A7) -> 3 | AG7: =SUMIFS('Исходные данные'!$J$2:$J$966,'Исходные данные'!$D$2:$D$966,AF$1,'Исходные данные'!$F$2:$F$966,$A7) -> 0 | AH7: =SUMIFS('Исходные данные'!$I$2:$I$966,'Исходные данные'!$D$2:$D$966,AH$1,'Исходные данные'!$F$2:$F$966,$A7) -> 4 | AI7: =SUMIFS('Исходные данные'!$J$2:$J$966,'Исходные данные'!$D$2:$D$966,AH$1,'Исходные данные'!$F$2:$F$966,$A7) -> 4 | AJ7: =SUMIFS('Исходные данные'!$I$2:$I$966,'Исходные данные'!$D$2:$D$966,AJ$1,'Исходные данные'!$F$2:$F$966,$A7) -> 3 | AK7: =SUMIFS('Исходные данные'!$J$2:$J$966,'Исходные данные'!$D$2:$D$966,AJ$1,'Исходные данные'!$F$2:$F$966,$A7) -> 3 | AL7: =SUMIFS('Исходные данные'!$I$2:$I$966,'Исходные данные'!$D$2:$D$966,AL$1,'Исходные данные'!$F$2:$F$966,$A7) -> 0 | AM7: =SUMIFS('Исходные данные'!$J$2:$J$966,'Исходные данные'!$D$2:$D$966,AL$1,'Исходные данные'!$F$2:$F$966,$A7) -> 0 | AN7: =SUMIFS('Исходные данные'!$I$2:$I$966,'Исходные данные'!$D$2:$D$966,AN$1,'Исходные данные'!$F$2:$F$966,$A7) -> 0 | AO7: =SUMIFS('Исходные данные'!$J$2:$J$966,'Исходные данные'!$D$2:$D$966,AN$1,'Исходные данные'!$F$2:$F$966,$A7) -> 0 | AP7: =SUMIFS('Исходные данные'!$I$2:$I$966,'Исходные данные'!$D$2:$D$966,AP$1,'Исходные данные'!$F$2:$F$966,$A7) -> 0 | AQ7: =SUMIFS('Исходные данные'!$J$2:$J$966,'Исходные данные'!$D$2:$D$966,AP$1,'Исходные данные'!$F$2:$F$966,$A7) -> 0 | AR7: =SUMIFS('Исходные данные'!$I$2:$I$966,'Исходные данные'!$D$2:$D$966,AR$1,'Исходные данные'!$F$2:$F$966,$A7) -> 0 | AS7: =SUMIFS('Исходные данные'!$J$2:$J$966,'Исходные данные'!$D$2:$D$966,AR$1,'Исходные данные'!$F$2:$F$966,$A7) -> 0 | AT7: =SUMIFS('Исходные данные'!$I$2:$I$966,'Исходные данные'!$D$2:$D$966,AT$1,'Исходные данные'!$F$2:$F$966,$A7) -> 0 | AU7: =SUMIFS('Исходные данные'!$J$2:$J$966,'Исходные данные'!$D$2:$D$966,AT$1,'Исходные данные'!$F$2:$F$966,$A7) -> 0 | AV7: =SUMIFS('Исходные данные'!$I$2:$I$966,'Исходные данные'!$D$2:$D$966,AV$1,'Исходные данные'!$F$2:$F$966,$A7) -> 0 | AW7: =SUMIFS('Исходные данные'!$J$2:$J$966,'Исходные данные'!$D$2:$D$966,AV$1,'Исходные данные'!$F$2:$F$966,$A7) -> 0 | AX7: =SUMIFS('Исходные данные'!$I$2:$I$966,'Исходные данные'!$D$2:$D$966,AX$1,'Исходные данные'!$F$2:$F$966,$A7) -> 0 | AY7: =SUMIFS('Исходные данные'!$J$2:$J$966,'Исходные данные'!$D$2:$D$966,AX$1,'Исходные данные'!$F$2:$F$966,$A7) -> 0 | AZ7: =SUMIFS('Исходные данные'!$I$2:$I$966,'Исходные данные'!$D$2:$D$966,AZ$1,'Исходные данные'!$F$2:$F$966,$A7) -> 0 | BA7: =SUMIFS('Исходные данные'!$J$2:$J$966,'Исходные данные'!$D$2:$D$966,AZ$1,'Исходные данные'!$F$2:$F$966,$A7) -> 0 | BB7: =SUMIFS('Исходные данные'!$I$2:$I$966,'Исходные данные'!$D$2:$D$966,BB$1,'Исходные данные'!$F$2:$F$966,$A7) -> 0 | BC7: =SUMIFS('Исходные данные'!$J$2:$J$966,'Исходные данные'!$D$2:$D$966,BB$1,'Исходные данные'!$F$2:$F$966,$A7) -> 0 | BD7: =SUMIFS('Исходные данные'!$I$2:$I$966,'Исходные данные'!$D$2:$D$966,BD$1,'Исходные данные'!$F$2:$F$966,$A7) -> 0 | BE7: =SUMIFS('Исходные данные'!$J$2:$J$966,'Исходные данные'!$D$2:$D$966,BD$1,'Исходные данные'!$F$2:$F$966,$A7) -> 0 | BF7: =SUMIFS('Исходные данные'!$I$2:$I$966,'Исходные данные'!$D$2:$D$966,BF$1,'Исходные данные'!$F$2:$F$966,$A7) -> 0 | BG7: =SUMIFS('Исходные данные'!$J$2:$J$966,'Исходные данные'!$D$2:$D$966,BF$1,'Исходные данные'!$F$2:$F$966,$A7) -> 0 | BH7: =SUMIFS('Исходные данные'!$I$2:$I$966,'Исходные данные'!$D$2:$D$966,BH$1,'Исходные данные'!$F$2:$F$966,$A7) -> 0 | BI7: =SUMIFS('Исходные данные'!$J$2:$J$966,'Исходные данные'!$D$2:$D$966,BH$1,'Исходные данные'!$F$2:$F$966,$A7) -> 0 | BJ7: =SUMIFS('Исходные данные'!$I$2:$I$966,'Исходные данные'!$D$2:$D$966,BJ$1,'Исходные данные'!$F$2:$F$966,$A7) -> 0 | BK7: =SUMIFS('Исходные данные'!$J$2:$J$966,'Исходные данные'!$D$2:$D$966,BJ$1,'Исходные данные'!$F$2:$F$966,$A7) -> 0 | BL7: =SUMIFS('Исходные данные'!$I$2:$I$966,'Исходные данные'!$D$2:$D$966,BL$1,'Исходные данные'!$F$2:$F$966,$A7) -> 0 | BM7: =SUMIFS('Исходные данные'!$J$2:$J$966,'Исходные данные'!$D$2:$D$966,BL$1,'Исходные данные'!$F$2:$F$966,$A7) -> 0 | BN7: =SUMIFS('Исходные данные'!$I$2:$I$966,'Исходные данные'!$D$2:$D$966,BN$1,'Исходные данные'!$F$2:$F$966,$A7) -> 0 | BO7: =SUMIFS('Исходные данные'!$J$2:$J$966,'Исходные данные'!$D$2:$D$966,BN$1,'Исходные данные'!$F$2:$F$966,$A7) -> 0 | BP7: =SUMIFS('Исходные данные'!$I$2:$I$966,'Исходные данные'!$D$2:$D$966,BP$1,'Исходные данные'!$F$2:$F$966,$A7) -> 0 | BQ7: =SUMIFS('Исходные данные'!$J$2:$J$966,'Исходные данные'!$D$2:$D$966,BP$1,'Исходные данные'!$F$2:$F$966,$A7) -> 0 | BR7: =SUMIFS('Исходные данные'!$I$2:$I$966,'Исходные данные'!$D$2:$D$966,BR$1,'Исходные данные'!$F$2:$F$966,$A7) -> 0 | BS7: =SUMIFS('Исходные данные'!$J$2:$J$966,'Исходные данные'!$D$2:$D$966,BR$1,'Исходные данные'!$F$2:$F$966,$A7) -> 0 | BT7: =SUMIFS('Исходные данные'!$I$2:$I$966,'Исходные данные'!$D$2:$D$966,BT$1,'Исходные данные'!$F$2:$F$966,$A7) -> 0 | BU7: =SUMIFS('Исходные данные'!$J$2:$J$966,'Исходные данные'!$D$2:$D$966,BT$1,'Исходные данные'!$F$2:$F$966,$A7) -> 0 | BV7: =SUMIFS('Исходные данные'!$I$2:$I$966,'Исходные данные'!$D$2:$D$966,BV$1,'Исходные данные'!$F$2:$F$966,$A7) -> 0 | BW7: =SUMIFS('Исходные данные'!$J$2:$J$966,'Исходные данные'!$D$2:$D$966,BV$1,'Исходные данные'!$F$2:$F$966,$A7) -> 0 | BX7: =SUMIFS('Исходные данные'!$I$2:$I$966,'Исходные данные'!$D$2:$D$966,BX$1,'Исходные данные'!$F$2:$F$966,$A7) -> 0 | BY7: =SUMIFS('Исходные данные'!$J$2:$J$966,'Исходные данные'!$D$2:$D$966,BX$1,'Исходные данные'!$F$2:$F$966,$A7) -> 0 | BZ7: =SUMIFS('Исходные данные'!$I$2:$I$966,'Исходные данные'!$D$2:$D$966,BZ$1,'Исходные данные'!$F$2:$F$966,$A7) -> 0 | CA7: =SUMIFS('Исходные данные'!$J$2:$J$966,'Исходные данные'!$D$2:$D$966,BZ$1,'Исходные данные'!$F$2:$F$966,$A7) -> 0 | CB7: =SUMIFS('Исходные данные'!$I$2:$I$966,'Исходные данные'!$D$2:$D$966,CB$1,'Исходные данные'!$F$2:$F$966,$A7) -> 0 | CC7: =SUMIFS('Исходные данные'!$J$2:$J$966,'Исходные данные'!$D$2:$D$966,CB$1,'Исходные данные'!$F$2:$F$966,$A7) -> 0 | CD7: =SUMIFS('Исходные данные'!$I$2:$I$966,'Исходные данные'!$D$2:$D$966,CD$1,'Исходные данные'!$F$2:$F$966,$A7) -> 0 | CE7: =SUMIFS('Исходные данные'!$J$2:$J$966,'Исходные данные'!$D$2:$D$966,CD$1,'Исходные данные'!$F$2:$F$966,$A7) -> 0 | CF7: =SUMIFS('Исходные данные'!$I$2:$I$966,'Исходные данные'!$D$2:$D$966,CF$1,'Исходные данные'!$F$2:$F$966,$A7) -> 0 | CG7: =SUMIFS('Исходные данные'!$J$2:$J$966,'Исходные данные'!$D$2:$D$966,CF$1,'Исходные данные'!$F$2:$F$966,$A7) -> 0 | CH7: =SUMIFS('Исходные данные'!$I$2:$I$966,'Исходные данные'!$D$2:$D$966,CH$1,'Исходные данные'!$F$2:$F$966,$A7) -> 0 | CI7: =SUMIFS('Исходные данные'!$J$2:$J$966,'Исходные данные'!$D$2:$D$966,CH$1,'Исходные данные'!$F$2:$F$966,$A7) -> 0 | CJ7: =SUMIFS('Исходные данные'!$I$2:$I$966,'Исходные данные'!$D$2:$D$966,CJ$1,'Исходные данные'!$F$2:$F$966,$A7) -> 0 | CK7: =SUMIFS('Исходные данные'!$J$2:$J$966,'Исходные данные'!$D$2:$D$966,CJ$1,'Исходные данные'!$F$2:$F$966,$A7) -> 0 | CL7: =SUMIFS('Исходные данные'!$I$2:$I$966,'Исходные данные'!$D$2:$D$966,CL$1,'Исходные данные'!$F$2:$F$966,$A7) -> 0 | CM7: =SUMIFS('Исходные данные'!$J$2:$J$966,'Исходные данные'!$D$2:$D$966,CL$1,'Исходные данные'!$F$2:$F$966,$A7) -> 0 | CN7: =SUMIFS('Исходные данные'!$I$2:$I$966,'Исходные данные'!$D$2:$D$966,CN$1,'Исходные данные'!$F$2:$F$966,$A7) -> 0 | CO7: =SUMIFS('Исходные данные'!$J$2:$J$966,'Исходные данные'!$D$2:$D$966,CN$1,'Исходные данные'!$F$2:$F$966,$A7) -> 0 | CP7: =SUMIFS('Исходные данные'!$I$2:$I$966,'Исходные данные'!$D$2:$D$966,CP$1,'Исходные данные'!$F$2:$F$966,$A7) -> 0 | CQ7: =SUMIFS('Исходные данные'!$J$2:$J$966,'Исходные данные'!$D$2:$D$966,CP$1,'Исходные данные'!$F$2:$F$966,$A7) -> 0
