Workbook

Sheet Ежедневная сводка
A1: Техника құралдарының Цехтарға шығуы | H1: күні 08.10.2026ж.
A3: 1 | I3: Техника | J3: План | K3: Факт | L3: Откл | M3: День | N3: Ночь | O3: ЦДН-1 | P3: ЦДН-2 | Q3: ЦДН-3 | R3: ЦППН | S3: ЦППД | T3: ЭЦ | U3: ОКС | V3: РСЦ | W3: ЦПП | X3: ЦИТС | Y3: ПРЦЭО | Z3: ГЦ | AA3: БМТС | AB3: Бурение | AC3: ЦПКРС-1 | AD3: ЦПКРС-2
A4: 2 | O4: =IF(SUMIFS('Исходные данные'!$I$2:$I$953,'Исходные данные'!$D$2:$D$953,O$3,'Исходные данные'!$F$2:$F$953,$H5&"",'Исходные данные'!$L$2:$L$953,"УТТ")+SUMIFS('Исходные данные'!$J$2:$J$953,'Исходные данные'!$D$2:$D$953,O$3,'Исходные данные'!$F$2:$F$953,$H5&"",'Исходные данные'!$L$2:$L$953,"УТТ")=0,"","утт-"&(SUMIFS('Исходные данные'!$I$2:$I$953,'Исходные данные'!$D$2:$D$953,O$3,'Исходные данные'!$F$2:$F$953,$H5&"",'Исходные данные'!$L$2:$L$953,"УТТ")+SUMIFS('Исходные данные'!$J$2:$J$953,'Исходные данные'!$D$2:$D$953,O$3,'Исходные данные'!$F$2:$F$953,$H5&"",'Исходные данные'!$L$2:$L$953,"УТТ"))) | P4: =IF(SUMIFS('Исходные данные'!$I$2:$I$953,'Исходные данные'!$D$2:$D$953,P$3,'Исходные данные'!$F$2:$F$953,$H5&"",'Исходные данные'!$L$2:$L$953,"УТТ")+SUMIFS('Исходные данные'!$J$2:$J$953,'Исходные данные'!$D$2:$D$953,P$3,'Исходные данные'!$F$2:$F$953,$H5&"",'Исходные данные'!$L$2:$L$953,"УТТ")=0,"","утт-"&(SUMIFS('Исходные данные'!$I$2:$I$953,'Исходные данные'!$D$2:$D$953,P$3,'Исходные данные'!$F$2:$F$953,$H5&"",'Исходные данные'!$L$2:$L$953,"УТТ")+SUMIFS('Исходные данные'!$J$2:$J$953,'Исходные данные'!$D$2:$D$953,P$3,'Исходные данные'!$F$2:$F$953,$H5&"",'Исходные данные'!$L$2:$L$953,"УТТ"))) | Q4: =IF(SUMIFS('Исходные данные'!$I$2:$I$953,'Исходные данные'!$D$2:$D$953,Q$3,'Исходные данные'!$F$2:$F$953,$H5&"",'Исходные данные'!$L$2:$L$953,"УТТ")+SUMIFS('Исходные данные'!$J$2:$J$953,'Исходные данные'!$D$2:$D$953,Q$3,'Исходные данные'!$F$2:$F$953,$H5&"",'Исходные данные'!$L$2:$L$953,"УТТ")=0,"","утт-"&(SUMIFS('Исходные данные'!$I$2:$I$953,'Исходные данные'!$D$2:$D$953,Q$3,'Исходные данные'!$F$2:$F$953,$H5&"",'Исходные данные'!$L$2:$L$953,"УТТ")+SUMIFS('Исходные данные'!$J$2:$J$953,'Исходные данные'!$D$2:$D$953,Q$3,'Исходные данные'!$F$2:$F$953,$H5&"",'Исходные данные'!$L$2:$L$953,"УТТ"))) | R4: =IF(SUMIFS('Исходные данные'!$I$2:$I$953,'Исходные данные'!$D$2:$D$953,R$3,'Исходные данные'!$F$2:$F$953,$H5&"",'Исходные данные'!$L$2:$L$953,"УТТ")+SUMIFS('Исходные данные'!$J$2:$J$953,'Исходные данные'!$D$2:$D$953,R$3,'Исходные данные'!$F$2:$F$953,$H5&"",'Исходные данные'!$L$2:$L$953,"УТТ")=0,"","утт-"&(SUMIFS('Исходные данные'!$I$2:$I$953,'Исходные данные'!$D$2:$D$953,R$3,'Исходные данные'!$F$2:$F$953,$H5&"",'Исходные данные'!$L$2:$L$953,"УТТ")+SUMIFS('Исходные данные'!$J$2:$J$953,'Исходные данные'!$D$2:$D$953,R$3,'Исходные данные'!$F$2:$F$953,$H5&"",'Исходные данные'!$L$2:$L$953,"УТТ"))) | S4: =IF(SUMIFS('Исходные данные'!$I$2:$I$953,'Исходные данные'!$D$2:$D$953,S$3,'Исходные данные'!$F$2:$F$953,$H5&"",'Исходные данные'!$L$2:$L$953,"УТТ")+SUMIFS('Исходные данные'!$J$2:$J$953,'Исходные данные'!$D$2:$D$953,S$3,'Исходные данные'!$F$2:$F$953,$H5&"",'Исходные данные'!$L$2:$L$953,"УТТ")=0,"","утт-"&(SUMIFS('Исходные данные'!$I$2:$I$953,'Исходные данные'!$D$2:$D$953,S$3,'Исходные данные'!$F$2:$F$953,$H5&"",'Исходные данные'!$L$2:$L$953,"УТТ")+SUMIFS('Исходные данные'!$J$2:$J$953,'Исходные данные'!$D$2:$D$953,S$3,'Исходные данные'!$F$2:$F$953,$H5&"",'Исходные данные'!$L$2:$L$953,"УТТ"))) | T4: =IF(SUMIFS('Исходные данные'!$I$2:$I$953,'Исходные данные'!$D$2:$D$953,T$3,'Исходные данные'!$F$2:$F$953,$H5&"",'Исходные данные'!$L$2:$L$953,"УТТ")+SUMIFS('Исходные данные'!$J$2:$J$953,'Исходные данные'!$D$2:$D$953,T$3,'Исходные данные'!$F$2:$F$953,$H5&"",'Исходные данные'!$L$2:$L$953,"УТТ")=0,"","утт-"&(SUMIFS('Исходные данные'!$I$2:$I$953,'Исходные данные'!$D$2:$D$953,T$3,'Исходные данные'!$F$2:$F$953,$H5&"",'Исходные данные'!$L$2:$L$953,"УТТ")+SUMIFS('Исходные данные'!$J$2:$J$953,'Исходные данные'!$D$2:$D$953,T$3,'Исходные данные'!$F$2:$F$953,$H5&"",'Исходные данные'!$L$2:$L$953,"УТТ"))) | U4: =IF(SUMIFS('Исходные данные'!$I$2:$I$953,'Исходные данные'!$D$2:$D$953,U$3,'Исходные данные'!$F$2:$F$953,$H5&"",'Исходные данные'!$L$2:$L$953,"УТТ")+SUMIFS('Исходные данные'!$J$2:$J$953,'Исходные данные'!$D$2:$D$953,U$3,'Исходные данные'!$F$2:$F$953,$H5&"",'Исходные данные'!$L$2:$L$953,"УТТ")=0,"","утт-"&(SUMIFS('Исходные данные'!$I$2:$I$953,'Исходные данные'!$D$2:$D$953,U$3,'Исходные данные'!$F$2:$F$953,$H5&"",'Исходные данные'!$L$2:$L$953,"УТТ")+SUMIFS('Исходные данные'!$J$2:$J$953,'Исходные данные'!$D$2:$D$953,U$3,'Исходные данные'!$F$2:$F$953,$H5&"",'Исходные данные'!$L$2:$L$953,"УТТ"))) | V4: =IF(SUMIFS('Исходные данные'!$I$2:$I$953,'Исходные данные'!$D$2:$D$953,V$3,'Исходные данные'!$F$2:$F$953,$H5&"",'Исходные данные'!$L$2:$L$953,"УТТ")+SUMIFS('Исходные данные'!$J$2:$J$953,'Исходные данные'!$D$2:$D$953,V$3,'Исходные данные'!$F$2:$F$953,$H5&"",'Исходные данные'!$L$2:$L$953,"УТТ")=0,"","утт-"&(SUMIFS('Исходные данные'!$I$2:$I$953,'Исходные данные'!$D$2:$D$953,V$3,'Исходные данные'!$F$2:$F$953,$H5&"",'Исходные данные'!$L$2:$L$953,"УТТ")+SUMIFS('Исходные данные'!$J$2:$J$953,'Исходные данные'!$D$2:$D$953,V$3,'Исходные данные'!$F$2:$F$953,$H5&"",'Исходные данные'!$L$2:$L$953,"УТТ"))) | ... AA4: =IF(SUMIFS('Исходные данные'!$I$2:$I$953,'Исходные данные'!$D$2:$D$953,AA$3,'Исходные данные'!$F$2:$F$953,$H5&"",'Исходные данные'!$L$2:$L$953,"УТТ")+SUMIFS('Исходные данные'!$J$2:$J$953,'Исходные данные'!$D$2:$D$953,AA$3,'Исходные данные'!$F$2:$F$953,$H5&"",'Исходные данные'!$L$2:$L$953,"УТТ")=0,"","утт-"&(SUMIFS('Исходные данные'!$I$2:$I$953,'Исходные данные'!$D$2:$D$953,AA$3,'Исходные данные'!$F$2:$F$953,$H5&"",'Исходные данные'!$L$2:$L$953,"УТТ")+SUMIFS('Исходные данные'!$J$2:$J$953,'Исходные данные'!$D$2:$D$953,AA$3,'Исходные данные'!$F$2:$F$953,$H5&"",'Исходные данные'!$L$2:$L$953,"УТТ"))) | AC4: =IF(SUMIFS('Исходные данные'!$I$2:$I$953,'Исходные данные'!$D$2:$D$953,AC$3,'Исходные данные'!$F$2:$F$953,$H5&"",'Исходные данные'!$L$2:$L$953,"УТТ")+SUMIFS('Исходные данные'!$J$2:$J$953,'Исходные данные'!$D$2:$D$953,AC$3,'Исходные данные'!$F$2:$F$953,$H5&"",'Исходные данные'!$L$2:$L$953,"УТТ")=0,"","утт-"&(SUMIFS('Исходные данные'!$I$2:$I$953,'Исходные данные'!$D$2:$D$953,AC$3,'Исходные данные'!$F$2:$F$953,$H5&"",'Исходные данные'!$L$2:$L$953,"УТТ")+SUMIFS('Исходные данные'!$J$2:$J$953,'Исходные данные'!$D$2:$D$953,AC$3,'Исходные данные'!$F$2:$F$953,$H5&"",'Исходные данные'!$L$2:$L$953,"УТТ"))) | AD4: =IF(SUMIFS('Исходные данные'!$I$2:$I$953,'Исходные данные'!$D$2:$D$953,AD$3,'Исходные данные'!$F$2:$F$953,$H5&"",'Исходные данные'!$L$2:$L$953,"УТТ")+SUMIFS('Исходные данные'!$J$2:$J$953,'Исходные данные'!$D$2:$D$953,AD$3,'Исходные данные'!$F$2:$F$953,$H5&"",'Исходные данные'!$L$2:$L$953,"УТТ")=0,"","утт-"&(SUMIFS('Исходные данные'!$I$2:$I$953,'Исходные данные'!$D$2:$D$953,AD$3,'Исходные данные'!$F$2:$F$953,$H5&"",'Исходные данные'!$L$2:$L$953,"УТТ")+SUMIFS('Исходные данные'!$J$2:$J$953,'Исходные данные'!$D$2:$D$953,AD$3,'Исходные данные'!$F$2:$F$953,$H5&"",'Исходные данные'!$L$2:$L$953,"УТТ")))
A5: 3 | H5: 34 | I5: ППУ | J5: =IFERROR(INDEX('Выход ТС'!$C:$C,MATCH($H5&"",'Выход ТС'!$A:$A,0)),"") | K5: =IFERROR(INDEX('Выход ТС'!$D:$D,MATCH($H5&"",'Выход ТС'!$A:$A,0)),"") | L5: =IFERROR(INDEX('Выход ТС'!$E:$E,MATCH($H5&"",'Выход ТС'!$A:$A,0)),"") | M5: =IFERROR(IF(INDEX('Выход ТС'!$F:$F,MATCH($H5&"",'Выход ТС'!$A:$A,0))=0,"",INDEX('Выход ТС'!$F:$F,MATCH($H5&"",'Выход ТС'!$A:$A,0))),"") | N5: =IFERROR(IF(INDEX('Выход ТС'!$G:$G,MATCH($H5&"",'Выход ТС'!$A:$A,0))=0,"",INDEX('Выход ТС'!$G:$G,MATCH($H5&"",'Выход ТС'!$A:$A,0))),"") | O5: =IF(SUMIFS('Исходные данные'!$I$2:$I$953,'Исходные данные'!$D$2:$D$953,O$3,'Исходные данные'!$F$2:$F$953,$H5&"")+SUMIFS('Исходные данные'!$J$2:$J$953,'Исходные данные'!$D$2:$D$953,O$3,'Исходные данные'!$F$2:$F$953,$H5&"")=0,"",IF(SUMIFS('Исходные данные'!$J$2:$J$953,'Исходные данные'!$D$2:$D$953,O$3,'Исходные данные'!$F$2:$F$953,$H5&"")=0,SUMIFS('Исходные данные'!$I$2:$I$953,'Исходные данные'!$D$2:$D$953,O$3,'Исходные данные'!$F$2:$F$953,$H5&""),IF(SUMIFS('Исходные данные'!$I$2:$I$953,'Исходные данные'!$D$2:$D$953,O$3,'Исходные данные'!$F$2:$F$953,$H5&"")=0,"0+"&SUMIFS('Исходные данные'!$J$2:$J$953,'Исходные данные'!$D$2:$D$953,O$3,'Исходные данные'!$F$2:$F$953,$H5&"")&"="&SUMIFS('Исходные данные'!$J$2:$J$953,'Исходные данные'!$D$2:$D$953,O$3,'Исходные данные'!$F$2:$F$953,$H5&""),SUMIFS('Исходные данные'!$I$2:$I$953,'Исходные данные'!$D$2:$D$953,O$3,'Исходные данные'!$F$2:$F$953,$H5&"")&"+"&SUMIFS('Исходные данные'!$J$2:$J$953,'Исходные данные'!$D$2:$D$953,O$3,'Исходные данные'!$F$2:$F$953,$H5&"")&"="&(SUMIFS('Исходные данные'!$I$2:$I$953,'Исходные данные'!$D$2:$D$953,O$3,'Исходные данные'!$F$2:$F$953,$H5&"")+SUMIFS('Исходные данные'!$J$2:$J$953,'Исходные данные'!$D$2:$D$953,O$3,'Исходные данные'!$F$2:$F$953,$H5&""))))) | P5: =IF(SUMIFS('Исходные данные'!$I$2:$I$953,'Исходные данные'!$D$2:$D$953,P$3,'Исходные данные'!$F$2:$F$953,$H5&"")+SUMIFS('Исходные данные'!$J$2:$J$953,'Исходные данные'!$D$2:$D$953,P$3,'Исходные данные'!$F$2:$F$953,$H5&"")=0,"",IF(SUMIFS('Исходные данные'!$J$2:$J$953,'Исходные данные'!$D$2:$D$953,P$3,'Исходные данные'!$F$2:$F$953,$H5&"")=0,SUMIFS('Исходные данные'!$I$2:$I$953,'Исходные данные'!$D$2:$D$953,P$3,'Исходные данные'!$F$2:$F$953,$H5&""),IF(SUMIFS('Исходные данные'!$I$2:$I$953,'Исходные данные'!$D$2:$D$953,P$3,'Исходные данные'!$F$2:$F$953,$H5&"")=0,"0+"&SUMIFS('Исходные данные'!$J$2:$J$953,'Исходные данные'!$D$2:$D$953,P$3,'Исходные данные'!$F$2:$F$953,$H5&"")&"="&SUMIFS('Исходные данные'!$J$2:$J$953,'Исходные данные'!$D$2:$D$953,P$3,'Исходные данные'!$F$2:$F$953,$H5&""),SUMIFS('Исходные данные'!$I$2:$I$953,'Исходные данные'!$D$2:$D$953,P$3,'Исходные данные'!$F$2:$F$953,$H5&"")&"+"&SUMIFS('Исходные данные'!$J$2:$J$953,'Исходные данные'!$D$2:$D$953,P$3,'Исходные данные'!$F$2:$F$953,$H5&"")&"="&(SUMIFS('Исходные данные'!$I$2:$I$953,'Исходные данные'!$D$2:$D$953,P$3,'Исходные данные'!$F$2:$F$953,$H5&"")+SUMIFS('Исходные данные'!$J$2:$J$953,'Исходные данные'!$D$2:$D$953,P$3,'Исходные данные'!$F$2:$F$953,$H5&""))))) | Q5: =IF(SUMIFS('Исходные данные'!$I$2:$I$953,'Исходные данные'!$D$2:$D$953,Q$3,'Исходные данные'!$F$2:$F$953,$H5&"")+SUMIFS('Исходные данные'!$J$2:$J$953,'Исходные данные'!$D$2:$D$953,Q$3,'Исходные данные'!$F$2:$F$953,$H5&"")=0,"",IF(SUMIFS('Исходные данные'!$J$2:$J$953,'Исходные данные'!$D$2:$D$953,Q$3,'Исходные данные'!$F$2:$F$953,$H5&"")=0,SUMIFS('Исходные данные'!$I$2:$I$953,'Исходные данные'!$D$2:$D$953,Q$3,'Исходные данные'!$F$2:$F$953,$H5&""),IF(SUMIFS('Исходные данные'!$I$2:$I$953,'Исходные данные'!$D$2:$D$953,Q$3,'Исходные данные'!$F$2:$F$953,$H5&"")=0,"0+"&SUMIFS('Исходные данные'!$J$2:$J$953,'Исходные данные'!$D$2:$D$953,Q$3,'Исходные данные'!$F$2:$F$953,$H5&"")&"="&SUMIFS('Исходные данные'!$J$2:$J$953,'Исходные данные'!$D$2:$D$953,Q$3,'Исходные данные'!$F$2:$F$953,$H5&""),SUMIFS('Исходные данные'!$I$2:$I$953,'Исходные данные'!$D$2:$D$953,Q$3,'Исходные данные'!$F$2:$F$953,$H5&"")&"+"&SUMIFS('Исходные данные'!$J$2:$J$953,'Исходные данные'!$D$2:$D$953,Q$3,'Исходные данные'!$F$2:$F$953,$H5&"")&"="&(SUMIFS('Исходные данные'!$I$2:$I$953,'Исходные данные'!$D$2:$D$953,Q$3,'Исходные данные'!$F$2:$F$953,$H5&"")+SUMIFS('Исходные данные'!$J$2:$J$953,'Исходные данные'!$D$2:$D$953,Q$3,'Исходные данные'!$F$2:$F$953,$H5&""))))) | R5: =IF(SUMIFS('Исходные данные'!$I$2:$I$953,'Исходные данные'!$D$2:$D$953,R$3,'Исходные данные'!$F$2:$F$953,$H5&"")+SUMIFS('Исходные данные'!$J$2:$J$953,'Исходные данные'!$D$2:$D$953,R$3,'Исходные данные'!$F$2:$F$953,$H5&"")=0,"",IF(SUMIFS('Исходные данные'!$J$2:$J$953,'Исходные данные'!$D$2:$D$953,R$3,'Исходные данные'!$F$2:$F$953,$H5&"")=0,SUMIFS('Исходные данные'!$I$2:$I$953,'Исходные данные'!$D$2:$D$953,R$3,'Исходные данные'!$F$2:$F$953,$H5&""),IF(SUMIFS('Исходные данные'!$I$2:$I$953,'Исходные данные'!$D$2:$D$953,R$3,'Исходные данные'!$F$2:$F$953,$H5&"")=0,"0+"&SUMIFS('Исходные данные'!$J$2:$J$953,'Исходные данные'!$D$2:$D$953,R$3,'Исходные данные'!$F$2:$F$953,$H5&"")&"="&SUMIFS('Исходные данные'!$J$2:$J$953,'Исходные данные'!$D$2:$D$953,R$3,'Исходные данные'!$F$2:$F$953,$H5&""),SUMIFS('Исходные данные'!$I$2:$I$953,'Исходные данные'!$D$2:$D$953,R$3,'Исходные данные'!$F$2:$F$953,$H5&"")&"+"&SUMIFS('Исходные данные'!$J$2:$J$953,'Исходные данные'!$D$2:$D$953,R$3,'Исходные данные'!$F$2:$F$953,$H5&"")&"="&(SUMIFS('Исходные данные'!$I$2:$I$953,'Исходные данные'!$D$2:$D$953,R$3,'Исходные данные'!$F$2:$F$953,$H5&"")+SUMIFS('Исходные данные'!$J$2:$J$953,'Исходные данные'!$D$2:$D$953,R$3,'Исходные данные'!$F$2:$F$953,$H5&""))))) | S5: =IF(SUMIFS('Исходные данные'!$I$2:$I$953,'Исходные данные'!$D$2:$D$953,S$3,'Исходные данные'!$F$2:$F$953,$H5&"")+SUMIFS('Исходные данные'!$J$2:$J$953,'Исходные данные'!$D$2:$D$953,S$3,'Исходные данные'!$F$2:$F$953,$H5&"")=0,"",IF(SUMIFS('Исходные данные'!$J$2:$J$953,'Исходные данные'!$D$2:$D$953,S$3,'Исходные данные'!$F$2:$F$953,$H5&"")=0,SUMIFS('Исходные данные'!$I$2:$I$953,'Исходные данные'!$D$2:$D$953,S$3,'Исходные данные'!$F$2:$F$953,$H5&""),IF(SUMIFS('Исходные данные'!$I$2:$I$953,'Исходные данные'!$D$2:$D$953,S$3,'Исходные данные'!$F$2:$F$953,$H5&"")=0,"0+"&SUMIFS('Исходные данные'!$J$2:$J$953,'Исходные данные'!$D$2:$D$953,S$3,'Исходные данные'!$F$2:$F$953,$H5&"")&"="&SUMIFS('Исходные данные'!$J$2:$J$953,'Исходные данные'!$D$2:$D$953,S$3,'Исходные данные'!$F$2:$F$953,$H5&""),SUMIFS('Исходные данные'!$I$2:$I$953,'Исходные данные'!$D$2:$D$953,S$3,'Исходные данные'!$F$2:$F$953,$H5&"")&"+"&SUMIFS('Исходные данные'!$J$2:$J$953,'Исходные данные'!$D$2:$D$953,S$3,'Исходные данные'!$F$2:$F$953,$H5&"")&"="&(SUMIFS('Исходные данные'!$I$2:$I$953,'Исходные данные'!$D$2:$D$953,S$3,'Исходные данные'!$F$2:$F$953,$H5&"")+SUMIFS('Исходные данные'!$J$2:$J$953,'Исходные данные'!$D$2:$D$953,S$3,'Исходные данные'!$F$2:$F$953,$H5&""))))) | T5: =IF(SUMIFS('Исходные данные'!$I$2:$I$953,'Исходные данные'!$D$2:$D$953,T$3,'Исходные данные'!$F$2:$F$953,$H5&"")+SUMIFS('Исходные данные'!$J$2:$J$953,'Исходные данные'!$D$2:$D$953,T$3,'Исходные данные'!$F$2:$F$953,$H5&"")=0,"",IF(SUMIFS('Исходные данные'!$J$2:$J$953,'Исходные данные'!$D$2:$D$953,T$3,'Исходные данные'!$F$2:$F$953,$H5&"")=0,SUMIFS('Исходные данные'!$I$2:$I$953,'Исходные данные'!$D$2:$D$953,T$3,'Исходные данные'!$F$2:$F$953,$H5&""),IF(SUMIFS('Исходные данные'!$I$2:$I$953,'Исходные данные'!$D$2:$D$953,T$3,'Исходные данные'!$F$2:$F$953,$H5&"")=0,"0+"&SUMIFS('Исходные данные'!$J$2:$J$953,'Исходные данные'!$D$2:$D$953,T$3,'Исходные данные'!$F$2:$F$953,$H5&"")&"="&SUMIFS('Исходные данные'!$J$2:$J$953,'Исходные данные'!$D$2:$D$953,T$3,'Исходные данные'!$F$2:$F$953,$H5&""),SUMIFS('Исходные данные'!$I$2:$I$953,'Исходные данные'!$D$2:$D$953,T$3,'Исходные данные'!$F$2:$F$953,$H5&"")&"+"&SUMIFS('Исходные данные'!$J$2:$J$953,'Исходные данные'!$D$2:$D$953,T$3,'Исходные данные'!$F$2:$F$953,$H5&"")&"="&(SUMIFS('Исходные данные'!$I$2:$I$953,'Исходные данные'!$D$2:$D$953,T$3,'Исходные данные'!$F$2:$F$953,$H5&"")+SUMIFS('Исходные данные'!$J$2:$J$953,'Исходные данные'!$D$2:$D$953,T$3,'Исходные данные'!$F$2:$F$953,$H5&""))))) | U5: =IF(SUMIFS('Исходные данные'!$I$2:$I$953,'Исходные данные'!$D$2:$D$953,U$3,'Исходные данные'!$F$2:$F$953,$H5&"")+SUMIFS('Исходные данные'!$J$2:$J$953,'Исходные данные'!$D$2:$D$953,U$3,'Исходные данные'!$F$2:$F$953,$H5&"")=0,"",IF(SUMIFS('Исходные данные'!$J$2:$J$953,'Исходные данные'!$D$2:$D$953,U$3,'Исходные данные'!$F$2:$F$953,$H5&"")=0,SUMIFS('Исходные данные'!$I$2:$I$953,'Исходные данные'!$D$2:$D$953,U$3,'Исходные данные'!$F$2:$F$953,$H5&""),IF(SUMIFS('Исходные данные'!$I$2:$I$953,'Исходные данные'!$D$2:$D$953,U$3,'Исходные данные'!$F$2:$F$953,$H5&"")=0,"0+"&SUMIFS('Исходные данные'!$J$2:$J$953,'Исходные данные'!$D$2:$D$953,U$3,'Исходные данные'!$F$2:$F$953,$H5&"")&"="&SUMIFS('Исходные данные'!$J$2:$J$953,'Исходные данные'!$D$2:$D$953,U$3,'Исходные данные'!$F$2:$F$953,$H5&""),SUMIFS('Исходные данные'!$I$2:$I$953,'Исходные данные'!$D$2:$D$953,U$3,'Исходные данные'!$F$2:$F$953,$H5&"")&"+"&SUMIFS('Исходные данные'!$J$2:$J$953,'Исходные данные'!$D$2:$D$953,U$3,'Исходные данные'!$F$2:$F$953,$H5&"")&"="&(SUMIFS('Исходные данные'!$I$2:$I$953,'Исходные данные'!$D$2:$D$953,U$3,'Исходные данные'!$F$2:$F$953,$H5&"")+SUMIFS('Исходные данные'!$J$2:$J$953,'Исходные данные'!$D$2:$D$953,U$3,'Исходные данные'!$F$2:$F$953,$H5&""))))) | V5: =IF(SUMIFS('Исходные данные'!$I$2:$I$953,'Исходные данные'!$D$2:$D$953,V$3,'Исходные данные'!$F$2:$F$953,$H5&"")+SUMIFS('Исходные данные'!$J$2:$J$953,'Исходные данные'!$D$2:$D$953,V$3,'Исходные данные'!$F$2:$F$953,$H5&"")=0,"",IF(SUMIFS('Исходные данные'!$J$2:$J$953,'Исходные данные'!$D$2:$D$953,V$3,'Исходные данные'!$F$2:$F$953,$H5&"")=0,SUMIFS('Исходные данные'!$I$2:$I$953,'Исходные данные'!$D$2:$D$953,V$3,'Исходные данные'!$F$2:$F$953,$H5&""),IF(SUMIFS('Исходные данные'!$I$2:$I$953,'Исходные данные'!$D$2:$D$953,V$3,'Исходные данные'!$F$2:$F$953,$H5&"")=0,"0+"&SUMIFS('Исходные данные'!$J$2:$J$953,'Исходные данные'!$D$2:$D$953,V$3,'Исходные данные'!$F$2:$F$953,$H5&"")&"="&SUMIFS('Исходные данные'!$J$2:$J$953,'Исходные данные'!$D$2:$D$953,V$3,'Исходные данные'!$F$2:$F$953,$H5&""),SUMIFS('Исходные данные'!$I$2:$I$953,'Исходные данные'!$D$2:$D$953,V$3,'Исходные данные'!$F$2:$F$953,$H5&"")&"+"&SUMIFS('Исходные данные'!$J$2:$J$953,'Исходные данные'!$D$2:$D$953,V$3,'Исходные данные'!$F$2:$F$953,$H5&"")&"="&(SUMIFS('Исходные данные'!$I$2:$I$953,'Исходные данные'!$D$2:$D$953,V$3,'Исходные данные'!$F$2:$F$953,$H5&"")+SUMIFS('Исходные данные'!$J$2:$J$953,'Исходные данные'!$D$2:$D$953,V$3,'Исходные данные'!$F$2:$F$953,$H5&""))))) | ... AA5: =IF(SUMIFS('Исходные данные'!$I$2:$I$953,'Исходные данные'!$D$2:$D$953,AA$3,'Исходные данные'!$F$2:$F$953,$H5&"")+SUMIFS('Исходные данные'!$J$2:$J$953,'Исходные данные'!$D$2:$D$953,AA$3,'Исходные данные'!$F$2:$F$953,$H5&"")=0,"",IF(SUMIFS('Исходные данные'!$J$2:$J$953,'Исходные данные'!$D$2:$D$953,AA$3,'Исходные данные'!$F$2:$F$953,$H5&"")=0,SUMIFS('Исходные данные'!$I$2:$I$953,'Исходные данные'!$D$2:$D$953,AA$3,'Исходные данные'!$F$2:$F$953,$H5&""),IF(SUMIFS('Исходные данные'!$I$2:$I$953,'Исходные данные'!$D$2:$D$953,AA$3,'Исходные данные'!$F$2:$F$953,$H5&"")=0,"0+"&SUMIFS('Исходные данные'!$J$2:$J$953,'Исходные данные'!$D$2:$D$953,AA$3,'Исходные данные'!$F$2:$F$953,$H5&"")&"="&SUMIFS('Исходные данные'!$J$2:$J$953,'Исходные данные'!$D$2:$D$953,AA$3,'Исходные данные'!$F$2:$F$953,$H5&""),SUMIFS('Исходные данные'!$I$2:$I$953,'Исходные данные'!$D$2:$D$953,AA$3,'Исходные данные'!$F$2:$F$953,$H5&"")&"+"&SUMIFS('Исходные данные'!$J$2:$J$953,'Исходные данные'!$D$2:$D$953,AA$3,'Исходные данные'!$F$2:$F$953,$H5&"")&"="&(SUMIFS('Исходные данные'!$I$2:$I$953,'Исходные данные'!$D$2:$D$953,AA$3,'Исходные данные'!$F$2:$F$953,$H5&"")+SUMIFS('Исходные данные'!$J$2:$J$953,'Исходные данные'!$D$2:$D$953,AA$3,'Исходные данные'!$F$2:$F$953,$H5&""))))) | AC5: =IF(SUMIFS('Исходные данные'!$I$2:$I$953,'Исходные данные'!$D$2:$D$953,AC$3,'Исходные данные'!$F$2:$F$953,$H5&"")+SUMIFS('Исходные данные'!$J$2:$J$953,'Исходные данные'!$D$2:$D$953,AC$3,'Исходные данные'!$F$2:$F$953,$H5&"")=0,"",IF(SUMIFS('Исходные данные'!$J$2:$J$953,'Исходные данные'!$D$2:$D$953,AC$3,'Исходные данные'!$F$2:$F$953,$H5&"")=0,SUMIFS('Исходные данные'!$I$2:$I$953,'Исходные данные'!$D$2:$D$953,AC$3,'Исходные данные'!$F$2:$F$953,$H5&""),IF(SUMIFS('Исходные данные'!$I$2:$I$953,'Исходные данные'!$D$2:$D$953,AC$3,'Исходные данные'!$F$2:$F$953,$H5&"")=0,"0+"&SUMIFS('Исходные данные'!$J$2:$J$953,'Исходные данные'!$D$2:$D$953,AC$3,'Исходные данные'!$F$2:$F$953,$H5&"")&"="&SUMIFS('Исходные данные'!$J$2:$J$953,'Исходные данные'!$D$2:$D$953,AC$3,'Исходные данные'!$F$2:$F$953,$H5&""),SUMIFS('Исходные данные'!$I$2:$I$953,'Исходные данные'!$D$2:$D$953,AC$3,'Исходные данные'!$F$2:$F$953,$H5&"")&"+"&SUMIFS('Исходные данные'!$J$2:$J$953,'Исходные данные'!$D$2:$D$953,AC$3,'Исходные данные'!$F$2:$F$953,$H5&"")&"="&(SUMIFS('Исходные данные'!$I$2:$I$953,'Исходные данные'!$D$2:$D$953,AC$3,'Исходные данные'!$F$2:$F$953,$H5&"")+SUMIFS('Исходные данные'!$J$2:$J$953,'Исходные данные'!$D$2:$D$953,AC$3,'Исходные данные'!$F$2:$F$953,$H5&""))))) | AD5: =IF(SUMIFS('Исходные данные'!$I$2:$I$953,'Исходные данные'!$D$2:$D$953,AD$3,'Исходные данные'!$F$2:$F$953,$H5&"")+SUMIFS('Исходные данные'!$J$2:$J$953,'Исходные данные'!$D$2:$D$953,AD$3,'Исходные данные'!$F$2:$F$953,$H5&"")=0,"",IF(SUMIFS('Исходные данные'!$J$2:$J$953,'Исходные данные'!$D$2:$D$953,AD$3,'Исходные данные'!$F$2:$F$953,$H5&"")=0,SUMIFS('Исходные данные'!$I$2:$I$953,'Исходные данные'!$D$2:$D$953,AD$3,'Исходные данные'!$F$2:$F$953,$H5&""),IF(SUMIFS('Исходные данные'!$I$2:$I$953,'Исходные данные'!$D$2:$D$953,AD$3,'Исходные данные'!$F$2:$F$953,$H5&"")=0,"0+"&SUMIFS('Исходные данные'!$J$2:$J$953,'Исходные данные'!$D$2:$D$953,AD$3,'Исходные данные'!$F$2:$F$953,$H5&"")&"="&SUMIFS('Исходные данные'!$J$2:$J$953,'Исходные данные'!$D$2:$D$953,AD$3,'Исходные данные'!$F$2:$F$953,$H5&""),SUMIFS('Исходные данные'!$I$2:$I$953,'Исходные данные'!$D$2:$D$953,AD$3,'Исходные данные'!$F$2:$F$953,$H5&"")&"+"&SUMIFS('Исходные данные'!$J$2:$J$953,'Исходные данные'!$D$2:$D$953,AD$3,'Исходные данные'!$F$2:$F$953,$H5&"")&"="&(SUMIFS('Исходные данные'!$I$2:$I$953,'Исходные данные'!$D$2:$D$953,AD$3,'Исходные данные'!$F$2:$F$953,$H5&"")+SUMIFS('Исходные данные'!$J$2:$J$953,'Исходные данные'!$D$2:$D$953,AD$3,'Исходные данные'!$F$2:$F$953,$H5&"")))))
A6: 4 | O6: =IF(SUMIFS('Исходные данные'!$I$2:$I$953,'Исходные данные'!$D$2:$D$953,O$3,'Исходные данные'!$F$2:$F$953,$H7&"",'Исходные данные'!$L$2:$L$953,"УТТ")+SUMIFS('Исходные данные'!$J$2:$J$953,'Исходные данные'!$D$2:$D$953,O$3,'Исходные данные'!$F$2:$F$953,$H7&"",'Исходные данные'!$L$2:$L$953,"УТТ")=0,"","утт-"&(SUMIFS('Исходные данные'!$I$2:$I$953,'Исходные данные'!$D$2:$D$953,O$3,'Исходные данные'!$F$2:$F$953,$H7&"",'Исходные данные'!$L$2:$L$953,"УТТ")+SUMIFS('Исходные данные'!$J$2:$J$953,'Исходные данные'!$D$2:$D$953,O$3,'Исходные данные'!$F$2:$F$953,$H7&"",'Исходные данные'!$L$2:$L$953,"УТТ"))) | P6: =IF(SUMIFS('Исходные данные'!$I$2:$I$953,'Исходные данные'!$D$2:$D$953,P$3,'Исходные данные'!$F$2:$F$953,$H7&"",'Исходные данные'!$L$2:$L$953,"УТТ")+SUMIFS('Исходные данные'!$J$2:$J$953,'Исходные данные'!$D$2:$D$953,P$3,'Исходные данные'!$F$2:$F$953,$H7&"",'Исходные данные'!$L$2:$L$953,"УТТ")=0,"","утт-"&(SUMIFS('Исходные данные'!$I$2:$I$953,'Исходные данные'!$D$2:$D$953,P$3,'Исходные данные'!$F$2:$F$953,$H7&"",'Исходные данные'!$L$2:$L$953,"УТТ")+SUMIFS('Исходные данные'!$J$2:$J$953,'Исходные данные'!$D$2:$D$953,P$3,'Исходные данные'!$F$2:$F$953,$H7&"",'Исходные данные'!$L$2:$L$953,"УТТ"))) | Q6: =IF(SUMIFS('Исходные данные'!$I$2:$I$953,'Исходные данные'!$D$2:$D$953,Q$3,'Исходные данные'!$F$2:$F$953,$H7&"",'Исходные данные'!$L$2:$L$953,"УТТ")+SUMIFS('Исходные данные'!$J$2:$J$953,'Исходные данные'!$D$2:$D$953,Q$3,'Исходные данные'!$F$2:$F$953,$H7&"",'Исходные данные'!$L$2:$L$953,"УТТ")=0,"","утт-"&(SUMIFS('Исходные данные'!$I$2:$I$953,'Исходные данные'!$D$2:$D$953,Q$3,'Исходные данные'!$F$2:$F$953,$H7&"",'Исходные данные'!$L$2:$L$953,"УТТ")+SUMIFS('Исходные данные'!$J$2:$J$953,'Исходные данные'!$D$2:$D$953,Q$3,'Исходные данные'!$F$2:$F$953,$H7&"",'Исходные данные'!$L$2:$L$953,"УТТ"))) | R6: =IF(SUMIFS('Исходные данные'!$I$2:$I$953,'Исходные данные'!$D$2:$D$953,R$3,'Исходные данные'!$F$2:$F$953,$H7&"",'Исходные данные'!$L$2:$L$953,"УТТ")+SUMIFS('Исходные данные'!$J$2:$J$953,'Исходные данные'!$D$2:$D$953,R$3,'Исходные данные'!$F$2:$F$953,$H7&"",'Исходные данные'!$L$2:$L$953,"УТТ")=0,"","утт-"&(SUMIFS('Исходные данные'!$I$2:$I$953,'Исходные данные'!$D$2:$D$953,R$3,'Исходные данные'!$F$2:$F$953,$H7&"",'Исходные данные'!$L$2:$L$953,"УТТ")+SUMIFS('Исходные данные'!$J$2:$J$953,'Исходные данные'!$D$2:$D$953,R$3,'Исходные данные'!$F$2:$F$953,$H7&"",'Исходные данные'!$L$2:$L$953,"УТТ"))) | S6: =IF(SUMIFS('Исходные данные'!$I$2:$I$953,'Исходные данные'!$D$2:$D$953,S$3,'Исходные данные'!$F$2:$F$953,$H7&"",'Исходные данные'!$L$2:$L$953,"УТТ")+SUMIFS('Исходные данные'!$J$2:$J$953,'Исходные данные'!$D$2:$D$953,S$3,'Исходные данные'!$F$2:$F$953,$H7&"",'Исходные данные'!$L$2:$L$953,"УТТ")=0,"","утт-"&(SUMIFS('Исходные данные'!$I$2:$I$953,'Исходные данные'!$D$2:$D$953,S$3,'Исходные данные'!$F$2:$F$953,$H7&"",'Исходные данные'!$L$2:$L$953,"УТТ")+SUMIFS('Исходные данные'!$J$2:$J$953,'Исходные данные'!$D$2:$D$953,S$3,'Исходные данные'!$F$2:$F$953,$H7&"",'Исходные данные'!$L$2:$L$953,"УТТ"))) | T6: =IF(SUMIFS('Исходные данные'!$I$2:$I$953,'Исходные данные'!$D$2:$D$953,T$3,'Исходные данные'!$F$2:$F$953,$H7&"",'Исходные данные'!$L$2:$L$953,"УТТ")+SUMIFS('Исходные данные'!$J$2:$J$953,'Исходные данные'!$D$2:$D$953,T$3,'Исходные данные'!$F$2:$F$953,$H7&"",'Исходные данные'!$L$2:$L$953,"УТТ")=0,"","утт-"&(SUMIFS('Исходные данные'!$I$2:$I$953,'Исходные данные'!$D$2:$D$953,T$3,'Исходные данные'!$F$2:$F$953,$H7&"",'Исходные данные'!$L$2:$L$953,"УТТ")+SUMIFS('Исходные данные'!$J$2:$J$953,'Исходные данные'!$D$2:$D$953,T$3,'Исходные данные'!$F$2:$F$953,$H7&"",'Исходные данные'!$L$2:$L$953,"УТТ"))) | U6: =IF(SUMIFS('Исходные данные'!$I$2:$I$953,'Исходные данные'!$D$2:$D$953,U$3,'Исходные данные'!$F$2:$F$953,$H7&"",'Исходные данные'!$L$2:$L$953,"УТТ")+SUMIFS('Исходные данные'!$J$2:$J$953,'Исходные данные'!$D$2:$D$953,U$3,'Исходные данные'!$F$2:$F$953,$H7&"",'Исходные данные'!$L$2:$L$953,"УТТ")=0,"","утт-"&(SUMIFS('Исходные данные'!$I$2:$I$953,'Исходные данные'!$D$2:$D$953,U$3,'Исходные данные'!$F$2:$F$953,$H7&"",'Исходные данные'!$L$2:$L$953,"УТТ")+SUMIFS('Исходные данные'!$J$2:$J$953,'Исходные данные'!$D$2:$D$953,U$3,'Исходные данные'!$F$2:$F$953,$H7&"",'Исходные данные'!$L$2:$L$953,"УТТ"))) | V6: =IF(SUMIFS('Исходные данные'!$I$2:$I$953,'Исходные данные'!$D$2:$D$953,V$3,'Исходные данные'!$F$2:$F$953,$H7&"",'Исходные данные'!$L$2:$L$953,"УТТ")+SUMIFS('Исходные данные'!$J$2:$J$953,'Исходные данные'!$D$2:$D$953,V$3,'Исходные данные'!$F$2:$F$953,$H7&"",'Исходные данные'!$L$2:$L$953,"УТТ")=0,"","утт-"&(SUMIFS('Исходные данные'!$I$2:$I$953,'Исходные данные'!$D$2:$D$953,V$3,'Исходные данные'!$F$2:$F$953,$H7&"",'Исходные данные'!$L$2:$L$953,"УТТ")+SUMIFS('Исходные данные'!$J$2:$J$953,'Исходные данные'!$D$2:$D$953,V$3,'Исходные данные'!$F$2:$F$953,$H7&"",'Исходные данные'!$L$2:$L$953,"УТТ"))) | ... AA6: =IF(SUMIFS('Исходные данные'!$I$2:$I$953,'Исходные данные'!$D$2:$D$953,AA$3,'Исходные данные'!$F$2:$F$953,$H7&"",'Исходные данные'!$L$2:$L$953,"УТТ")+SUMIFS('Исходные данные'!$J$2:$J$953,'Исходные данные'!$D$2:$D$953,AA$3,'Исходные данные'!$F$2:$F$953,$H7&"",'Исходные данные'!$L$2:$L$953,"УТТ")=0,"","утт-"&(SUMIFS('Исходные данные'!$I$2:$I$953,'Исходные данные'!$D$2:$D$953,AA$3,'Исходные данные'!$F$2:$F$953,$H7&"",'Исходные данные'!$L$2:$L$953,"УТТ")+SUMIFS('Исходные данные'!$J$2:$J$953,'Исходные данные'!$D$2:$D$953,AA$3,'Исходные данные'!$F$2:$F$953,$H7&"",'Исходные данные'!$L$2:$L$953,"УТТ"))) | AC6: =IF(SUMIFS('Исходные данные'!$I$2:$I$953,'Исходные данные'!$D$2:$D$953,AC$3,'Исходные данные'!$F$2:$F$953,$H7&"",'Исходные данные'!$L$2:$L$953,"УТТ")+SUMIFS('Исходные данные'!$J$2:$J$953,'Исходные данные'!$D$2:$D$953,AC$3,'Исходные данные'!$F$2:$F$953,$H7&"",'Исходные данные'!$L$2:$L$953,"УТТ")=0,"","утт-"&(SUMIFS('Исходные данные'!$I$2:$I$953,'Исходные данные'!$D$2:$D$953,AC$3,'Исходные данные'!$F$2:$F$953,$H7&"",'Исходные данные'!$L$2:$L$953,"УТТ")+SUMIFS('Исходные данные'!$J$2:$J$953,'Исходные данные'!$D$2:$D$953,AC$3,'Исходные данные'!$F$2:$F$953,$H7&"",'Исходные данные'!$L$2:$L$953,"УТТ"))) | AD6: =IF(SUMIFS('Исходные данные'!$I$2:$I$953,'Исходные данные'!$D$2:$D$953,AD$3,'Исходные данные'!$F$2:$F$953,$H7&"",'Исходные данные'!$L$2:$L$953,"УТТ")+SUMIFS('Исходные данные'!$J$2:$J$953,'Исходные данные'!$D$2:$D$953,AD$3,'Исходные данные'!$F$2:$F$953,$H7&"",'Исходные данные'!$L$2:$L$953,"УТТ")=0,"","утт-"&(SUMIFS('Исходные данные'!$I$2:$I$953,'Исходные данные'!$D$2:$D$953,AD$3,'Исходные данные'!$F$2:$F$953,$H7&"",'Исходные данные'!$L$2:$L$953,"УТТ")+SUMIFS('Исходные данные'!$J$2:$J$953,'Исходные данные'!$D$2:$D$953,AD$3,'Исходные данные'!$F$2:$F$953,$H7&"",'Исходные данные'!$L$2:$L$953,"УТТ")))
A7: 5 | H7: 47 | I7: Экскаватор | J7: =IFERROR(INDEX('Выход ТС'!$C:$C,MATCH($H7&"",'Выход ТС'!$A:$A,0)),"") | K7: =IFERROR(INDEX('Выход ТС'!$D:$D,MATCH($H7&"",'Выход ТС'!$A:$A,0)),"") | L7: =IFERROR(INDEX('Выход ТС'!$E:$E,MATCH($H7&"",'Выход ТС'!$A:$A,0)),"") | M7: =IFERROR(IF(INDEX('Выход ТС'!$F:$F,MATCH($H7&"",'Выход ТС'!$A:$A,0))=0,"",INDEX('Выход ТС'!$F:$F,MATCH($H7&"",'Выход ТС'!$A:$A,0))),"") | N7: =IFERROR(IF(INDEX('Выход ТС'!$G:$G,MATCH($H7&"",'Выход ТС'!$A:$A,0))=0,"",INDEX('Выход ТС'!$G:$G,MATCH($H7&"",'Выход ТС'!$A:$A,0))),"") | O7: =IF(SUMIFS('Исходные данные'!$I$2:$I$953,'Исходные данные'!$D$2:$D$953,O$3,'Исходные данные'!$F$2:$F$953,$H7&"")+SUMIFS('Исходные данные'!$J$2:$J$953,'Исходные данные'!$D$2:$D$953,O$3,'Исходные данные'!$F$2:$F$953,$H7&"")=0,"",IF(SUMIFS('Исходные данные'!$J$2:$J$953,'Исходные данные'!$D$2:$D$953,O$3,'Исходные данные'!$F$2:$F$953,$H7&"")=0,SUMIFS('Исходные данные'!$I$2:$I$953,'Исходные данные'!$D$2:$D$953,O$3,'Исходные данные'!$F$2:$F$953,$H7&""),IF(SUMIFS('Исходные данные'!$I$2:$I$953,'Исходные данные'!$D$2:$D$953,O$3,'Исходные данные'!$F$2:$F$953,$H7&"")=0,"0+"&SUMIFS('Исходные данные'!$J$2:$J$953,'Исходные данные'!$D$2:$D$953,O$3,'Исходные данные'!$F$2:$F$953,$H7&"")&"="&SUMIFS('Исходные данные'!$J$2:$J$953,'Исходные данные'!$D$2:$D$953,O$3,'Исходные данные'!$F$2:$F$953,$H7&""),SUMIFS('Исходные данные'!$I$2:$I$953,'Исходные данные'!$D$2:$D$953,O$3,'Исходные данные'!$F$2:$F$953,$H7&"")&"+"&SUMIFS('Исходные данные'!$J$2:$J$953,'Исходные данные'!$D$2:$D$953,O$3,'Исходные данные'!$F$2:$F$953,$H7&"")&"="&(SUMIFS('Исходные данные'!$I$2:$I$953,'Исходные данные'!$D$2:$D$953,O$3,'Исходные данные'!$F$2:$F$953,$H7&"")+SUMIFS('Исходные данные'!$J$2:$J$953,'Исходные данные'!$D$2:$D$953,O$3,'Исходные данные'!$F$2:$F$953,$H7&""))))) | P7: =IF(SUMIFS('Исходные данные'!$I$2:$I$953,'Исходные данные'!$D$2:$D$953,P$3,'Исходные данные'!$F$2:$F$953,$H7&"")+SUMIFS('Исходные данные'!$J$2:$J$953,'Исходные данные'!$D$2:$D$953,P$3,'Исходные данные'!$F$2:$F$953,$H7&"")=0,"",IF(SUMIFS('Исходные данные'!$J$2:$J$953,'Исходные данные'!$D$2:$D$953,P$3,'Исходные данные'!$F$2:$F$953,$H7&"")=0,SUMIFS('Исходные данные'!$I$2:$I$953,'Исходные данные'!$D$2:$D$953,P$3,'Исходные данные'!$F$2:$F$953,$H7&""),IF(SUMIFS('Исходные данные'!$I$2:$I$953,'Исходные данные'!$D$2:$D$953,P$3,'Исходные данные'!$F$2:$F$953,$H7&"")=0,"0+"&SUMIFS('Исходные данные'!$J$2:$J$953,'Исходные данные'!$D$2:$D$953,P$3,'Исходные данные'!$F$2:$F$953,$H7&"")&"="&SUMIFS('Исходные данные'!$J$2:$J$953,'Исходные данные'!$D$2:$D$953,P$3,'Исходные данные'!$F$2:$F$953,$H7&""),SUMIFS('Исходные данные'!$I$2:$I$953,'Исходные данные'!$D$2:$D$953,P$3,'Исходные данные'!$F$2:$F$953,$H7&"")&"+"&SUMIFS('Исходные данные'!$J$2:$J$953,'Исходные данные'!$D$2:$D$953,P$3,'Исходные данные'!$F$2:$F$953,$H7&"")&"="&(SUMIFS('Исходные данные'!$I$2:$I$953,'Исходные данные'!$D$2:$D$953,P$3,'Исходные данные'!$F$2:$F$953,$H7&"")+SUMIFS('Исходные данные'!$J$2:$J$953,'Исходные данные'!$D$2:$D$953,P$3,'Исходные данные'!$F$2:$F$953,$H7&""))))) | Q7: =IF(SUMIFS('Исходные данные'!$I$2:$I$953,'Исходные данные'!$D$2:$D$953,Q$3,'Исходные данные'!$F$2:$F$953,$H7&"")+SUMIFS('Исходные данные'!$J$2:$J$953,'Исходные данные'!$D$2:$D$953,Q$3,'Исходные данные'!$F$2:$F$953,$H7&"")=0,"",IF(SUMIFS('Исходные данные'!$J$2:$J$953,'Исходные данные'!$D$2:$D$953,Q$3,'Исходные данные'!$F$2:$F$953,$H7&"")=0,SUMIFS('Исходные данные'!$I$2:$I$953,'Исходные данные'!$D$2:$D$953,Q$3,'Исходные данные'!$F$2:$F$953,$H7&""),IF(SUMIFS('Исходные данные'!$I$2:$I$953,'Исходные данные'!$D$2:$D$953,Q$3,'Исходные данные'!$F$2:$F$953,$H7&"")=0,"0+"&SUMIFS('Исходные данные'!$J$2:$J$953,'Исходные данные'!$D$2:$D$953,Q$3,'Исходные данные'!$F$2:$F$953,$H7&"")&"="&SUMIFS('Исходные данные'!$J$2:$J$953,'Исходные данные'!$D$2:$D$953,Q$3,'Исходные данные'!$F$2:$F$953,$H7&""),SUMIFS('Исходные данные'!$I$2:$I$953,'Исходные данные'!$D$2:$D$953,Q$3,'Исходные данные'!$F$2:$F$953,$H7&"")&"+"&SUMIFS('Исходные данные'!$J$2:$J$953,'Исходные данные'!$D$2:$D$953,Q$3,'Исходные данные'!$F$2:$F$953,$H7&"")&"="&(SUMIFS('Исходные данные'!$I$2:$I$953,'Исходные данные'!$D$2:$D$953,Q$3,'Исходные данные'!$F$2:$F$953,$H7&"")+SUMIFS('Исходные данные'!$J$2:$J$953,'Исходные данные'!$D$2:$D$953,Q$3,'Исходные данные'!$F$2:$F$953,$H7&""))))) | R7: =IF(SUMIFS('Исходные данные'!$I$2:$I$953,'Исходные данные'!$D$2:$D$953,R$3,'Исходные данные'!$F$2:$F$953,$H7&"")+SUMIFS('Исходные данные'!$J$2:$J$953,'Исходные данные'!$D$2:$D$953,R$3,'Исходные данные'!$F$2:$F$953,$H7&"")=0,"",IF(SUMIFS('Исходные данные'!$J$2:$J$953,'Исходные данные'!$D$2:$D$953,R$3,'Исходные данные'!$F$2:$F$953,$H7&"")=0,SUMIFS('Исходные данные'!$I$2:$I$953,'Исходные данные'!$D$2:$D$953,R$3,'Исходные данные'!$F$2:$F$953,$H7&""),IF(SUMIFS('Исходные данные'!$I$2:$I$953,'Исходные данные'!$D$2:$D$953,R$3,'Исходные данные'!$F$2:$F$953,$H7&"")=0,"0+"&SUMIFS('Исходные данные'!$J$2:$J$953,'Исходные данные'!$D$2:$D$953,R$3,'Исходные данные'!$F$2:$F$953,$H7&"")&"="&SUMIFS('Исходные данные'!$J$2:$J$953,'Исходные данные'!$D$2:$D$953,R$3,'Исходные данные'!$F$2:$F$953,$H7&""),SUMIFS('Исходные данные'!$I$2:$I$953,'Исходные данные'!$D$2:$D$953,R$3,'Исходные данные'!$F$2:$F$953,$H7&"")&"+"&SUMIFS('Исходные данные'!$J$2:$J$953,'Исходные данные'!$D$2:$D$953,R$3,'Исходные данные'!$F$2:$F$953,$H7&"")&"="&(SUMIFS('Исходные данные'!$I$2:$I$953,'Исходные данные'!$D$2:$D$953,R$3,'Исходные данные'!$F$2:$F$953,$H7&"")+SUMIFS('Исходные данные'!$J$2:$J$953,'Исходные данные'!$D$2:$D$953,R$3,'Исходные данные'!$F$2:$F$953,$H7&""))))) | S7: =IF(SUMIFS('Исходные данные'!$I$2:$I$953,'Исходные данные'!$D$2:$D$953,S$3,'Исходные данные'!$F$2:$F$953,$H7&"")+SUMIFS('Исходные данные'!$J$2:$J$953,'Исходные данные'!$D$2:$D$953,S$3,'Исходные данные'!$F$2:$F$953,$H7&"")=0,"",IF(SUMIFS('Исходные данные'!$J$2:$J$953,'Исходные данные'!$D$2:$D$953,S$3,'Исходные данные'!$F$2:$F$953,$H7&"")=0,SUMIFS('Исходные данные'!$I$2:$I$953,'Исходные данные'!$D$2:$D$953,S$3,'Исходные данные'!$F$2:$F$953,$H7&""),IF(SUMIFS('Исходные данные'!$I$2:$I$953,'Исходные данные'!$D$2:$D$953,S$3,'Исходные данные'!$F$2:$F$953,$H7&"")=0,"0+"&SUMIFS('Исходные данные'!$J$2:$J$953,'Исходные данные'!$D$2:$D$953,S$3,'Исходные данные'!$F$2:$F$953,$H7&"")&"="&SUMIFS('Исходные данные'!$J$2:$J$953,'Исходные данные'!$D$2:$D$953,S$3,'Исходные данные'!$F$2:$F$953,$H7&""),SUMIFS('Исходные данные'!$I$2:$I$953,'Исходные данные'!$D$2:$D$953,S$3,'Исходные данные'!$F$2:$F$953,$H7&"")&"+"&SUMIFS('Исходные данные'!$J$2:$J$953,'Исходные данные'!$D$2:$D$953,S$3,'Исходные данные'!$F$2:$F$953,$H7&"")&"="&(SUMIFS('Исходные данные'!$I$2:$I$953,'Исходные данные'!$D$2:$D$953,S$3,'Исходные данные'!$F$2:$F$953,$H7&"")+SUMIFS('Исходные данные'!$J$2:$J$953,'Исходные данные'!$D$2:$D$953,S$3,'Исходные данные'!$F$2:$F$953,$H7&""))))) | T7: =IF(SUMIFS('Исходные данные'!$I$2:$I$953,'Исходные данные'!$D$2:$D$953,T$3,'Исходные данные'!$F$2:$F$953,$H7&"")+SUMIFS('Исходные данные'!$J$2:$J$953,'Исходные данные'!$D$2:$D$953,T$3,'Исходные данные'!$F$2:$F$953,$H7&"")=0,"",IF(SUMIFS('Исходные данные'!$J$2:$J$953,'Исходные данные'!$D$2:$D$953,T$3,'Исходные данные'!$F$2:$F$953,$H7&"")=0,SUMIFS('Исходные данные'!$I$2:$I$953,'Исходные данные'!$D$2:$D$953,T$3,'Исходные данные'!$F$2:$F$953,$H7&""),IF(SUMIFS('Исходные данные'!$I$2:$I$953,'Исходные данные'!$D$2:$D$953,T$3,'Исходные данные'!$F$2:$F$953,$H7&"")=0,"0+"&SUMIFS('Исходные данные'!$J$2:$J$953,'Исходные данные'!$D$2:$D$953,T$3,'Исходные данные'!$F$2:$F$953,$H7&"")&"="&SUMIFS('Исходные данные'!$J$2:$J$953,'Исходные данные'!$D$2:$D$953,T$3,'Исходные данные'!$F$2:$F$953,$H7&""),SUMIFS('Исходные данные'!$I$2:$I$953,'Исходные данные'!$D$2:$D$953,T$3,'Исходные данные'!$F$2:$F$953,$H7&"")&"+"&SUMIFS('Исходные данные'!$J$2:$J$953,'Исходные данные'!$D$2:$D$953,T$3,'Исходные данные'!$F$2:$F$953,$H7&"")&"="&(SUMIFS('Исходные данные'!$I$2:$I$953,'Исходные данные'!$D$2:$D$953,T$3,'Исходные данные'!$F$2:$F$953,$H7&"")+SUMIFS('Исходные данные'!$J$2:$J$953,'Исходные данные'!$D$2:$D$953,T$3,'Исходные данные'!$F$2:$F$953,$H7&""))))) | U7: =IF(SUMIFS('Исходные данные'!$I$2:$I$953,'Исходные данные'!$D$2:$D$953,U$3,'Исходные данные'!$F$2:$F$953,$H7&"")+SUMIFS('Исходные данные'!$J$2:$J$953,'Исходные данные'!$D$2:$D$953,U$3,'Исходные данные'!$F$2:$F$953,$H7&"")=0,"",IF(SUMIFS('Исходные данные'!$J$2:$J$953,'Исходные данные'!$D$2:$D$953,U$3,'Исходные данные'!$F$2:$F$953,$H7&"")=0,SUMIFS('Исходные данные'!$I$2:$I$953,'Исходные данные'!$D$2:$D$953,U$3,'Исходные данные'!$F$2:$F$953,$H7&""),IF(SUMIFS('Исходные данные'!$I$2:$I$953,'Исходные данные'!$D$2:$D$953,U$3,'Исходные данные'!$F$2:$F$953,$H7&"")=0,"0+"&SUMIFS('Исходные данные'!$J$2:$J$953,'Исходные данные'!$D$2:$D$953,U$3,'Исходные данные'!$F$2:$F$953,$H7&"")&"="&SUMIFS('Исходные данные'!$J$2:$J$953,'Исходные данные'!$D$2:$D$953,U$3,'Исходные данные'!$F$2:$F$953,$H7&""),SUMIFS('Исходные данные'!$I$2:$I$953,'Исходные данные'!$D$2:$D$953,U$3,'Исходные данные'!$F$2:$F$953,$H7&"")&"+"&SUMIFS('Исходные данные'!$J$2:$J$953,'Исходные данные'!$D$2:$D$953,U$3,'Исходные данные'!$F$2:$F$953,$H7&"")&"="&(SUMIFS('Исходные данные'!$I$2:$I$953,'Исходные данные'!$D$2:$D$953,U$3,'Исходные данные'!$F$2:$F$953,$H7&"")+SUMIFS('Исходные данные'!$J$2:$J$953,'Исходные данные'!$D$2:$D$953,U$3,'Исходные данные'!$F$2:$F$953,$H7&""))))) | V7: =IF(SUMIFS('Исходные данные'!$I$2:$I$953,'Исходные данные'!$D$2:$D$953,V$3,'Исходные данные'!$F$2:$F$953,$H7&"")+SUMIFS('Исходные данные'!$J$2:$J$953,'Исходные данные'!$D$2:$D$953,V$3,'Исходные данные'!$F$2:$F$953,$H7&"")=0,"",IF(SUMIFS('Исходные данные'!$J$2:$J$953,'Исходные данные'!$D$2:$D$953,V$3,'Исходные данные'!$F$2:$F$953,$H7&"")=0,SUMIFS('Исходные данные'!$I$2:$I$953,'Исходные данные'!$D$2:$D$953,V$3,'Исходные данные'!$F$2:$F$953,$H7&""),IF(SUMIFS('Исходные данные'!$I$2:$I$953,'Исходные данные'!$D$2:$D$953,V$3,'Исходные данные'!$F$2:$F$953,$H7&"")=0,"0+"&SUMIFS('Исходные данные'!$J$2:$J$953,'Исходные данные'!$D$2:$D$953,V$3,'Исходные данные'!$F$2:$F$953,$H7&"")&"="&SUMIFS('Исходные данные'!$J$2:$J$953,'Исходные данные'!$D$2:$D$953,V$3,'Исходные данные'!$F$2:$F$953,$H7&""),SUMIFS('Исходные данные'!$I$2:$I$953,'Исходные данные'!$D$2:$D$953,V$3,'Исходные данные'!$F$2:$F$953,$H7&"")&"+"&SUMIFS('Исходные данные'!$J$2:$J$953,'Исходные данные'!$D$2:$D$953,V$3,'Исходные данные'!$F$2:$F$953,$H7&"")&"="&(SUMIFS('Исходные данные'!$I$2:$I$953,'Исходные данные'!$D$2:$D$953,V$3,'Исходные данные'!$F$2:$F$953,$H7&"")+SUMIFS('Исходные данные'!$J$2:$J$953,'Исходные данные'!$D$2:$D$953,V$3,'Исходные данные'!$F$2:$F$953,$H7&""))))) | ... AA7: =IF(SUMIFS('Исходные данные'!$I$2:$I$953,'Исходные данные'!$D$2:$D$953,AA$3,'Исходные данные'!$F$2:$F$953,$H7&"")+SUMIFS('Исходные данные'!$J$2:$J$953,'Исходные данные'!$D$2:$D$953,AA$3,'Исходные данные'!$F$2:$F$953,$H7&"")=0,"",IF(SUMIFS('Исходные данные'!$J$2:$J$953,'Исходные данные'!$D$2:$D$953,AA$3,'Исходные данные'!$F$2:$F$953,$H7&"")=0,SUMIFS('Исходные данные'!$I$2:$I$953,'Исходные данные'!$D$2:$D$953,AA$3,'Исходные данные'!$F$2:$F$953,$H7&""),IF(SUMIFS('Исходные данные'!$I$2:$I$953,'Исходные данные'!$D$2:$D$953,AA$3,'Исходные данные'!$F$2:$F$953,$H7&"")=0,"0+"&SUMIFS('Исходные данные'!$J$2:$J$953,'Исходные данные'!$D$2:$D$953,AA$3,'Исходные данные'!$F$2:$F$953,$H7&"")&"="&SUMIFS('Исходные данные'!$J$2:$J$953,'Исходные данные'!$D$2:$D$953,AA$3,'Исходные данные'!$F$2:$F$953,$H7&""),SUMIFS('Исходные данные'!$I$2:$I$953,'Исходные данные'!$D$2:$D$953,AA$3,'Исходные данные'!$F$2:$F$953,$H7&"")&"+"&SUMIFS('Исходные данные'!$J$2:$J$953,'Исходные данные'!$D$2:$D$953,AA$3,'Исходные данные'!$F$2:$F$953,$H7&"")&"="&(SUMIFS('Исходные данные'!$I$2:$I$953,'Исходные данные'!$D$2:$D$953,AA$3,'Исходные данные'!$F$2:$F$953,$H7&"")+SUMIFS('Исходные данные'!$J$2:$J$953,'Исходные данные'!$D$2:$D$953,AA$3,'Исходные данные'!$F$2:$F$953,$H7&""))))) | AC7: =IF(SUMIFS('Исходные данные'!$I$2:$I$953,'Исходные данные'!$D$2:$D$953,AC$3,'Исходные данные'!$F$2:$F$953,$H7&"")+SUMIFS('Исходные данные'!$J$2:$J$953,'Исходные данные'!$D$2:$D$953,AC$3,'Исходные данные'!$F$2:$F$953,$H7&"")=0,"",IF(SUMIFS('Исходные данные'!$J$2:$J$953,'Исходные данные'!$D$2:$D$953,AC$3,'Исходные данные'!$F$2:$F$953,$H7&"")=0,SUMIFS('Исходные данные'!$I$2:$I$953,'Исходные данные'!$D$2:$D$953,AC$3,'Исходные данные'!$F$2:$F$953,$H7&""),IF(SUMIFS('Исходные данные'!$I$2:$I$953,'Исходные данные'!$D$2:$D$953,AC$3,'Исходные данные'!$F$2:$F$953,$H7&"")=0,"0+"&SUMIFS('Исходные данные'!$J$2:$J$953,'Исходные данные'!$D$2:$D$953,AC$3,'Исходные данные'!$F$2:$F$953,$H7&"")&"="&SUMIFS('Исходные данные'!$J$2:$J$953,'Исходные данные'!$D$2:$D$953,AC$3,'Исходные данные'!$F$2:$F$953,$H7&""),SUMIFS('Исходные данные'!$I$2:$I$953,'Исходные данные'!$D$2:$D$953,AC$3,'Исходные данные'!$F$2:$F$953,$H7&"")&"+"&SUMIFS('Исходные данные'!$J$2:$J$953,'Исходные данные'!$D$2:$D$953,AC$3,'Исходные данные'!$F$2:$F$953,$H7&"")&"="&(SUMIFS('Исходные данные'!$I$2:$I$953,'Исходные данные'!$D$2:$D$953,AC$3,'Исходные данные'!$F$2:$F$953,$H7&"")+SUMIFS('Исходные данные'!$J$2:$J$953,'Исходные данные'!$D$2:$D$953,AC$3,'Исходные данные'!$F$2:$F$953,$H7&""))))) | AD7: =IF(SUMIFS('Исходные данные'!$I$2:$I$953,'Исходные данные'!$D$2:$D$953,AD$3,'Исходные данные'!$F$2:$F$953,$H7&"")+SUMIFS('Исходные данные'!$J$2:$J$953,'Исходные данные'!$D$2:$D$953,AD$3,'Исходные данные'!$F$2:$F$953,$H7&"")=0,"",IF(SUMIFS('Исходные данные'!$J$2:$J$953,'Исходные данные'!$D$2:$D$953,AD$3,'Исходные данные'!$F$2:$F$953,$H7&"")=0,SUMIFS('Исходные данные'!$I$2:$I$953,'Исходные данные'!$D$2:$D$953,AD$3,'Исходные данные'!$F$2:$F$953,$H7&""),IF(SUMIFS('Исходные данные'!$I$2:$I$953,'Исходные данные'!$D$2:$D$953,AD$3,'Исходные данные'!$F$2:$F$953,$H7&"")=0,"0+"&SUMIFS('Исходные данные'!$J$2:$J$953,'Исходные данные'!$D$2:$D$953,AD$3,'Исходные данные'!$F$2:$F$953,$H7&"")&"="&SUMIFS('Исходные данные'!$J$2:$J$953,'Исходные данные'!$D$2:$D$953,AD$3,'Исходные данные'!$F$2:$F$953,$H7&""),SUMIFS('Исходные данные'!$I$2:$I$953,'Исходные данные'!$D$2:$D$953,AD$3,'Исходные данные'!$F$2:$F$953,$H7&"")&"+"&SUMIFS('Исходные данные'!$J$2:$J$953,'Исходные данные'!$D$2:$D$953,AD$3,'Исходные данные'!$F$2:$F$953,$H7&"")&"="&(SUMIFS('Исходные данные'!$I$2:$I$953,'Исходные данные'!$D$2:$D$953,AD$3,'Исходные данные'!$F$2:$F$953,$H7&"")+SUMIFS('Исходные данные'!$J$2:$J$953,'Исходные данные'!$D$2:$D$953,AD$3,'Исходные данные'!$F$2:$F$953,$H7&"")))))
A8: 6 | O8: =IF(SUMIFS('Исходные данные'!$I$2:$I$953,'Исходные данные'!$D$2:$D$953,O$3,'Исходные данные'!$F$2:$F$953,$H9&"",'Исходные данные'!$L$2:$L$953,"УТТ")+SUMIFS('Исходные данные'!$J$2:$J$953,'Исходные данные'!$D$2:$D$953,O$3,'Исходные данные'!$F$2:$F$953,$H9&"",'Исходные данные'!$L$2:$L$953,"УТТ")=0,"","утт-"&(SUMIFS('Исходные данные'!$I$2:$I$953,'Исходные данные'!$D$2:$D$953,O$3,'Исходные данные'!$F$2:$F$953,$H9&"",'Исходные данные'!$L$2:$L$953,"УТТ")+SUMIFS('Исходные данные'!$J$2:$J$953,'Исходные данные'!$D$2:$D$953,O$3,'Исходные данные'!$F$2:$F$953,$H9&"",'Исходные данные'!$L$2:$L$953,"УТТ"))) | P8: =IF(SUMIFS('Исходные данные'!$I$2:$I$953,'Исходные данные'!$D$2:$D$953,P$3,'Исходные данные'!$F$2:$F$953,$H9&"",'Исходные данные'!$L$2:$L$953,"УТТ")+SUMIFS('Исходные данные'!$J$2:$J$953,'Исходные данные'!$D$2:$D$953,P$3,'Исходные данные'!$F$2:$F$953,$H9&"",'Исходные данные'!$L$2:$L$953,"УТТ")=0,"","утт-"&(SUMIFS('Исходные данные'!$I$2:$I$953,'Исходные данные'!$D$2:$D$953,P$3,'Исходные данные'!$F$2:$F$953,$H9&"",'Исходные данные'!$L$2:$L$953,"УТТ")+SUMIFS('Исходные данные'!$J$2:$J$953,'Исходные данные'!$D$2:$D$953,P$3,'Исходные данные'!$F$2:$F$953,$H9&"",'Исходные данные'!$L$2:$L$953,"УТТ"))) | Q8: =IF(SUMIFS('Исходные данные'!$I$2:$I$953,'Исходные данные'!$D$2:$D$953,Q$3,'Исходные данные'!$F$2:$F$953,$H9&"",'Исходные данные'!$L$2:$L$953,"УТТ")+SUMIFS('Исходные данные'!$J$2:$J$953,'Исходные данные'!$D$2:$D$953,Q$3,'Исходные данные'!$F$2:$F$953,$H9&"",'Исходные данные'!$L$2:$L$953,"УТТ")=0,"","утт-"&(SUMIFS('Исходные данные'!$I$2:$I$953,'Исходные данные'!$D$2:$D$953,Q$3,'Исходные данные'!$F$2:$F$953,$H9&"",'Исходные данные'!$L$2:$L$953,"УТТ")+SUMIFS('Исходные данные'!$J$2:$J$953,'Исходные данные'!$D$2:$D$953,Q$3,'Исходные данные'!$F$2:$F$953,$H9&"",'Исходные данные'!$L$2:$L$953,"УТТ"))) | R8: =IF(SUMIFS('Исходные данные'!$I$2:$I$953,'Исходные данные'!$D$2:$D$953,R$3,'Исходные данные'!$F$2:$F$953,$H9&"",'Исходные данные'!$L$2:$L$953,"УТТ")+SUMIFS('Исходные данные'!$J$2:$J$953,'Исходные данные'!$D$2:$D$953,R$3,'Исходные данные'!$F$2:$F$953,$H9&"",'Исходные данные'!$L$2:$L$953,"УТТ")=0,"","утт-"&(SUMIFS('Исходные данные'!$I$2:$I$953,'Исходные данные'!$D$2:$D$953,R$3,'Исходные данные'!$F$2:$F$953,$H9&"",'Исходные данные'!$L$2:$L$953,"УТТ")+SUMIFS('Исходные данные'!$J$2:$J$953,'Исходные данные'!$D$2:$D$953,R$3,'Исходные данные'!$F$2:$F$953,$H9&"",'Исходные данные'!$L$2:$L$953,"УТТ"))) | S8: =IF(SUMIFS('Исходные данные'!$I$2:$I$953,'Исходные данные'!$D$2:$D$953,S$3,'Исходные данные'!$F$2:$F$953,$H9&"",'Исходные данные'!$L$2:$L$953,"УТТ")+SUMIFS('Исходные данные'!$J$2:$J$953,'Исходные данные'!$D$2:$D$953,S$3,'Исходные данные'!$F$2:$F$953,$H9&"",'Исходные данные'!$L$2:$L$953,"УТТ")=0,"","утт-"&(SUMIFS('Исходные данные'!$I$2:$I$953,'Исходные данные'!$D$2:$D$953,S$3,'Исходные данные'!$F$2:$F$953,$H9&"",'Исходные данные'!$L$2:$L$953,"УТТ")+SUMIFS('Исходные данные'!$J$2:$J$953,'Исходные данные'!$D$2:$D$953,S$3,'Исходные данные'!$F$2:$F$953,$H9&"",'Исходные данные'!$L$2:$L$953,"УТТ"))) | T8: =IF(SUMIFS('Исходные данные'!$I$2:$I$953,'Исходные данные'!$D$2:$D$953,T$3,'Исходные данные'!$F$2:$F$953,$H9&"",'Исходные данные'!$L$2:$L$953,"УТТ")+SUMIFS('Исходные данные'!$J$2:$J$953,'Исходные данные'!$D$2:$D$953,T$3,'Исходные данные'!$F$2:$F$953,$H9&"",'Исходные данные'!$L$2:$L$953,"УТТ")=0,"","утт-"&(SUMIFS('Исходные данные'!$I$2:$I$953,'Исходные данные'!$D$2:$D$953,T$3,'Исходные данные'!$F$2:$F$953,$H9&"",'Исходные данные'!$L$2:$L$953,"УТТ")+SUMIFS('Исходные данные'!$J$2:$J$953,'Исходные данные'!$D$2:$D$953,T$3,'Исходные данные'!$F$2:$F$953,$H9&"",'Исходные данные'!$L$2:$L$953,"УТТ"))) | U8: =IF(SUMIFS('Исходные данные'!$I$2:$I$953,'Исходные данные'!$D$2:$D$953,U$3,'Исходные данные'!$F$2:$F$953,$H9&"",'Исходные данные'!$L$2:$L$953,"УТТ")+SUMIFS('Исходные данные'!$J$2:$J$953,'Исходные данные'!$D$2:$D$953,U$3,'Исходные данные'!$F$2:$F$953,$H9&"",'Исходные данные'!$L$2:$L$953,"УТТ")=0,"","утт-"&(SUMIFS('Исходные данные'!$I$2:$I$953,'Исходные данные'!$D$2:$D$953,U$3,'Исходные данные'!$F$2:$F$953,$H9&"",'Исходные данные'!$L$2:$L$953,"УТТ")+SUMIFS('Исходные данные'!$J$2:$J$953,'Исходные данные'!$D$2:$D$953,U$3,'Исходные данные'!$F$2:$F$953,$H9&"",'Исходные данные'!$L$2:$L$953,"УТТ"))) | V8: =IF(SUMIFS('Исходные данные'!$I$2:$I$953,'Исходные данные'!$D$2:$D$953,V$3,'Исходные данные'!$F$2:$F$953,$H9&"",'Исходные данные'!$L$2:$L$953,"УТТ")+SUMIFS('Исходные данные'!$J$2:$J$953,'Исходные данные'!$D$2:$D$953,V$3,'Исходные данные'!$F$2:$F$953,$H9&"",'Исходные данные'!$L$2:$L$953,"УТТ")=0,"","утт-"&(SUMIFS('Исходные данные'!$I$2:$I$953,'Исходные данные'!$D$2:$D$953,V$3,'Исходные данные'!$F$2:$F$953,$H9&"",'Исходные данные'!$L$2:$L$953,"УТТ")+SUMIFS('Исходные данные'!$J$2:$J$953,'Исходные данные'!$D$2:$D$953,V$3,'Исходные данные'!$F$2:$F$953,$H9&"",'Исходные данные'!$L$2:$L$953,"УТТ"))) | ... AA8: =IF(SUMIFS('Исходные данные'!$I$2:$I$953,'Исходные данные'!$D$2:$D$953,AA$3,'Исходные данные'!$F$2:$F$953,$H9&"",'Исходные данные'!$L$2:$L$953,"УТТ")+SUMIFS('Исходные данные'!$J$2:$J$953,'Исходные данные'!$D$2:$D$953,AA$3,'Исходные данные'!$F$2:$F$953,$H9&"",'Исходные данные'!$L$2:$L$953,"УТТ")=0,"","утт-"&(SUMIFS('Исходные данные'!$I$2:$I$953,'Исходные данные'!$D$2:$D$953,AA$3,'Исходные данные'!$F$2:$F$953,$H9&"",'Исходные данные'!$L$2:$L$953,"УТТ")+SUMIFS('Исходные данные'!$J$2:$J$953,'Исходные данные'!$D$2:$D$953,AA$3,'Исходные данные'!$F$2:$F$953,$H9&"",'Исходные данные'!$L$2:$L$953,"УТТ"))) | AC8: =IF(SUMIFS('Исходные данные'!$I$2:$I$953,'Исходные данные'!$D$2:$D$953,AC$3,'Исходные данные'!$F$2:$F$953,$H9&"",'Исходные данные'!$L$2:$L$953,"УТТ")+SUMIFS('Исходные данные'!$J$2:$J$953,'Исходные данные'!$D$2:$D$953,AC$3,'Исходные данные'!$F$2:$F$953,$H9&"",'Исходные данные'!$L$2:$L$953,"УТТ")=0,"","утт-"&(SUMIFS('Исходные данные'!$I$2:$I$953,'Исходные данные'!$D$2:$D$953,AC$3,'Исходные данные'!$F$2:$F$953,$H9&"",'Исходные данные'!$L$2:$L$953,"УТТ")+SUMIFS('Исходные данные'!$J$2:$J$953,'Исходные данные'!$D$2:$D$953,AC$3,'Исходные данные'!$F$2:$F$953,$H9&"",'Исходные данные'!$L$2:$L$953,"УТТ"))) | AD8: =IF(SUMIFS('Исходные данные'!$I$2:$I$953,'Исходные данные'!$D$2:$D$953,AD$3,'Исходные данные'!$F$2:$F$953,$H9&"",'Исходные данные'!$L$2:$L$953,"УТТ")+SUMIFS('Исходные данные'!$J$2:$J$953,'Исходные данные'!$D$2:$D$953,AD$3,'Исходные данные'!$F$2:$F$953,$H9&"",'Исходные данные'!$L$2:$L$953,"УТТ")=0,"","утт-"&(SUMIFS('Исходные данные'!$I$2:$I$953,'Исходные данные'!$D$2:$D$953,AD$3,'Исходные данные'!$F$2:$F$953,$H9&"",'Исходные данные'!$L$2:$L$953,"УТТ")+SUMIFS('Исходные данные'!$J$2:$J$953,'Исходные данные'!$D$2:$D$953,AD$3,'Исходные данные'!$F$2:$F$953,$H9&"",'Исходные данные'!$L$2:$L$953,"УТТ")))
