Workbook

Sheet Выход ТС
A1: Префикс | B1: Название типа | C1: План | D1: По формуле | E1: Факт | F1: Откл | G1: Всего Д | H1: Всего Н | I1: План | K1: ЦДН-1 | M1: План | O1: ЦДН-2 | Q1: План | S1: ЦДН-3 | U1: План | W1: ЦППН | Y1: План | AA1: ЦППД | AC1: План | AE1: ЭЦ | AG1: План | AI1: ОКС | AK1: План | AM1: РСЦ | AO1: План | AQ1: ЦИТС | AS1: План | AU1: ПРЦЭО | AW1: План | AY1: ГЦ | BA1: План | BC1: ЦПП | BE1: План | BG1: БМТС | BI1: План | BK1: ЦПКРС-1 | BM1: План | BO1: ЦПКРС-2 | BQ1: План | BS1: Гараж-1 | BU1: План | BW1: ЦНИПР | BY1: План | CA1: ОБиПКРС | CC1: План | CE1: ЦАП | CG1: План | CI1: ГООС | CK1: План | CM1: Бурение | CO1: План | CQ1: ЦТВС | CS1: План | CU1: ТБ | CW1: План | CY1: ОТДН | DA1: План | DC1: БД | DE1: План | DG1: ОГиР | DI1: План | DK1: ГСРиВК | DM1: План | DO1: ЛД | DQ1: План | DS1: Отделкадр | DU1: План | DW1: УЖЭО | DY1: План | EA1: ГАПиИТ | EC1: План | EE1: ОМ | EG1: План | EI1: ПСО | EK1: План | EM1: Гараж-2 | EO1: План | EQ1: СМУ УТТ | ES1: План | EU1: СБ | EW1: План | EY1: МГС | FA1: План | FC1: IR | FE1: План | FG1: ОБиОТ
I2: Д | J2: Н | K2: Д | L2: Н | M2: Д | N2: Н | O2: Д | P2: Н | Q2: Д | R2: Н | S2: Д | T2: Н | U2: Д | V2: Н | W2: Д | X2: Н | Y2: Д | Z2: Н | AA2: Д | AB2: Н | AC2: Д | AD2: Н | AE2: Д | AF2: Н | AG2: Д | AH2: Н | AI2: Д | AJ2: Н | AK2: Д | AL2: Н | AM2: Д | AN2: Н | AO2: Д | AP2: Н | AQ2: Д | AR2: Н | AS2: Д | AT2: Н | AU2: Д | AV2: Н | AW2: Д | AX2: Н | AY2: Д | AZ2: Н | BA2: Д | BB2: Н | BC2: Д | BD2: Н | BE2: Д | BF2: Н | BG2: Д | BH2: Н | BI2: Д | BJ2: Н | BK2: Д | BL2: Н | BM2: Д | BN2: Н | BO2: Д | BP2: Н | BQ2: Д | BR2: Н | BS2: Д | BT2: Н | BU2: Д | BV2: Н | BW2: Д | BX2: Н | BY2: Д | BZ2: Н | CA2: Д | CB2: Н | CC2: Д | CD2: Н | CE2: Д | CF2: Н | CG2: Д | CH2: Н | CI2: Д | CJ2: Н | CK2: Д | CL2: Н | CM2: Д | CN2: Н | CO2: Д | CP2: Н | CQ2: Д | CR2: Н | CS2: Д | CT2: Н | CU2: Д | CV2: Н | CW2: Д | CX2: Н | CY2: Д | CZ2: Н | DA2: Д | DB2: Н | DC2: Д | DD2: Н | DE2: Д | DF2: Н | DG2: Д | DH2: Н | DI2: Д | DJ2: Н | DK2: Д | DL2: Н | DM2: Д | DN2: Н | DO2: Д | DP2: Н | DQ2: Д | DR2: Н | DS2: Д | DT2: Н | DU2: Д | DV2: Н | DW2: Д | DX2: Н | DY2: Д | DZ2: Н | EA2: Д | EB2: Н | EC2: Д | ED2: Н | EE2: Д | EF2: Н | EG2: Д | EH2: Н | EI2: Д | EJ2: Н | EK2: Д | EL2: Н | EM2: Д | EN2: Н | EO2: Д | EP2: Н | EQ2: Д | ER2: Н | ES2: Д | ET2: Н | EU2: Д | EV2: Н | EW2: Д | EX2: Н | EY2: Д | EZ2: Н | FA2: Д | FB2: Н | FC2: Д | FD2: Н | FE2: Д | FF2: Н | FG2: Д | FH2: Н
A3: 34 | B3: ППУА | C3: 29 | D3: =I3+J3+M3+N3+Q3+R3+U3+V3+Y3+Z3+AC3+AD3+AG3+AH3+AK3+AL3+AO3+AP3+AS3+AT3+AW3+AX3+BA3+BB3+BE3+BF3+BI3+BJ3+BM3+BN3+BQ3+BR3+BU3+BV3+BY3+BZ3+CC3+CD3+CG3+CH3+CK3+CL3+CO3+CP3+CS3+CT3+CW3+CX3+DA3+DB3+DE3+DF3+DI3+DJ3+DM3+DN3+DQ3+DR3+DU3+DV3+DY3+DZ3+EC3+ED3+EG3+EH3+EK3+EL3+EO3+EP3+ES3+ET3+EW3+EX3+FA3+FB3+FE3+FF3 -> 29 | E3: =G3+H3 -> 27 | F3: =E3-C3 -> -2 | G3: =K3+O3+S3+W3+AA3+AE3+AI3+AM3+AQ3+AU3+AY3+BC3+BG3+BK3+BO3+BS3+BW3+CA3+CE3+CI3+CM3+CQ3+CU3+CY3+DC3+DG3+DK3+DO3+DS3+DW3+EA3+EE3+EI3+EM3+EQ3+EU3+EY3+FC3+FG3 -> 19 | H3: =L3+P3+T3+X3+AB3+AF3+AJ3+AN3+AR3+AV3+AZ3+BD3+BH3+BL3+BP3+BT3+BX3+CB3+CF3+CJ3+CN3+CR3+CV3+CZ3+DD3+DH3+DL3+DP3+DT3+DX3+EB3+EF3+EJ3+EN3+ER3+EV3+EZ3+FD3+FH3 -> 8 | I3: 3 | J3: 2 | K3: =SUMIFS('Исходные данные'!$I$2:$I$964,'Исходные данные'!$D$2:$D$964,K$1,'Исходные данные'!$F$2:$F$964,$A3) -> 3 | L3: =SUMIFS('Исходные данные'!$J$2:$J$964,'Исходные данные'!$D$2:$D$964,K$1,'Исходные данные'!$F$2:$F$964,$A3) -> 1 | M3: 2 | N3: 1 | O3: =SUMIFS('Исходные данные'!$I$2:$I$964,'Исходные данные'!$D$2:$D$964,O$1,'Исходные данные'!$F$2:$F$964,$A3) -> 2 | P3: =SUMIFS('Исходные данные'!$J$2:$J$964,'Исходные данные'!$D$2:$D$964,O$1,'Исходные данные'!$F$2:$F$964,$A3) -> 0 | Q3: 4 | R3: 1 | S3: =SUMIFS('Исходные данные'!$I$2:$I$964,'Исходные данные'!$D$2:$D$964,S$1,'Исходные данные'!$F$2:$F$964,$A3) -> 3 | T3: =SUMIFS('Исходные данные'!$J$2:$J$964,'Исходные данные'!$D$2:$D$964,S$1,'Исходные данные'!$F$2:$F$964,$A3) -> 1 | U3: 0 | V3: 0 | W3: =SUMIFS('Исходные данные'!$I$2:$I$964,'Исходные данные'!$D$2:$D$964,W$1,'Исходные данные'!$F$2:$F$964,$A3) -> 1 | X3: =SUMIFS('Исходные данные'!$J$2:$J$964,'Исходные данные'!$D$2:$D$964,W$1,'Исходные данные'!$F$2:$F$964,$A3) -> 0 | Y3: 1 | Z3: 0 | AA3: =SUMIFS('Исходные данные'!$I$2:$I$964,'Исходные данные'!$D$2:$D$964,AA$1,'Исходные данные'!$F$2:$F$964,$A3) -> 1 | AB3: =SUMIFS('Исходные данные'!$J$2:$J$964,'Исходные данные'!$D$2:$D$964,AA$1,'Исходные данные'!$F$2:$F$964,$A3) -> 0 | AC3: 0 | AD3: 0 | AE3: =SUMIFS('Исходные данные'!$I$2:$I$964,'Исходные данные'!$D$2:$D$964,AE$1,'Исходные данные'!$F$2:$F$964,$A3) -> 0 | AF3: =SUMIFS('Исходные данные'!$J$2:$J$964,'Исходные данные'!$D$2:$D$964,AE$1,'Исходные данные'!$F$2:$F$964,$A3) -> 0 | AG3: 0 | AH3: 0 | AI3: =SUMIFS('Исходные данные'!$I$2:$I$964,'Исходные данные'!$D$2:$D$964,AI$1,'Исходные данные'!$F$2:$F$964,$A3) -> 0 | AJ3: =SUMIFS('Исходные данные'!$J$2:$J$964,'Исходные данные'!$D$2:$D$964,AI$1,'Исходные данные'!$F$2:$F$964,$A3) -> 0 | AK3: 0 | AL3: 0 | AM3: =SUMIFS('Исходные данные'!$I$2:$I$964,'Исходные данные'!$D$2:$D$964,AM$1,'Исходные данные'!$F$2:$F$964,$A3) -> 0 | AN3: =SUMIFS('Исходные данные'!$J$2:$J$964,'Исходные данные'!$D$2:$D$964,AM$1,'Исходные данные'!$F$2:$F$964,$A3) -> 0 | AO3: 0 | AP3: 0 | AQ3: =SUMIFS('Исходные данные'!$I$2:$I$964,'Исходные данные'!$D$2:$D$964,AQ$1,'Исходные данные'!$F$2:$F$964,$A3) -> 0 | AR3: =SUMIFS('Исходные данные'!$J$2:$J$964,'Исходные данные'!$D$2:$D$964,AQ$1,'Исходные данные'!$F$2:$F$964,$A3) -> 0 | AS3: 0 | AT3: 0 | AU3: =SUMIFS('Исходные данные'!$I$2:$I$964,'Исходные данные'!$D$2:$D$964,AU$1,'Исходные данные'!$F$2:$F$964,$A3) -> 0 | AV3: =SUMIFS('Исходные данные'!$J$2:$J$964,'Исходные данные'!$D$2:$D$964,AU$1,'Исходные данные'!$F$2:$F$964,$A3) -> 0 | AW3: 0 | AX3: 0 | AY3: =SUMIFS('Исходные данные'!$I$2:$I$964,'Исходные данные'!$D$2:$D$964,AY$1,'Исходные данные'!$F$2:$F$964,$A3) -> 0 | AZ3: =SUMIFS('Исходные данные'!$J$2:$J$964,'Исходные данные'!$D$2:$D$964,AY$1,'Исходные данные'!$F$2:$F$964,$A3) -> 0 | BA3: 0 | BB3: 0 | BC3: =SUMIFS('Исходные данные'!$I$2:$I$964,'Исходные данные'!$D$2:$D$964,BC$1,'Исходные данные'!$F$2:$F$964,$A3) -> 0 | BD3: =SUMIFS('Исходные данные'!$J$2:$J$964,'Исходные данные'!$D$2:$D$964,BC$1,'Исходные данные'!$F$2:$F$964,$A3) -> 0 | BE3: 0 | BF3: 0 | BG3: =SUMIFS('Исходные данные'!$I$2:$I$964,'Исходные данные'!$D$2:$D$964,BG$1,'Исходные данные'!$F$2:$F$964,$A3) -> 0 | BH3: =SUMIFS('Исходные данные'!$J$2:$J$964,'Исходные данные'!$D$2:$D$964,BG$1,'Исходные данные'!$F$2:$F$964,$A3) -> 0 | BI3: 5 | BJ3: 3 | BK3: =SUMIFS('Исходные данные'!$I$2:$I$964,'Исходные данные'!$D$2:$D$964,BK$1,'Исходные данные'!$F$2:$F$964,$A3) -> 5 | BL3: =SUMIFS('Исходные данные'!$J$2:$J$964,'Исходные данные'!$D$2:$D$964,BK$1,'Исходные данные'!$F$2:$F$964,$A3) -> 3 | BM3: 4 | BN3: 3 | BO3: =SUMIFS('Исходные данные'!$I$2:$I$964,'Исходные данные'!$D$2:$D$964,BO$1,'Исходные данные'!$F$2:$F$964,$A3) -> 4 | BP3: =SUMIFS('Исходные данные'!$J$2:$J$964,'Исходные данные'!$D$2:$D$964,BO$1,'Исходные данные'!$F$2:$F$964,$A3) -> 3 | BQ3: 0 | BR3: 0 | BS3: =SUMIFS('Исходные данные'!$I$2:$I$964,'Исходные данные'!$D$2:$D$964,BS$1,'Исходные данные'!$F$2:$F$964,$A3) -> 0 | BT3: =SUMIFS('Исходные данные'!$J$2:$J$964,'Исходные данные'!$D$2:$D$964,BS$1,'Исходные данные'!$F$2:$F$964,$A3) -> 0 | BU3: 0 | BV3: 0 | BW3: =SUMIFS('Исходные данные'!$I$2:$I$964,'Исходные данные'!$D$2:$D$964,BW$1,'Исходные данные'!$F$2:$F$964,$A3) -> 0 | BX3: =SUMIFS('Исходные данные'!$J$2:$J$964,'Исходные данные'!$D$2:$D$964,BW$1,'Исходные данные'!$F$2:$F$964,$A3) -> 0 | BY3: 0 | BZ3: 0 | CA3: =SUMIFS('Исходные данные'!$I$2:$I$964,'Исходные данные'!$D$2:$D$964,CA$1,'Исходные данные'!$F$2:$F$964,$A3) -> 0 | CB3: =SUMIFS('Исходные данные'!$J$2:$J$964,'Исходные данные'!$D$2:$D$964,CA$1,'Исходные данные'!$F$2:$F$964,$A3) -> 0 | CC3: 0 | CD3: 0 | CE3: =SUMIFS('Исходные данные'!$I$2:$I$964,'Исходные данные'!$D$2:$D$964,CE$1,'Исходные данные'!$F$2:$F$964,$A3) -> 0 | CF3: =SUMIFS('Исходные данные'!$J$2:$J$964,'Исходные данные'!$D$2:$D$964,CE$1,'Исходные данные'!$F$2:$F$964,$A3) -> 0 | CG3: 0 | CH3: 0 | CI3: =SUMIFS('Исходные данные'!$I$2:$I$964,'Исходные данные'!$D$2:$D$964,CI$1,'Исходные данные'!$F$2:$F$964,$A3) -> 0 | CJ3: =SUMIFS('Исходные данные'!$J$2:$J$964,'Исходные данные'!$D$2:$D$964,CI$1,'Исходные данные'!$F$2:$F$964,$A3) -> 0 | CK3: 0 | CL3: 0 | CM3: =SUMIFS('Исходные данные'!$I$2:$I$964,'Исходные данные'!$D$2:$D$964,CM$1,'Исходные данные'!$F$2:$F$964,$A3) -> 0 | CN3: =SUMIFS('Исходные данные'!$J$2:$J$964,'Исходные данные'!$D$2:$D$964,CM$1,'Исходные данные'!$F$2:$F$964,$A3) -> 0 | CO3: 0 | CP3: 0 | CQ3: =SUMIFS('Исходные данные'!$I$2:$I$964,'Исходные данные'!$D$2:$D$964,CQ$1,'Исходные данные'!$F$2:$F$964,$A3) -> 0 | CR3: =SUMIFS('Исходные данные'!$J$2:$J$964,'Исходные данные'!$D$2:$D$964,CQ$1,'Исходные данные'!$F$2:$F$964,$A3) -> 0 | CS3: 0 | CT3: 0 | CU3: =SUMIFS('Исходные данные'!$I$2:$I$964,'Исходные данные'!$D$2:$D$964,CU$1,'Исходные данные'!$F$2:$F$964,$A3) -> 0 | CV3: =SUMIFS('Исходные данные'!$J$2:$J$964,'Исходные данные'!$D$2:$D$964,CU$1,'Исходные данные'!$F$2:$F$964,$A3) -> 0 | CW3: 0 | CX3: 0 | CY3: =SUMIFS('Исходные данные'!$I$2:$I$964,'Исходные данные'!$D$2:$D$964,CY$1,'Исходные данные'!$F$2:$F$964,$A3) -> 0 | CZ3: =SUMIFS('Исходные данные'!$J$2:$J$964,'Исходные данные'!$D$2:$D$964,CY$1,'Исходные данные'!$F$2:$F$964,$A3) -> 0 | DA3: 0 | DB3: 0 | DC3: =SUMIFS('Исходные данные'!$I$2:$I$964,'Исходные данные'!$D$2:$D$964,DC$1,'Исходные данные'!$F$2:$F$964,$A3) -> 0 | DD3: =SUMIFS('Исходные данные'!$J$2:$J$964,'Исходные данные'!$D$2:$D$964,DC$1,'Исходные данные'!$F$2:$F$964,$A3) -> 0 | DE3: 0 | DF3: 0 | DG3: =SUMIFS('Исходные данные'!$I$2:$I$964,'Исходные данные'!$D$2:$D$964,DG$1,'Исходные данные'!$F$2:$F$964,$A3) -> 0 | DH3: =SUMIFS('Исходные данные'!$J$2:$J$964,'Исходные данные'!$D$2:$D$964,DG$1,'Исходные данные'!$F$2:$F$964,$A3) -> 0 | DI3: 0 | DJ3: 0 | DK3: =SUMIFS('Исходные данные'!$I$2:$I$964,'Исходные данные'!$D$2:$D$964,DK$1,'Исходные данные'!$F$2:$F$964,$A3) -> 0 | DL3: =SUMIFS('Исходные данные'!$J$2:$J$964,'Исходные данные'!$D$2:$D$964,DK$1,'Исходные данные'!$F$2:$F$964,$A3) -> 0 | DM3: 0 | DN3: 0 | DO3: =SUMIFS('Исходные данные'!$I$2:$I$964,'Исходные данные'!$D$2:$D$964,DO$1,'Исходные данные'!$F$2:$F$964,$A3) -> 0 | DP3: =SUMIFS('Исходные данные'!$J$2:$J$964,'Исходные данные'!$D$2:$D$964,DO$1,'Исходные данные'!$F$2:$F$964,$A3) -> 0 | DQ3: 0 | DR3: 0 | DS3: =SUMIFS('Исходные данные'!$I$2:$I$964,'Исходные данные'!$D$2:$D$964,DS$1,'Исходные данные'!$F$2:$F$964,$A3) -> 0 | DT3: =SUMIFS('Исходные данные'!$J$2:$J$964,'Исходные данные'!$D$2:$D$964,DS$1,'Исходные данные'!$F$2:$F$964,$A3) -> 0 | DU3: 0 | DV3: 0 | DW3: =SUMIFS('Исходные данные'!$I$2:$I$964,'Исходные данные'!$D$2:$D$964,DW$1,'Исходные данные'!$F$2:$F$964,$A3) -> 0 | DX3: =SUMIFS('Исходные данные'!$J$2:$J$964,'Исходные данные'!$D$2:$D$964,DW$1,'Исходные данные'!$F$2:$F$964,$A3) -> 0 | DY3: 0 | DZ3: 0 | EA3: =SUMIFS('Исходные данные'!$I$2:$I$964,'Исходные данные'!$D$2:$D$964,EA$1,'Исходные данные'!$F$2:$F$964,$A3) -> 0 | EB3: =SUMIFS('Исходные данные'!$J$2:$J$964,'Исходные данные'!$D$2:$D$964,EA$1,'Исходные данные'!$F$2:$F$964,$A3) -> 0 | EC3: 0 | ED3: 0 | EE3: =SUMIFS('Исходные данные'!$I$2:$I$964,'Исходные данные'!$D$2:$D$964,EE$1,'Исходные данные'!$F$2:$F$964,$A3) -> 0 | EF3: =SUMIFS('Исходные данные'!$J$2:$J$964,'Исходные данные'!$D$2:$D$964,EE$1,'Исходные данные'!$F$2:$F$964,$A3) -> 0 | EG3: 0 | EH3: 0 | EI3: =SUMIFS('Исходные данные'!$I$2:$I$964,'Исходные данные'!$D$2:$D$964,EI$1,'Исходные данные'!$F$2:$F$964,$A3) -> 0 | EJ3: =SUMIFS('Исходные данные'!$J$2:$J$964,'Исходные данные'!$D$2:$D$964,EI$1,'Исходные данные'!$F$2:$F$964,$A3) -> 0 | EK3: 0 | EL3: 0 | EM3: =SUMIFS('Исходные данные'!$I$2:$I$964,'Исходные данные'!$D$2:$D$964,EM$1,'Исходные данные'!$F$2:$F$964,$A3) -> 0 | EN3: =SUMIFS('Исходные данные'!$J$2:$J$964,'Исходные данные'!$D$2:$D$964,EM$1,'Исходные данные'!$F$2:$F$964,$A3) -> 0 | EO3: 0 | EP3: 0 | EQ3: =SUMIFS('Исходные данные'!$I$2:$I$964,'Исходные данные'!$D$2:$D$964,EQ$1,'Исходные данные'!$F$2:$F$964,$A3) -> 0 | ER3: =SUMIFS('Исходные данные'!$J$2:$J$964,'Исходные данные'!$D$2:$D$964,EQ$1,'Исходные данные'!$F$2:$F$964,$A3) -> 0 | ES3: 0 | ET3: 0 | EU3: =SUMIFS('Исходные данные'!$I$2:$I$964,'Исходные данные'!$D$2:$D$964,EU$1,'Исходные данные'!$F$2:$F$964,$A3) -> 0 | EV3: =SUMIFS('Исходные данные'!$J$2:$J$964,'Исходные данные'!$D$2:$D$964,EU$1,'Исходные данные'!$F$2:$F$964,$A3) -> 0 | EW3: 0 | EX3: 0 | EY3: =SUMIFS('Исходные данные'!$I$2:$I$964,'Исходные данные'!$D$2:$D$964,EY$1,'Исходные данные'!$F$2:$F$964,$A3) -> 0 | EZ3: =SUMIFS('Исходные данные'!$J$2:$J$964,'Исходные данные'!$D$2:$D$964,EY$1,'Исходные данные'!$F$2:$F$964,$A3) -> 0 | FA3: 0 | FB3: 0 | FC3: =SUMIFS('Исходные данные'!$I$2:$I$964,'Исходные данные'!$D$2:$D$964,FC$1,'Исходные данные'!$F$2:$F$964,$A3) -> 0 | FD3: =SUMIFS('Исходные данные'!$J$2:$J$964,'Исходные данные'!$D$2:$D$964,FC$1,'Исходные данные'!$F$2:$F$964,$A3) -> 0 | FE3: 0 | FF3: 0 | FG3: =SUMIFS('Исходные данные'!$I$2:$I$964,'Исходные данные'!$D$2:$D$964,FG$1,'Исходные данные'!$F$2:$F$964,$A3) -> 0 | FH3: =SUMIFS('Исходные данные'!$J$2:$J$964,'Исходные данные'!$D$2:$D$964,FG$1,'Исходные данные'!$F$2:$F$964,$A3) -> 0
A4: 47 | B4: Тракторный экскаватор | C4: 10 | D4: =I4+J4+M4+N4+Q4+R4+U4+V4+Y4+Z4+AC4+AD4+AG4+AH4+AK4+AL4+AO4+AP4+AS4+AT4+AW4+AX4+BA4+BB4+BE4+BF4+BI4+BJ4+BM4+BN4+BQ4+BR4+BU4+BV4+BY4+BZ4+CC4+CD4+CG4+CH4+CK4+CL4+CO4+CP4+CS4+CT4+CW4+CX4+DA4+DB4+DE4+DF4+DI4+DJ4+DM4+DN4+DQ4+DR4+DU4+DV4+DY4+DZ4+EC4+ED4+EG4+EH4+EK4+EL4+EO4+EP4+ES4+ET4+EW4+EX4+FA4+FB4+FE4+FF4 -> 10 | E4: =G4+H4 -> 8 | F4: =E4-C4 -> -2 | G4: =K4+O4+S4+W4+AA4+AE4+AI4+AM4+AQ4+AU4+AY4+BC4+BG4+BK4+BO4+BS4+BW4+CA4+CE4+CI4+CM4+CQ4+CU4+CY4+DC4+DG4+DK4+DO4+DS4+DW4+EA4+EE4+EI4+EM4+EQ4+EU4+EY4+FC4+FG4 -> 8 | H4: =L4+P4+T4+X4+AB4+AF4+AJ4+AN4+AR4+AV4+AZ4+BD4+BH4+BL4+BP4+BT4+BX4+CB4+CF4+CJ4+CN4+CR4+CV4+CZ4+DD4+DH4+DL4+DP4+DT4+DX4+EB4+EF4+EJ4+EN4+ER4+EV4+EZ4+FD4+FH4 -> 0 | I4: 1 | J4: 0 | K4: =SUMIFS('Исходные данные'!$I$2:$I$964,'Исходные данные'!$D$2:$D$964,K$1,'Исходные данные'!$F$2:$F$964,$A4) -> 1 | L4: =SUMIFS('Исходные данные'!$J$2:$J$964,'Исходные данные'!$D$2:$D$964,K$1,'Исходные данные'!$F$2:$F$964,$A4) -> 0 | M4: 1 | N4: 0 | O4: =SUMIFS('Исходные данные'!$I$2:$I$964,'Исходные данные'!$D$2:$D$964,O$1,'Исходные данные'!$F$2:$F$964,$A4) -> 1 | P4: =SUMIFS('Исходные данные'!$J$2:$J$964,'Исходные данные'!$D$2:$D$964,O$1,'Исходные данные'!$F$2:$F$964,$A4) -> 0 | Q4: 2 | R4: 0 | S4: =SUMIFS('Исходные данные'!$I$2:$I$964,'Исходные данные'!$D$2:$D$964,S$1,'Исходные данные'!$F$2:$F$964,$A4) -> 2 | T4: =SUMIFS('Исходные данные'!$J$2:$J$964,'Исходные данные'!$D$2:$D$964,S$1,'Исходные данные'!$F$2:$F$964,$A4) -> 0 | U4: 0 | V4: 0 | W4: =SUMIFS('Исходные данные'!$I$2:$I$964,'Исходные данные'!$D$2:$D$964,W$1,'Исходные данные'!$F$2:$F$964,$A4) -> 0 | X4: =SUMIFS('Исходные данные'!$J$2:$J$964,'Исходные данные'!$D$2:$D$964,W$1,'Исходные данные'!$F$2:$F$964,$A4) -> 0 | Y4: 1 | Z4: 0 | AA4: =SUMIFS('Исходные данные'!$I$2:$I$964,'Исходные данные'!$D$2:$D$964,AA$1,'Исходные данные'!$F$2:$F$964,$A4) -> 1 | AB4: =SUMIFS('Исходные данные'!$J$2:$J$964,'Исходные данные'!$D$2:$D$964,AA$1,'Исходные данные'!$F$2:$F$964,$A4) -> 0 | AC4: 0 | AD4: 0 | AE4: =SUMIFS('Исходные данные'!$I$2:$I$964,'Исходные данные'!$D$2:$D$964,AE$1,'Исходные данные'!$F$2:$F$964,$A4) -> 0 | AF4: =SUMIFS('Исходные данные'!$J$2:$J$964,'Исходные данные'!$D$2:$D$964,AE$1,'Исходные данные'!$F$2:$F$964,$A4) -> 0 | AG4: 4 | AH4: 0 | AI4: =SUMIFS('Исходные данные'!$I$2:$I$964,'Исходные данные'!$D$2:$D$964,AI$1,'Исходные данные'!$F$2:$F$964,$A4) -> 2 | AJ4: =SUMIFS('Исходные данные'!$J$2:$J$964,'Исходные данные'!$D$2:$D$964,AI$1,'Исходные данные'!$F$2:$F$964,$A4) -> 0 | AK4: 1 | AL4: 0 | AM4: =SUMIFS('Исходные данные'!$I$2:$I$964,'Исходные данные'!$D$2:$D$964,AM$1,'Исходные данные'!$F$2:$F$964,$A4) -> 1 | AN4: =SUMIFS('Исходные данные'!$J$2:$J$964,'Исходные данные'!$D$2:$D$964,AM$1,'Исходные данные'!$F$2:$F$964,$A4) -> 0 | AO4: 0 | AP4: 0 | AQ4: =SUMIFS('Исходные данные'!$I$2:$I$964,'Исходные данные'!$D$2:$D$964,AQ$1,'Исходные данные'!$F$2:$F$964,$A4) -> 0 | AR4: =SUMIFS('Исходные данные'!$J$2:$J$964,'Исходные данные'!$D$2:$D$964,AQ$1,'Исходные данные'!$F$2:$F$964,$A4) -> 0 | AS4: 0 | AT4: 0 | AU4: =SUMIFS('Исходные данные'!$I$2:$I$964,'Исходные данные'!$D$2:$D$964,AU$1,'Исходные данные'!$F$2:$F$964,$A4) -> 0 | AV4: =SUMIFS('Исходные данные'!$J$2:$J$964,'Исходные данные'!$D$2:$D$964,AU$1,'Исходные данные'!$F$2:$F$964,$A4) -> 0 | AW4: 0 | AX4: 0 | AY4: =SUMIFS('Исходные данные'!$I$2:$I$964,'Исходные данные'!$D$2:$D$964,AY$1,'Исходные данные'!$F$2:$F$964,$A4) -> 0 | AZ4: =SUMIFS('Исходные данные'!$J$2:$J$964,'Исходные данные'!$D$2:$D$964,AY$1,'Исходные данные'!$F$2:$F$964,$A4) -> 0 | BA4: 0 | BB4: 0 | BC4: =SUMIFS('Исходные данные'!$I$2:$I$964,'Исходные данные'!$D$2:$D$964,BC$1,'Исходные данные'!$F$2:$F$964,$A4) -> 0 | BD4: =SUMIFS('Исходные данные'!$J$2:$J$964,'Исходные данные'!$D$2:$D$964,BC$1,'Исходные данные'!$F$2:$F$964,$A4) -> 0 | BE4: 0 | BF4: 0 | BG4: =SUMIFS('Исходные данные'!$I$2:$I$964,'Исходные данные'!$D$2:$D$964,BG$1,'Исходные данные'!$F$2:$F$964,$A4) -> 0 | BH4: =SUMIFS('Исходные данные'!$J$2:$J$964,'Исходные данные'!$D$2:$D$964,BG$1,'Исходные данные'!$F$2:$F$964,$A4) -> 0 | BI4: 0 | BJ4: 0 | BK4: =SUMIFS('Исходные данные'!$I$2:$I$964,'Исходные данные'!$D$2:$D$964,BK$1,'Исходные данные'!$F$2:$F$964,$A4) -> 0 | BL4: =SUMIFS('Исходные данные'!$J$2:$J$964,'Исходные данные'!$D$2:$D$964,BK$1,'Исходные данные'!$F$2:$F$964,$A4) -> 0 | BM4: 0 | BN4: 0 | BO4: =SUMIFS('Исходные данные'!$I$2:$I$964,'Исходные данные'!$D$2:$D$964,BO$1,'Исходные данные'!$F$2:$F$964,$A4) -> 0 | BP4: =SUMIFS('Исходные данные'!$J$2:$J$964,'Исходные данные'!$D$2:$D$964,BO$1,'Исходные данные'!$F$2:$F$964,$A4) -> 0 | BQ4: 0 | BR4: 0 | BS4: =SUMIFS('Исходные данные'!$I$2:$I$964,'Исходные данные'!$D$2:$D$964,BS$1,'Исходные данные'!$F$2:$F$964,$A4) -> 0 | BT4: =SUMIFS('Исходные данные'!$J$2:$J$964,'Исходные данные'!$D$2:$D$964,BS$1,'Исходные данные'!$F$2:$F$964,$A4) -> 0 | BU4: 0 | BV4: 0 | BW4: =SUMIFS('Исходные данные'!$I$2:$I$964,'Исходные данные'!$D$2:$D$964,BW$1,'Исходные данные'!$F$2:$F$964,$A4) -> 0 | BX4: =SUMIFS('Исходные данные'!$J$2:$J$964,'Исходные данные'!$D$2:$D$964,BW$1,'Исходные данные'!$F$2:$F$964,$A4) -> 0 | BY4: 0 | BZ4: 0 | CA4: =SUMIFS('Исходные данные'!$I$2:$I$964,'Исходные данные'!$D$2:$D$964,CA$1,'Исходные данные'!$F$2:$F$964,$A4) -> 0 | CB4: =SUMIFS('Исходные данные'!$J$2:$J$964,'Исходные данные'!$D$2:$D$964,CA$1,'Исходные данные'!$F$2:$F$964,$A4) -> 0 | CC4: 0 | CD4: 0 | CE4: =SUMIFS('Исходные данные'!$I$2:$I$964,'Исходные данные'!$D$2:$D$964,CE$1,'Исходные данные'!$F$2:$F$964,$A4) -> 0 | CF4: =SUMIFS('Исходные данные'!$J$2:$J$964,'Исходные данные'!$D$2:$D$964,CE$1,'Исходные данные'!$F$2:$F$964,$A4) -> 0 | CG4: 0 | CH4: 0 | CI4: =SUMIFS('Исходные данные'!$I$2:$I$964,'Исходные данные'!$D$2:$D$964,CI$1,'Исходные данные'!$F$2:$F$964,$A4) -> 0 | CJ4: =SUMIFS('Исходные данные'!$J$2:$J$964,'Исходные данные'!$D$2:$D$964,CI$1,'Исходные данные'!$F$2:$F$964,$A4) -> 0 | CK4: 0 | CL4: 0 | CM4: =SUMIFS('Исходные данные'!$I$2:$I$964,'Исходные данные'!$D$2:$D$964,CM$1,'Исходные данные'!$F$2:$F$964,$A4) -> 0 | CN4: =SUMIFS('Исходные данные'!$J$2:$J$964,'Исходные данные'!$D$2:$D$964,CM$1,'Исходные данные'!$F$2:$F$964,$A4) -> 0 | CO4: 0 | CP4: 0 | CQ4: =SUMIFS('Исходные данные'!$I$2:$I$964,'Исходные данные'!$D$2:$D$964,CQ$1,'Исходные данные'!$F$2:$F$964,$A4) -> 0 | CR4: =SUMIFS('Исходные данные'!$J$2:$J$964,'Исходные данные'!$D$2:$D$964,CQ$1,'Исходные данные'!$F$2:$F$964,$A4) -> 0 | CS4: 0 | CT4: 0 | CU4: =SUMIFS('Исходные данные'!$I$2:$I$964,'Исходные данные'!$D$2:$D$964,CU$1,'Исходные данные'!$F$2:$F$964,$A4) -> 0 | CV4: =SUMIFS('Исходные данные'!$J$2:$J$964,'Исходные данные'!$D$2:$D$964,CU$1,'Исходные данные'!$F$2:$F$964,$A4) -> 0 | CW4: 0 | CX4: 0 | CY4: =SUMIFS('Исходные данные'!$I$2:$I$964,'Исходные данные'!$D$2:$D$964,CY$1,'Исходные данные'!$F$2:$F$964,$A4) -> 0 | CZ4: =SUMIFS('Исходные данные'!$J$2:$J$964,'Исходные данные'!$D$2:$D$964,CY$1,'Исходные данные'!$F$2:$F$964,$A4) -> 0 | DA4: 0 | DB4: 0 | DC4: =SUMIFS('Исходные данные'!$I$2:$I$964,'Исходные данные'!$D$2:$D$964,DC$1,'Исходные данные'!$F$2:$F$964,$A4) -> 0 | DD4: =SUMIFS('Исходные данные'!$J$2:$J$964,'Исходные данные'!$D$2:$D$964,DC$1,'Исходные данные'!$F$2:$F$964,$A4) -> 0 | DE4: 0 | DF4: 0 | DG4: =SUMIFS('Исходные данные'!$I$2:$I$964,'Исходные данные'!$D$2:$D$964,DG$1,'Исходные данные'!$F$2:$F$964,$A4) -> 0 | DH4: =SUMIFS('Исходные данные'!$J$2:$J$964,'Исходные данные'!$D$2:$D$964,DG$1,'Исходные данные'!$F$2:$F$964,$A4) -> 0 | DI4: 0 | DJ4: 0 | DK4: =SUMIFS('Исходные данные'!$I$2:$I$964,'Исходные данные'!$D$2:$D$964,DK$1,'Исходные данные'!$F$2:$F$964,$A4) -> 0 | DL4: =SUMIFS('Исходные данные'!$J$2:$J$964,'Исходные данные'!$D$2:$D$964,DK$1,'Исходные данные'!$F$2:$F$964,$A4) -> 0 | DM4: 0 | DN4: 0 | DO4: =SUMIFS('Исходные данные'!$I$2:$I$964,'Исходные данные'!$D$2:$D$964,DO$1,'Исходные данные'!$F$2:$F$964,$A4) -> 0 | DP4: =SUMIFS('Исходные данные'!$J$2:$J$964,'Исходные данные'!$D$2:$D$964,DO$1,'Исходные данные'!$F$2:$F$964,$A4) -> 0 | DQ4: 0 | DR4: 0 | DS4: =SUMIFS('Исходные данные'!$I$2:$I$964,'Исходные данные'!$D$2:$D$964,DS$1,'Исходные данные'!$F$2:$F$964,$A4) -> 0 | DT4: =SUMIFS('Исходные данные'!$J$2:$J$964,'Исходные данные'!$D$2:$D$964,DS$1,'Исходные данные'!$F$2:$F$964,$A4) -> 0 | DU4: 0 | DV4: 0 | DW4: =SUMIFS('Исходные данные'!$I$2:$I$964,'Исходные данные'!$D$2:$D$964,DW$1,'Исходные данные'!$F$2:$F$964,$A4) -> 0 | DX4: =SUMIFS('Исходные данные'!$J$2:$J$964,'Исходные данные'!$D$2:$D$964,DW$1,'Исходные данные'!$F$2:$F$964,$A4) -> 0 | DY4: 0 | DZ4: 0 | EA4: =SUMIFS('Исходные данные'!$I$2:$I$964,'Исходные данные'!$D$2:$D$964,EA$1,'Исходные данные'!$F$2:$F$964,$A4) -> 0 | EB4: =SUMIFS('Исходные данные'!$J$2:$J$964,'Исходные данные'!$D$2:$D$964,EA$1,'Исходные данные'!$F$2:$F$964,$A4) -> 0 | EC4: 0 | ED4: 0 | EE4: =SUMIFS('Исходные данные'!$I$2:$I$964,'Исходные данные'!$D$2:$D$964,EE$1,'Исходные данные'!$F$2:$F$964,$A4) -> 0 | EF4: =SUMIFS('Исходные данные'!$J$2:$J$964,'Исходные данные'!$D$2:$D$964,EE$1,'Исходные данные'!$F$2:$F$964,$A4) -> 0 | EG4: 0 | EH4: 0 | EI4: =SUMIFS('Исходные данные'!$I$2:$I$964,'Исходные данные'!$D$2:$D$964,EI$1,'Исходные данные'!$F$2:$F$964,$A4) -> 0 | EJ4: =SUMIFS('Исходные данные'!$J$2:$J$964,'Исходные данные'!$D$2:$D$964,EI$1,'Исходные данные'!$F$2:$F$964,$A4) -> 0 | EK4: 0 | EL4: 0 | EM4: =SUMIFS('Исходные данные'!$I$2:$I$964,'Исходные данные'!$D$2:$D$964,EM$1,'Исходные данные'!$F$2:$F$964,$A4) -> 0 | EN4: =SUMIFS('Исходные данные'!$J$2:$J$964,'Исходные данные'!$D$2:$D$964,EM$1,'Исходные данные'!$F$2:$F$964,$A4) -> 0 | EO4: 0 | EP4: 0 | EQ4: =SUMIFS('Исходные данные'!$I$2:$I$964,'Исходные данные'!$D$2:$D$964,EQ$1,'Исходные данные'!$F$2:$F$964,$A4) -> 0 | ER4: =SUMIFS('Исходные данные'!$J$2:$J$964,'Исходные данные'!$D$2:$D$964,EQ$1,'Исходные данные'!$F$2:$F$964,$A4) -> 0 | ES4: 0 | ET4: 0 | EU4: =SUMIFS('Исходные данные'!$I$2:$I$964,'Исходные данные'!$D$2:$D$964,EU$1,'Исходные данные'!$F$2:$F$964,$A4) -> 0 | EV4: =SUMIFS('Исходные данные'!$J$2:$J$964,'Исходные данные'!$D$2:$D$964,EU$1,'Исходные данные'!$F$2:$F$964,$A4) -> 0 | EW4: 0 | EX4: 0 | EY4: =SUMIFS('Исходные данные'!$I$2:$I$964,'Исходные данные'!$D$2:$D$964,EY$1,'Исходные данные'!$F$2:$F$964,$A4) -> 0 | EZ4: =SUMIFS('Исходные данные'!$J$2:$J$964,'Исходные данные'!$D$2:$D$964,EY$1,'Исходные данные'!$F$2:$F$964,$A4) -> 0 | FA4: 0 | FB4: 0 | FC4: =SUMIFS('Исходные данные'!$I$2:$I$964,'Исходные данные'!$D$2:$D$964,FC$1,'Исходные данные'!$F$2:$F$964,$A4) -> 0 | FD4: =SUMIFS('Исходные данные'!$J$2:$J$964,'Исходные данные'!$D$2:$D$964,FC$1,'Исходные данные'!$F$2:$F$964,$A4) -> 0 | FE4: 0 | FF4: 0 | FG4: =SUMIFS('Исходные данные'!$I$2:$I$964,'Исходные данные'!$D$2:$D$964,FG$1,'Исходные данные'!$F$2:$F$964,$A4) -> 0 | FH4: =SUMIFS('Исходные данные'!$J$2:$J$964,'Исходные данные'!$D$2:$D$964,FG$1,'Исходные данные'!$F$2:$F$964,$A4) -> 0
A5: 49 | B5: Вакуумная установка | C5: 15 | D5: =I5+J5+M5+N5+Q5+R5+U5+V5+Y5+Z5+AC5+AD5+AG5+AH5+AK5+AL5+AO5+AP5+AS5+AT5+AW5+AX5+BA5+BB5+BE5+BF5+BI5+BJ5+BM5+BN5+BQ5+BR5+BU5+BV5+BY5+BZ5+CC5+CD5+CG5+CH5+CK5+CL5+CO5+CP5+CS5+CT5+CW5+CX5+DA5+DB5+DE5+DF5+DI5+DJ5+DM5+DN5+DQ5+DR5+DU5+DV5+DY5+DZ5+EC5+ED5+EG5+EH5+EK5+EL5+EO5+EP5+ES5+ET5+EW5+EX5+FA5+FB5+FE5+FF5 -> 15 | E5: =G5+H5 -> 13 | F5: =E5-C5 -> -2 | G5: =K5+O5+S5+W5+AA5+AE5+AI5+AM5+AQ5+AU5+AY5+BC5+BG5+BK5+BO5+BS5+BW5+CA5+CE5+CI5+CM5+CQ5+CU5+CY5+DC5+DG5+DK5+DO5+DS5+DW5+EA5+EE5+EI5+EM5+EQ5+EU5+EY5+FC5+FG5 -> 7 | H5: =L5+P5+T5+X5+AB5+AF5+AJ5+AN5+AR5+AV5+AZ5+BD5+BH5+BL5+BP5+BT5+BX5+CB5+CF5+CJ5+CN5+CR5+CV5+CZ5+DD5+DH5+DL5+DP5+DT5+DX5+EB5+EF5+EJ5+EN5+ER5+EV5+EZ5+FD5+FH5 -> 6 | I5: 2 | J5: 2 | K5: =SUMIFS('Исходные данные'!$I$2:$I$964,'Исходные данные'!$D$2:$D$964,K$1,'Исходные данные'!$F$2:$F$964,$A5) -> 2 | L5: =SUMIFS('Исходные данные'!$J$2:$J$964,'Исходные данные'!$D$2:$D$964,K$1,'Исходные данные'!$F$2:$F$964,$A5) -> 2 | M5: 1 | N5: 0 | O5: =SUMIFS('Исходные данные'!$I$2:$I$964,'Исходные данные'!$D$2:$D$964,O$1,'Исходные данные'!$F$2:$F$964,$A5) -> 1 | P5: =SUMIFS('Исходные данные'!$J$2:$J$964,'Исходные данные'!$D$2:$D$964,O$1,'Исходные данные'!$F$2:$F$964,$A5) -> 0 | Q5: 2 | R5: 1 | S5: =SUMIFS('Исходные данные'!$I$2:$I$964,'Исходные данные'!$D$2:$D$964,S$1,'Исходные данные'!$F$2:$F$964,$A5) -> 2 | T5: =SUMIFS('Исходные данные'!$J$2:$J$964,'Исходные данные'!$D$2:$D$964,S$1,'Исходные данные'!$F$2:$F$964,$A5) -> 1 | U5: 0 | V5: 0 | W5: =SUMIFS('Исходные данные'!$I$2:$I$964,'Исходные данные'!$D$2:$D$964,W$1,'Исходные данные'!$F$2:$F$964,$A5) -> 0 | X5: =SUMIFS('Исходные данные'!$J$2:$J$964,'Исходные данные'!$D$2:$D$964,W$1,'Исходные данные'!$F$2:$F$964,$A5) -> 0 | Y5: 0 | Z5: 0 | AA5: =SUMIFS('Исходные данные'!$I$2:$I$964,'Исходные данные'!$D$2:$D$964,AA$1,'Исходные данные'!$F$2:$F$964,$A5) -> 0 | AB5: =SUMIFS('Исходные данные'!$J$2:$J$964,'Исходные данные'!$D$2:$D$964,AA$1,'Исходные данные'!$F$2:$F$964,$A5) -> 0 | AC5: 0 | AD5: 0 | AE5: =SUMIFS('Исходные данные'!$I$2:$I$964,'Исходные данные'!$D$2:$D$964,AE$1,'Исходные данные'!$F$2:$F$964,$A5) -> 0 | AF5: =SUMIFS('Исходные данные'!$J$2:$J$964,'Исходные данные'!$D$2:$D$964,AE$1,'Исходные данные'!$F$2:$F$964,$A5) -> 0 | AG5: 0 | AH5: 0 | AI5: =SUMIFS('Исходные данные'!$I$2:$I$964,'Исходные данные'!$D$2:$D$964,AI$1,'Исходные данные'!$F$2:$F$964,$A5) -> 0 | AJ5: =SUMIFS('Исходные данные'!$J$2:$J$964,'Исходные данные'!$D$2:$D$964,AI$1,'Исходные данные'!$F$2:$F$964,$A5) -> 0 | AK5: 0 | AL5: 0 | AM5: =SUMIFS('Исходные данные'!$I$2:$I$964,'Исходные данные'!$D$2:$D$964,AM$1,'Исходные данные'!$F$2:$F$964,$A5) -> 0 | AN5: =SUMIFS('Исходные данные'!$J$2:$J$964,'Исходные данные'!$D$2:$D$964,AM$1,'Исходные данные'!$F$2:$F$964,$A5) -> 0 | AO5: 1 | AP5: 0 | AQ5: =SUMIFS('Исходные данные'!$I$2:$I$964,'Исходные данные'!$D$2:$D$964,AQ$1,'Исходные данные'!$F$2:$F$964,$A5) -> 1 | AR5: =SUMIFS('Исходные данные'!$J$2:$J$964,'Исходные данные'!$D$2:$D$964,AQ$1,'Исходные данные'!$F$2:$F$964,$A5) -> 0 | AS5: 0 | AT5: 0 | AU5: =SUMIFS('Исходные данные'!$I$2:$I$964,'Исходные данные'!$D$2:$D$964,AU$1,'Исходные данные'!$F$2:$F$964,$A5) -> 0 | AV5: =SUMIFS('Исходные данные'!$J$2:$J$964,'Исходные данные'!$D$2:$D$964,AU$1,'Исходные данные'!$F$2:$F$964,$A5) -> 0 | AW5: 0 | AX5: 0 | AY5: =SUMIFS('Исходные данные'!$I$2:$I$964,'Исходные данные'!$D$2:$D$964,AY$1,'Исходные данные'!$F$2:$F$964,$A5) -> 0 | AZ5: =SUMIFS('Исходные данные'!$J$2:$J$964,'Исходные данные'!$D$2:$D$964,AY$1,'Исходные данные'!$F$2:$F$964,$A5) -> 0 | BA5: 0 | BB5: 0 | BC5: =SUMIFS('Исходные данные'!$I$2:$I$964,'Исходные данные'!$D$2:$D$964,BC$1,'Исходные данные'!$F$2:$F$964,$A5) -> 0 | BD5: =SUMIFS('Исходные данные'!$J$2:$J$964,'Исходные данные'!$D$2:$D$964,BC$1,'Исходные данные'!$F$2:$F$964,$A5) -> 0 | BE5: 0 | BF5: 0 | BG5: =SUMIFS('Исходные данные'!$I$2:$I$964,'Исходные данные'!$D$2:$D$964,BG$1,'Исходные данные'!$F$2:$F$964,$A5) -> 0 | BH5: =SUMIFS('Исходные данные'!$J$2:$J$964,'Исходные данные'!$D$2:$D$964,BG$1,'Исходные данные'!$F$2:$F$964,$A5) -> 0 | BI5: 2 | BJ5: 2 | BK5: =SUMIFS('Исходные данные'!$I$2:$I$964,'Исходные данные'!$D$2:$D$964,BK$1,'Исходные данные'!$F$2:$F$964,$A5) -> 1 | BL5: =SUMIFS('Исходные данные'!$J$2:$J$964,'Исходные данные'!$D$2:$D$964,BK$1,'Исходные данные'!$F$2:$F$964,$A5) -> 2 | BM5: 1 | BN5: 1 | BO5: =SUMIFS('Исходные данные'!$I$2:$I$964,'Исходные данные'!$D$2:$D$964,BO$1,'Исходные данные'!$F$2:$F$964,$A5) -> 0 | BP5: =SUMIFS('Исходные данные'!$J$2:$J$964,'Исходные данные'!$D$2:$D$964,BO$1,'Исходные данные'!$F$2:$F$964,$A5) -> 1 | BQ5: 0 | BR5: 0 | BS5: =SUMIFS('Исходные данные'!$I$2:$I$964,'Исходные данные'!$D$2:$D$964,BS$1,'Исходные данные'!$F$2:$F$964,$A5) -> 0 | BT5: =SUMIFS('Исходные данные'!$J$2:$J$964,'Исходные данные'!$D$2:$D$964,BS$1,'Исходные данные'!$F$2:$F$964,$A5) -> 0 | BU5: 0 | BV5: 0 | BW5: =SUMIFS('Исходные данные'!$I$2:$I$964,'Исходные данные'!$D$2:$D$964,BW$1,'Исходные данные'!$F$2:$F$964,$A5) -> 0 | BX5: =SUMIFS('Исходные данные'!$J$2:$J$964,'Исходные данные'!$D$2:$D$964,BW$1,'Исходные данные'!$F$2:$F$964,$A5) -> 0 | BY5: 0 | BZ5: 0 | CA5: =SUMIFS('Исходные данные'!$I$2:$I$964,'Исходные данные'!$D$2:$D$964,CA$1,'Исходные данные'!$F$2:$F$964,$A5) -> 0 | CB5: =SUMIFS('Исходные данные'!$J$2:$J$964,'Исходные данные'!$D$2:$D$964,CA$1,'Исходные данные'!$F$2:$F$964,$A5) -> 0 | CC5: 0 | CD5: 0 | CE5: =SUMIFS('Исходные данные'!$I$2:$I$964,'Исходные данные'!$D$2:$D$964,CE$1,'Исходные данные'!$F$2:$F$964,$A5) -> 0 | CF5: =SUMIFS('Исходные данные'!$J$2:$J$964,'Исходные данные'!$D$2:$D$964,CE$1,'Исходные данные'!$F$2:$F$964,$A5) -> 0 | CG5: 0 | CH5: 0 | CI5: =SUMIFS('Исходные данные'!$I$2:$I$964,'Исходные данные'!$D$2:$D$964,CI$1,'Исходные данные'!$F$2:$F$964,$A5) -> 0 | CJ5: =SUMIFS('Исходные данные'!$J$2:$J$964,'Исходные данные'!$D$2:$D$964,CI$1,'Исходные данные'!$F$2:$F$964,$A5) -> 0 | CK5: 0 | CL5: 0 | CM5: =SUMIFS('Исходные данные'!$I$2:$I$964,'Исходные данные'!$D$2:$D$964,CM$1,'Исходные данные'!$F$2:$F$964,$A5) -> 0 | CN5: =SUMIFS('Исходные данные'!$J$2:$J$964,'Исходные данные'!$D$2:$D$964,CM$1,'Исходные данные'!$F$2:$F$964,$A5) -> 0 | CO5: 0 | CP5: 0 | CQ5: =SUMIFS('Исходные данные'!$I$2:$I$964,'Исходные данные'!$D$2:$D$964,CQ$1,'Исходные данные'!$F$2:$F$964,$A5) -> 0 | CR5: =SUMIFS('Исходные данные'!$J$2:$J$964,'Исходные данные'!$D$2:$D$964,CQ$1,'Исходные данные'!$F$2:$F$964,$A5) -> 0 | CS5: 0 | CT5: 0 | CU5: =SUMIFS('Исходные данные'!$I$2:$I$964,'Исходные данные'!$D$2:$D$964,CU$1,'Исходные данные'!$F$2:$F$964,$A5) -> 0 | CV5: =SUMIFS('Исходные данные'!$J$2:$J$964,'Исходные данные'!$D$2:$D$964,CU$1,'Исходные данные'!$F$2:$F$964,$A5) -> 0 | CW5: 0 | CX5: 0 | CY5: =SUMIFS('Исходные данные'!$I$2:$I$964,'Исходные данные'!$D$2:$D$964,CY$1,'Исходные данные'!$F$2:$F$964,$A5) -> 0 | CZ5: =SUMIFS('Исходные данные'!$J$2:$J$964,'Исходные данные'!$D$2:$D$964,CY$1,'Исходные данные'!$F$2:$F$964,$A5) -> 0 | DA5: 0 | DB5: 0 | DC5: =SUMIFS('Исходные данные'!$I$2:$I$964,'Исходные данные'!$D$2:$D$964,DC$1,'Исходные данные'!$F$2:$F$964,$A5) -> 0 | DD5: =SUMIFS('Исходные данные'!$J$2:$J$964,'Исходные данные'!$D$2:$D$964,DC$1,'Исходные данные'!$F$2:$F$964,$A5) -> 0 | DE5: 0 | DF5: 0 | DG5: =SUMIFS('Исходные данные'!$I$2:$I$964,'Исходные данные'!$D$2:$D$964,DG$1,'Исходные данные'!$F$2:$F$964,$A5) -> 0 | DH5: =SUMIFS('Исходные данные'!$J$2:$J$964,'Исходные данные'!$D$2:$D$964,DG$1,'Исходные данные'!$F$2:$F$964,$A5) -> 0 | DI5: 0 | DJ5: 0 | DK5: =SUMIFS('Исходные данные'!$I$2:$I$964,'Исходные данные'!$D$2:$D$964,DK$1,'Исходные данные'!$F$2:$F$964,$A5) -> 0 | DL5: =SUMIFS('Исходные данные'!$J$2:$J$964,'Исходные данные'!$D$2:$D$964,DK$1,'Исходные данные'!$F$2:$F$964,$A5) -> 0 | DM5: 0 | DN5: 0 | DO5: =SUMIFS('Исходные данные'!$I$2:$I$964,'Исходные данные'!$D$2:$D$964,DO$1,'Исходные данные'!$F$2:$F$964,$A5) -> 0 | DP5: =SUMIFS('Исходные данные'!$J$2:$J$964,'Исходные данные'!$D$2:$D$964,DO$1,'Исходные данные'!$F$2:$F$964,$A5) -> 0 | DQ5: 0 | DR5: 0 | DS5: =SUMIFS('Исходные данные'!$I$2:$I$964,'Исходные данные'!$D$2:$D$964,DS$1,'Исходные данные'!$F$2:$F$964,$A5) -> 0 | DT5: =SUMIFS('Исходные данные'!$J$2:$J$964,'Исходные данные'!$D$2:$D$964,DS$1,'Исходные данные'!$F$2:$F$964,$A5) -> 0 | DU5: 0 | DV5: 0 | DW5: =SUMIFS('Исходные данные'!$I$2:$I$964,'Исходные данные'!$D$2:$D$964,DW$1,'Исходные данные'!$F$2:$F$964,$A5) -> 0 | DX5: =SUMIFS('Исходные данные'!$J$2:$J$964,'Исходные данные'!$D$2:$D$964,DW$1,'Исходные данные'!$F$2:$F$964,$A5) -> 0 | DY5: 0 | DZ5: 0 | EA5: =SUMIFS('Исходные данные'!$I$2:$I$964,'Исходные данные'!$D$2:$D$964,EA$1,'Исходные данные'!$F$2:$F$964,$A5) -> 0 | EB5: =SUMIFS('Исходные данные'!$J$2:$J$964,'Исходные данные'!$D$2:$D$964,EA$1,'Исходные данные'!$F$2:$F$964,$A5) -> 0 | EC5: 0 | ED5: 0 | EE5: =SUMIFS('Исходные данные'!$I$2:$I$964,'Исходные данные'!$D$2:$D$964,EE$1,'Исходные данные'!$F$2:$F$964,$A5) -> 0 | EF5: =SUMIFS('Исходные данные'!$J$2:$J$964,'Исходные данные'!$D$2:$D$964,EE$1,'Исходные данные'!$F$2:$F$964,$A5) -> 0 | EG5: 0 | EH5: 0 | EI5: =SUMIFS('Исходные данные'!$I$2:$I$964,'Исходные данные'!$D$2:$D$964,EI$1,'Исходные данные'!$F$2:$F$964,$A5) -> 0 | EJ5: =SUMIFS('Исходные данные'!$J$2:$J$964,'Исходные данные'!$D$2:$D$964,EI$1,'Исходные данные'!$F$2:$F$964,$A5) -> 0 | EK5: 0 | EL5: 0 | EM5: =SUMIFS('Исходные данные'!$I$2:$I$964,'Исходные данные'!$D$2:$D$964,EM$1,'Исходные данные'!$F$2:$F$964,$A5) -> 0 | EN5: =SUMIFS('Исходные данные'!$J$2:$J$964,'Исходные данные'!$D$2:$D$964,EM$1,'Исходные данные'!$F$2:$F$964,$A5) -> 0 | EO5: 0 | EP5: 0 | EQ5: =SUMIFS('Исходные данные'!$I$2:$I$964,'Исходные данные'!$D$2:$D$964,EQ$1,'Исходные данные'!$F$2:$F$964,$A5) -> 0 | ER5: =SUMIFS('Исходные данные'!$J$2:$J$964,'Исходные данные'!$D$2:$D$964,EQ$1,'Исходные данные'!$F$2:$F$964,$A5) -> 0 | ES5: 0 | ET5: 0 | EU5: =SUMIFS('Исходные данные'!$I$2:$I$964,'Исходные данные'!$D$2:$D$964,EU$1,'Исходные данные'!$F$2:$F$964,$A5) -> 0 | EV5: =SUMIFS('Исходные данные'!$J$2:$J$964,'Исходные данные'!$D$2:$D$964,EU$1,'Исходные данные'!$F$2:$F$964,$A5) -> 0 | EW5: 0 | EX5: 0 | EY5: =SUMIFS('Исходные данные'!$I$2:$I$964,'Исходные данные'!$D$2:$D$964,EY$1,'Исходные данные'!$F$2:$F$964,$A5) -> 0 | EZ5: =SUMIFS('Исходные данные'!$J$2:$J$964,'Исходные данные'!$D$2:$D$964,EY$1,'Исходные данные'!$F$2:$F$964,$A5) -> 0 | FA5: 0 | FB5: 0 | FC5: =SUMIFS('Исходные данные'!$I$2:$I$964,'Исходные данные'!$D$2:$D$964,FC$1,'Исходные данные'!$F$2:$F$964,$A5) -> 0 | FD5: =SUMIFS('Исходные данные'!$J$2:$J$964,'Исходные данные'!$D$2:$D$964,FC$1,'Исходные данные'!$F$2:$F$964,$A5) -> 0 | FE5: 0 | FF5: 0 | FG5: =SUMIFS('Исходные данные'!$I$2:$I$964,'Исходные данные'!$D$2:$D$964,FG$1,'Исходные данные'!$F$2:$F$964,$A5) -> 0 | FH5: =SUMIFS('Исходные данные'!$J$2:$J$964,'Исходные данные'!$D$2:$D$964,FG$1,'Исходные данные'!$F$2:$F$964,$A5) -> 0
A6: 28 | B6: Кран 16-20т | C6: 25 | D6: =I6+J6+M6+N6+Q6+R6+U6+V6+Y6+Z6+AC6+AD6+AG6+AH6+AK6+AL6+AO6+AP6+AS6+AT6+AW6+AX6+BA6+BB6+BE6+BF6+BI6+BJ6+BM6+BN6+BQ6+BR6+BU6+BV6+BY6+BZ6+CC6+CD6+CG6+CH6+CK6+CL6+CO6+CP6+CS6+CT6+CW6+CX6+DA6+DB6+DE6+DF6+DI6+DJ6+DM6+DN6+DQ6+DR6+DU6+DV6+DY6+DZ6+EC6+ED6+EG6+EH6+EK6+EL6+EO6+EP6+ES6+ET6+EW6+EX6+FA6+FB6+FE6+FF6 -> 25 | E6: =G6+H6 -> 23 | F6: =E6-C6 -> -2 | G6: =K6+O6+S6+W6+AA6+AE6+AI6+AM6+AQ6+AU6+AY6+BC6+BG6+BK6+BO6+BS6+BW6+CA6+CE6+CI6+CM6+CQ6+CU6+CY6+DC6+DG6+DK6+DO6+DS6+DW6+EA6+EE6+EI6+EM6+EQ6+EU6+EY6+FC6+FG6 -> 16 | H6: =L6+P6+T6+X6+AB6+AF6+AJ6+AN6+AR6+AV6+AZ6+BD6+BH6+BL6+BP6+BT6+BX6+CB6+CF6+CJ6+CN6+CR6+CV6+CZ6+DD6+DH6+DL6+DP6+DT6+DX6+EB6+EF6+EJ6+EN6+ER6+EV6+EZ6+FD6+FH6 -> 7 | I6: 1 | J6: 0 | K6: =SUMIFS('Исходные данные'!$I$2:$I$964,'Исходные данные'!$D$2:$D$964,K$1,'Исходные данные'!$F$2:$F$964,$A6) -> 1 | L6: =SUMIFS('Исходные данные'!$J$2:$J$964,'Исходные данные'!$D$2:$D$964,K$1,'Исходные данные'!$F$2:$F$964,$A6) -> 0 | M6: 1 | N6: 0 | O6: =SUMIFS('Исходные данные'!$I$2:$I$964,'Исходные данные'!$D$2:$D$964,O$1,'Исходные данные'!$F$2:$F$964,$A6) -> 1 | P6: =SUMIFS('Исходные данные'!$J$2:$J$964,'Исходные данные'!$D$2:$D$964,O$1,'Исходные данные'!$F$2:$F$964,$A6) -> 0 | Q6: 2 | R6: 0 | S6: =SUMIFS('Исходные данные'!$I$2:$I$964,'Исходные данные'!$D$2:$D$964,S$1,'Исходные данные'!$F$2:$F$964,$A6) -> 2 | T6: =SUMIFS('Исходные данные'!$J$2:$J$964,'Исходные данные'!$D$2:$D$964,S$1,'Исходные данные'!$F$2:$F$964,$A6) -> 0 | U6: 1 | V6: 0 | W6: =SUMIFS('Исходные данные'!$I$2:$I$964,'Исходные данные'!$D$2:$D$964,W$1,'Исходные данные'!$F$2:$F$964,$A6) -> 1 | X6: =SUMIFS('Исходные данные'!$J$2:$J$964,'Исходные данные'!$D$2:$D$964,W$1,'Исходные данные'!$F$2:$F$964,$A6) -> 0 | Y6: 0 | Z6: 0 | AA6: =SUMIFS('Исходные данные'!$I$2:$I$964,'Исходные данные'!$D$2:$D$964,AA$1,'Исходные данные'!$F$2:$F$964,$A6) -> 0 | AB6: =SUMIFS('Исходные данные'!$J$2:$J$964,'Исходные данные'!$D$2:$D$964,AA$1,'Исходные данные'!$F$2:$F$964,$A6) -> 0 | AC6: 1 | AD6: 0 | AE6: =SUMIFS('Исходные данные'!$I$2:$I$964,'Исходные данные'!$D$2:$D$964,AE$1,'Исходные данные'!$F$2:$F$964,$A6) -> 1 | AF6: =SUMIFS('Исходные данные'!$J$2:$J$964,'Исходные данные'!$D$2:$D$964,AE$1,'Исходные данные'!$F$2:$F$964,$A6) -> 0 | AG6: 1 | AH6: 0 | AI6: =SUMIFS('Исходные данные'!$I$2:$I$964,'Исходные данные'!$D$2:$D$964,AI$1,'Исходные данные'!$F$2:$F$964,$A6) -> 0 | AJ6: =SUMIFS('Исходные данные'!$J$2:$J$964,'Исходные данные'!$D$2:$D$964,AI$1,'Исходные данные'!$F$2:$F$964,$A6) -> 0 | AK6: 1 | AL6: 0 | AM6: =SUMIFS('Исходные данные'!$I$2:$I$964,'Исходные данные'!$D$2:$D$964,AM$1,'Исходные данные'!$F$2:$F$964,$A6) -> 1 | AN6: =SUMIFS('Исходные данные'!$J$2:$J$964,'Исходные данные'!$D$2:$D$964,AM$1,'Исходные данные'!$F$2:$F$964,$A6) -> 0 | AO6: 1 | AP6: 0 | AQ6: =SUMIFS('Исходные данные'!$I$2:$I$964,'Исходные данные'!$D$2:$D$964,AQ$1,'Исходные данные'!$F$2:$F$964,$A6) -> 1 | AR6: =SUMIFS('Исходные данные'!$J$2:$J$964,'Исходные данные'!$D$2:$D$964,AQ$1,'Исходные данные'!$F$2:$F$964,$A6) -> 0 | AS6: 0 | AT6: 0 | AU6: =SUMIFS('Исходные данные'!$I$2:$I$964,'Исходные данные'!$D$2:$D$964,AU$1,'Исходные данные'!$F$2:$F$964,$A6) -> 0 | AV6: =SUMIFS('Исходные данные'!$J$2:$J$964,'Исходные данные'!$D$2:$D$964,AU$1,'Исходные данные'!$F$2:$F$964,$A6) -> 0 | AW6: 0 | AX6: 0 | AY6: =SUMIFS('Исходные данные'!$I$2:$I$964,'Исходные данные'!$D$2:$D$964,AY$1,'Исходные данные'!$F$2:$F$964,$A6) -> 0 | AZ6: =SUMIFS('Исходные данные'!$J$2:$J$964,'Исходные данные'!$D$2:$D$964,AY$1,'Исходные данные'!$F$2:$F$964,$A6) -> 0 | BA6: 0 | BB6: 0 | BC6: =SUMIFS('Исходные данные'!$I$2:$I$964,'Исходные данные'!$D$2:$D$964,BC$1,'Исходные данные'!$F$2:$F$964,$A6) -> 1 | BD6: =SUMIFS('Исходные данные'!$J$2:$J$964,'Исходные данные'!$D$2:$D$964,BC$1,'Исходные данные'!$F$2:$F$964,$A6) -> 0 | BE6: 0 | BF6: 0 | BG6: =SUMIFS('Исходные данные'!$I$2:$I$964,'Исходные данные'!$D$2:$D$964,BG$1,'Исходные данные'!$F$2:$F$964,$A6) -> 0 | BH6: =SUMIFS('Исходные данные'!$J$2:$J$964,'Исходные данные'!$D$2:$D$964,BG$1,'Исходные данные'!$F$2:$F$964,$A6) -> 0 | BI6: 5 | BJ6: 5 | BK6: =SUMIFS('Исходные данные'!$I$2:$I$964,'Исходные данные'!$D$2:$D$964,BK$1,'Исходные данные'!$F$2:$F$964,$A6) -> 4 | BL6: =SUMIFS('Исходные данные'!$J$2:$J$964,'Исходные данные'!$D$2:$D$964,BK$1,'Исходные данные'!$F$2:$F$964,$A6) -> 5 | BM6: 3 | BN6: 3 | BO6: =SUMIFS('Исходные данные'!$I$2:$I$964,'Исходные данные'!$D$2:$D$964,BO$1,'Исходные данные'!$F$2:$F$964,$A6) -> 3 | BP6: =SUMIFS('Исходные данные'!$J$2:$J$964,'Исходные данные'!$D$2:$D$964,BO$1,'Исходные данные'!$F$2:$F$964,$A6) -> 2 | BQ6: 0 | BR6: 0 | BS6: =SUMIFS('Исходные данные'!$I$2:$I$964,'Исходные данные'!$D$2:$D$964,BS$1,'Исходные данные'!$F$2:$F$964,$A6) -> 0 | BT6: =SUMIFS('Исходные данные'!$J$2:$J$964,'Исходные данные'!$D$2:$D$964,BS$1,'Исходные данные'!$F$2:$F$964,$A6) -> 0 | BU6: 0 | BV6: 0 | BW6: =SUMIFS('Исходные данные'!$I$2:$I$964,'Исходные данные'!$D$2:$D$964,BW$1,'Исходные данные'!$F$2:$F$964,$A6) -> 0 | BX6: =SUMIFS('Исходные данные'!$J$2:$J$964,'Исходные данные'!$D$2:$D$964,BW$1,'Исходные данные'!$F$2:$F$964,$A6) -> 0 | BY6: 0 | BZ6: 0 | CA6: =SUMIFS('Исходные данные'!$I$2:$I$964,'Исходные данные'!$D$2:$D$964,CA$1,'Исходные данные'!$F$2:$F$964,$A6) -> 0 | CB6: =SUMIFS('Исходные данные'!$J$2:$J$964,'Исходные данные'!$D$2:$D$964,CA$1,'Исходные данные'!$F$2:$F$964,$A6) -> 0 | CC6: 0 | CD6: 0 | CE6: =SUMIFS('Исходные данные'!$I$2:$I$964,'Исходные данные'!$D$2:$D$964,CE$1,'Исходные данные'!$F$2:$F$964,$A6) -> 0 | CF6: =SUMIFS('Исходные данные'!$J$2:$J$964,'Исходные данные'!$D$2:$D$964,CE$1,'Исходные данные'!$F$2:$F$964,$A6) -> 0 | CG6: 0 | CH6: 0 | CI6: =SUMIFS('Исходные данные'!$I$2:$I$964,'Исходные данные'!$D$2:$D$964,CI$1,'Исходные данные'!$F$2:$F$964,$A6) -> 0 | CJ6: =SUMIFS('Исходные данные'!$J$2:$J$964,'Исходные данные'!$D$2:$D$964,CI$1,'Исходные данные'!$F$2:$F$964,$A6) -> 0 | CK6: 0 | CL6: 0 | CM6: =SUMIFS('Исходные данные'!$I$2:$I$964,'Исходные данные'!$D$2:$D$964,CM$1,'Исходные данные'!$F$2:$F$964,$A6) -> 0 | CN6: =SUMIFS('Исходные данные'!$J$2:$J$964,'Исходные данные'!$D$2:$D$964,CM$1,'Исходные данные'!$F$2:$F$964,$A6) -> 0 | CO6: 0 | CP6: 0 | CQ6: =SUMIFS('Исходные данные'!$I$2:$I$964,'Исходные данные'!$D$2:$D$964,CQ$1,'Исходные данные'!$F$2:$F$964,$A6) -> 0 | CR6: =SUMIFS('Исходные данные'!$J$2:$J$964,'Исходные данные'!$D$2:$D$964,CQ$1,'Исходные данные'!$F$2:$F$964,$A6) -> 0 | CS6: 0 | CT6: 0 | CU6: =SUMIFS('Исходные данные'!$I$2:$I$964,'Исходные данные'!$D$2:$D$964,CU$1,'Исходные данные'!$F$2:$F$964,$A6) -> 0 | CV6: =SUMIFS('Исходные данные'!$J$2:$J$964,'Исходные данные'!$D$2:$D$964,CU$1,'Исходные данные'!$F$2:$F$964,$A6) -> 0 | CW6: 0 | CX6: 0 | CY6: =SUMIFS('Исходные данные'!$I$2:$I$964,'Исходные данные'!$D$2:$D$964,CY$1,'Исходные данные'!$F$2:$F$964,$A6) -> 0 | CZ6: =SUMIFS('Исходные данные'!$J$2:$J$964,'Исходные данные'!$D$2:$D$964,CY$1,'Исходные данные'!$F$2:$F$964,$A6) -> 0 | DA6: 0 | DB6: 0 | DC6: =SUMIFS('Исходные данные'!$I$2:$I$964,'Исходные данные'!$D$2:$D$964,DC$1,'Исходные данные'!$F$2:$F$964,$A6) -> 0 | DD6: =SUMIFS('Исходные данные'!$J$2:$J$964,'Исходные данные'!$D$2:$D$964,DC$1,'Исходные данные'!$F$2:$F$964,$A6) -> 0 | DE6: 0 | DF6: 0 | DG6: =SUMIFS('Исходные данные'!$I$2:$I$964,'Исходные данные'!$D$2:$D$964,DG$1,'Исходные данные'!$F$2:$F$964,$A6) -> 0 | DH6: =SUMIFS('Исходные данные'!$J$2:$J$964,'Исходные данные'!$D$2:$D$964,DG$1,'Исходные данные'!$F$2:$F$964,$A6) -> 0 | DI6: 0 | DJ6: 0 | DK6: =SUMIFS('Исходные данные'!$I$2:$I$964,'Исходные данные'!$D$2:$D$964,DK$1,'Исходные данные'!$F$2:$F$964,$A6) -> 0 | DL6: =SUMIFS('Исходные данные'!$J$2:$J$964,'Исходные данные'!$D$2:$D$964,DK$1,'Исходные данные'!$F$2:$F$964,$A6) -> 0 | DM6: 0 | DN6: 0 | DO6: =SUMIFS('Исходные данные'!$I$2:$I$964,'Исходные данные'!$D$2:$D$964,DO$1,'Исходные данные'!$F$2:$F$964,$A6) -> 0 | DP6: =SUMIFS('Исходные данные'!$J$2:$J$964,'Исходные данные'!$D$2:$D$964,DO$1,'Исходные данные'!$F$2:$F$964,$A6) -> 0 | DQ6: 0 | DR6: 0 | DS6: =SUMIFS('Исходные данные'!$I$2:$I$964,'Исходные данные'!$D$2:$D$964,DS$1,'Исходные данные'!$F$2:$F$964,$A6) -> 0 | DT6: =SUMIFS('Исходные данные'!$J$2:$J$964,'Исходные данные'!$D$2:$D$964,DS$1,'Исходные данные'!$F$2:$F$964,$A6) -> 0 | DU6: 0 | DV6: 0 | DW6: =SUMIFS('Исходные данные'!$I$2:$I$964,'Исходные данные'!$D$2:$D$964,DW$1,'Исходные данные'!$F$2:$F$964,$A6) -> 0 | DX6: =SUMIFS('Исходные данные'!$J$2:$J$964,'Исходные данные'!$D$2:$D$964,DW$1,'Исходные данные'!$F$2:$F$964,$A6) -> 0 | DY6: 0 | DZ6: 0 | EA6: =SUMIFS('Исходные данные'!$I$2:$I$964,'Исходные данные'!$D$2:$D$964,EA$1,'Исходные данные'!$F$2:$F$964,$A6) -> 0 | EB6: =SUMIFS('Исходные данные'!$J$2:$J$964,'Исходные данные'!$D$2:$D$964,EA$1,'Исходные данные'!$F$2:$F$964,$A6) -> 0 | EC6: 0 | ED6: 0 | EE6: =SUMIFS('Исходные данные'!$I$2:$I$964,'Исходные данные'!$D$2:$D$964,EE$1,'Исходные данные'!$F$2:$F$964,$A6) -> 0 | EF6: =SUMIFS('Исходные данные'!$J$2:$J$964,'Исходные данные'!$D$2:$D$964,EE$1,'Исходные данные'!$F$2:$F$964,$A6) -> 0 | EG6: 0 | EH6: 0 | EI6: =SUMIFS('Исходные данные'!$I$2:$I$964,'Исходные данные'!$D$2:$D$964,EI$1,'Исходные данные'!$F$2:$F$964,$A6) -> 0 | EJ6: =SUMIFS('Исходные данные'!$J$2:$J$964,'Исходные данные'!$D$2:$D$964,EI$1,'Исходные данные'!$F$2:$F$964,$A6) -> 0 | EK6: 0 | EL6: 0 | EM6: =SUMIFS('Исходные данные'!$I$2:$I$964,'Исходные данные'!$D$2:$D$964,EM$1,'Исходные данные'!$F$2:$F$964,$A6) -> 0 | EN6: =SUMIFS('Исходные данные'!$J$2:$J$964,'Исходные данные'!$D$2:$D$964,EM$1,'Исходные данные'!$F$2:$F$964,$A6) -> 0 | EO6: 0 | EP6: 0 | EQ6: =SUMIFS('Исходные данные'!$I$2:$I$964,'Исходные данные'!$D$2:$D$964,EQ$1,'Исходные данные'!$F$2:$F$964,$A6) -> 0 | ER6: =SUMIFS('Исходные данные'!$J$2:$J$964,'Исходные данные'!$D$2:$D$964,EQ$1,'Исходные данные'!$F$2:$F$964,$A6) -> 0 | ES6: 0 | ET6: 0 | EU6: =SUMIFS('Исходные данные'!$I$2:$I$964,'Исходные данные'!$D$2:$D$964,EU$1,'Исходные данные'!$F$2:$F$964,$A6) -> 0 | EV6: =SUMIFS('Исходные данные'!$J$2:$J$964,'Исходные данные'!$D$2:$D$964,EU$1,'Исходные данные'!$F$2:$F$964,$A6) -> 0 | EW6: 0 | EX6: 0 | EY6: =SUMIFS('Исходные данные'!$I$2:$I$964,'Исходные данные'!$D$2:$D$964,EY$1,'Исходные данные'!$F$2:$F$964,$A6) -> 0 | EZ6: =SUMIFS('Исходные данные'!$J$2:$J$964,'Исходные данные'!$D$2:$D$964,EY$1,'Исходные данные'!$F$2:$F$964,$A6) -> 0 | FA6: 0 | FB6: 0 | FC6: =SUMIFS('Исходные данные'!$I$2:$I$964,'Исходные данные'!$D$2:$D$964,FC$1,'Исходные данные'!$F$2:$F$964,$A6) -> 0 | FD6: =SUMIFS('Исходные данные'!$J$2:$J$964,'Исходные данные'!$D$2:$D$964,FC$1,'Исходные данные'!$F$2:$F$964,$A6) -> 0 | FE6: 0 | FF6: 0 | FG6: =SUMIFS('Исходные данные'!$I$2:$I$964,'Исходные данные'!$D$2:$D$964,FG$1,'Исходные данные'!$F$2:$F$964,$A6) -> 0 | FH6: =SUMIFS('Исходные данные'!$J$2:$J$964,'Исходные данные'!$D$2:$D$964,FG$1,'Исходные данные'!$F$2:$F$964,$A6) -> 0
A7: 22 | B7: Седельный тягач | C7: 23 | D7: =I7+J7+M7+N7+Q7+R7+U7+V7+Y7+Z7+AC7+AD7+AG7+AH7+AK7+AL7+AO7+AP7+AS7+AT7+AW7+AX7+BA7+BB7+BE7+BF7+BI7+BJ7+BM7+BN7+BQ7+BR7+BU7+BV7+BY7+BZ7+CC7+CD7+CG7+CH7+CK7+CL7+CO7+CP7+CS7+CT7+CW7+CX7+DA7+DB7+DE7+DF7+DI7+DJ7+DM7+DN7+DQ7+DR7+DU7+DV7+DY7+DZ7+EC7+ED7+EG7+EH7+EK7+EL7+EO7+EP7+ES7+ET7+EW7+EX7+FA7+FB7+FE7+FF7 -> 23 | E7: =G7+H7 -> 20 | F7: =E7-C7 -> -3 | G7: =K7+O7+S7+W7+AA7+AE7+AI7+AM7+AQ7+AU7+AY7+BC7+BG7+BK7+BO7+BS7+BW7+CA7+CE7+CI7+CM7+CQ7+CU7+CY7+DC7+DG7+DK7+DO7+DS7+DW7+EA7+EE7+EI7+EM7+EQ7+EU7+EY7+FC7+FG7 -> 13 | H7: =L7+P7+T7+X7+AB7+AF7+AJ7+AN7+AR7+AV7+AZ7+BD7+BH7+BL7+BP7+BT7+BX7+CB7+CF7+CJ7+CN7+CR7+CV7+CZ7+DD7+DH7+DL7+DP7+DT7+DX7+EB7+EF7+EJ7+EN7+ER7+EV7+EZ7+FD7+FH7 -> 7 | I7: 1 | J7: 0 | K7: =SUMIFS('Исходные данные'!$I$2:$I$964,'Исходные данные'!$D$2:$D$964,K$1,'Исходные данные'!$F$2:$F$964,$A7) -> 0 | L7: =SUMIFS('Исходные данные'!$J$2:$J$964,'Исходные данные'!$D$2:$D$964,K$1,'Исходные данные'!$F$2:$F$964,$A7) -> 0 | M7: 1 | N7: 0 | O7: =SUMIFS('Исходные данные'!$I$2:$I$964,'Исходные данные'!$D$2:$D$964,O$1,'Исходные данные'!$F$2:$F$964,$A7) -> 1 | P7: =SUMIFS('Исходные данные'!$J$2:$J$964,'Исходные данные'!$D$2:$D$964,O$1,'Исходные данные'!$F$2:$F$964,$A7) -> 0 | Q7: 1 | R7: 0 | S7: =SUMIFS('Исходные данные'!$I$2:$I$964,'Исходные данные'!$D$2:$D$964,S$1,'Исходные данные'!$F$2:$F$964,$A7) -> 1 | T7: =SUMIFS('Исходные данные'!$J$2:$J$964,'Исходные данные'!$D$2:$D$964,S$1,'Исходные данные'!$F$2:$F$964,$A7) -> 0 | U7: 0 | V7: 0 | W7: =SUMIFS('Исходные данные'!$I$2:$I$964,'Исходные данные'!$D$2:$D$964,W$1,'Исходные данные'!$F$2:$F$964,$A7) -> 0 | X7: =SUMIFS('Исходные данные'!$J$2:$J$964,'Исходные данные'!$D$2:$D$964,W$1,'Исходные данные'!$F$2:$F$964,$A7) -> 0 | Y7: 0 | Z7: 0 | AA7: =SUMIFS('Исходные данные'!$I$2:$I$964,'Исходные данные'!$D$2:$D$964,AA$1,'Исходные данные'!$F$2:$F$964,$A7) -> 0 | AB7: =SUMIFS('Исходные данные'!$J$2:$J$964,'Исходные данные'!$D$2:$D$964,AA$1,'Исходные данные'!$F$2:$F$964,$A7) -> 0 | AC7: 1 | AD7: 0 | AE7: =SUMIFS('Исходные данные'!$I$2:$I$964,'Исходные данные'!$D$2:$D$964,AE$1,'Исходные данные'!$F$2:$F$964,$A7) -> 1 | AF7: =SUMIFS('Исходные данные'!$J$2:$J$964,'Исходные данные'!$D$2:$D$964,AE$1,'Исходные данные'!$F$2:$F$964,$A7) -> 0 | AG7: 0 | AH7: 0 | AI7: =SUMIFS('Исходные данные'!$I$2:$I$964,'Исходные данные'!$D$2:$D$964,AI$1,'Исходные данные'!$F$2:$F$964,$A7) -> 0 | AJ7: =SUMIFS('Исходные данные'!$J$2:$J$964,'Исходные данные'!$D$2:$D$964,AI$1,'Исходные данные'!$F$2:$F$964,$A7) -> 0 | AK7: 0 | AL7: 0 | AM7: =SUMIFS('Исходные данные'!$I$2:$I$964,'Исходные данные'!$D$2:$D$964,AM$1,'Исходные данные'!$F$2:$F$964,$A7) -> 0 | AN7: =SUMIFS('Исходные данные'!$J$2:$J$964,'Исходные данные'!$D$2:$D$964,AM$1,'Исходные данные'!$F$2:$F$964,$A7) -> 0 | AO7: 1 | AP7: 0 | AQ7: =SUMIFS('Исходные данные'!$I$2:$I$964,'Исходные данные'!$D$2:$D$964,AQ$1,'Исходные данные'!$F$2:$F$964,$A7) -> 0 | AR7: =SUMIFS('Исходные данные'!$J$2:$J$964,'Исходные данные'!$D$2:$D$964,AQ$1,'Исходные данные'!$F$2:$F$964,$A7) -> 0 | AS7: 0 | AT7: 0 | AU7: =SUMIFS('Исходные данные'!$I$2:$I$964,'Исходные данные'!$D$2:$D$964,AU$1,'Исходные данные'!$F$2:$F$964,$A7) -> 0 | AV7: =SUMIFS('Исходные данные'!$J$2:$J$964,'Исходные данные'!$D$2:$D$964,AU$1,'Исходные данные'!$F$2:$F$964,$A7) -> 0 | AW7: 0 | AX7: 0 | AY7: =SUMIFS('Исходные данные'!$I$2:$I$964,'Исходные данные'!$D$2:$D$964,AY$1,'Исходные данные'!$F$2:$F$964,$A7) -> 0 | AZ7: =SUMIFS('Исходные данные'!$J$2:$J$964,'Исходные данные'!$D$2:$D$964,AY$1,'Исходные данные'!$F$2:$F$964,$A7) -> 0 | BA7: 0 | BB7: 0 | BC7: =SUMIFS('Исходные данные'!$I$2:$I$964,'Исходные данные'!$D$2:$D$964,BC$1,'Исходные данные'!$F$2:$F$964,$A7) -> 0 | BD7: =SUMIFS('Исходные данные'!$J$2:$J$964,'Исходные данные'!$D$2:$D$964,BC$1,'Исходные данные'!$F$2:$F$964,$A7) -> 0 | BE7: 3 | BF7: 0 | BG7: =SUMIFS('Исходные данные'!$I$2:$I$964,'Исходные данные'!$D$2:$D$964,BG$1,'Исходные данные'!$F$2:$F$964,$A7) -> 2 | BH7: =SUMIFS('Исходные данные'!$J$2:$J$964,'Исходные данные'!$D$2:$D$964,BG$1,'Исходные данные'!$F$2:$F$964,$A7) -> 0 | BI7: 4 | BJ7: 4 | BK7: =SUMIFS('Исходные данные'!$I$2:$I$964,'Исходные данные'!$D$2:$D$964,BK$1,'Исходные данные'!$F$2:$F$964,$A7) -> 4 | BL7: =SUMIFS('Исходные данные'!$J$2:$J$964,'Исходные данные'!$D$2:$D$964,BK$1,'Исходные данные'!$F$2:$F$964,$A7) -> 4 | BM7: 4 | BN7: 3 | BO7: =SUMIFS('Исходные данные'!$I$2:$I$964,'Исходные данные'!$D$2:$D$964,BO$1,'Исходные данные'!$F$2:$F$964,$A7) -> 4 | BP7: =SUMIFS('Исходные данные'!$J$2:$J$964,'Исходные данные'!$D$2:$D$964,BO$1,'Исходные данные'!$F$2:$F$964,$A7) -> 3 | BQ7: 0 | BR7: 0 | BS7: =SUMIFS('Исходные данные'!$I$2:$I$964,'Исходные данные'!$D$2:$D$964,BS$1,'Исходные данные'!$F$2:$F$964,$A7) -> 0 | BT7: =SUMIFS('Исходные данные'!$J$2:$J$964,'Исходные данные'!$D$2:$D$964,BS$1,'Исходные данные'!$F$2:$F$964,$A7) -> 0 | BU7: 0 | BV7: 0 | BW7: =SUMIFS('Исходные данные'!$I$2:$I$964,'Исходные данные'!$D$2:$D$964,BW$1,'Исходные данные'!$F$2:$F$964,$A7) -> 0 | BX7: =SUMIFS('Исходные данные'!$J$2:$J$964,'Исходные данные'!$D$2:$D$964,BW$1,'Исходные данные'!$F$2:$F$964,$A7) -> 0 | BY7: 0 | BZ7: 0 | CA7: =SUMIFS('Исходные данные'!$I$2:$I$964,'Исходные данные'!$D$2:$D$964,CA$1,'Исходные данные'!$F$2:$F$964,$A7) -> 0 | CB7: =SUMIFS('Исходные данные'!$J$2:$J$964,'Исходные данные'!$D$2:$D$964,CA$1,'Исходные данные'!$F$2:$F$964,$A7) -> 0 | CC7: 0 | CD7: 0 | CE7: =SUMIFS('Исходные данные'!$I$2:$I$964,'Исходные данные'!$D$2:$D$964,CE$1,'Исходные данные'!$F$2:$F$964,$A7) -> 0 | CF7: =SUMIFS('Исходные данные'!$J$2:$J$964,'Исходные данные'!$D$2:$D$964,CE$1,'Исходные данные'!$F$2:$F$964,$A7) -> 0 | CG7: 0 | CH7: 0 | CI7: =SUMIFS('Исходные данные'!$I$2:$I$964,'Исходные данные'!$D$2:$D$964,CI$1,'Исходные данные'!$F$2:$F$964,$A7) -> 0 | CJ7: =SUMIFS('Исходные данные'!$J$2:$J$964,'Исходные данные'!$D$2:$D$964,CI$1,'Исходные данные'!$F$2:$F$964,$A7) -> 0 | CK7: 0 | CL7: 0 | CM7: =SUMIFS('Исходные данные'!$I$2:$I$964,'Исходные данные'!$D$2:$D$964,CM$1,'Исходные данные'!$F$2:$F$964,$A7) -> 0 | CN7: =SUMIFS('Исходные данные'!$J$2:$J$964,'Исходные данные'!$D$2:$D$964,CM$1,'Исходные данные'!$F$2:$F$964,$A7) -> 0 | CO7: 0 | CP7: 0 | CQ7: =SUMIFS('Исходные данные'!$I$2:$I$964,'Исходные данные'!$D$2:$D$964,CQ$1,'Исходные данные'!$F$2:$F$964,$A7) -> 0 | CR7: =SUMIFS('Исходные данные'!$J$2:$J$964,'Исходные данные'!$D$2:$D$964,CQ$1,'Исходные данные'!$F$2:$F$964,$A7) -> 0 | CS7: 0 | CT7: 0 | CU7: =SUMIFS('Исходные данные'!$I$2:$I$964,'Исходные данные'!$D$2:$D$964,CU$1,'Исходные данные'!$F$2:$F$964,$A7) -> 0 | CV7: =SUMIFS('Исходные данные'!$J$2:$J$964,'Исходные данные'!$D$2:$D$964,CU$1,'Исходные данные'!$F$2:$F$964,$A7) -> 0 | CW7: 0 | CX7: 0 | CY7: =SUMIFS('Исходные данные'!$I$2:$I$964,'Исходные данные'!$D$2:$D$964,CY$1,'Исходные данные'!$F$2:$F$964,$A7) -> 0 | CZ7: =SUMIFS('Исходные данные'!$J$2:$J$964,'Исходные данные'!$D$2:$D$964,CY$1,'Исходные данные'!$F$2:$F$964,$A7) -> 0 | DA7: 0 | DB7: 0 | DC7: =SUMIFS('Исходные данные'!$I$2:$I$964,'Исходные данные'!$D$2:$D$964,DC$1,'Исходные данные'!$F$2:$F$964,$A7) -> 0 | DD7: =SUMIFS('Исходные данные'!$J$2:$J$964,'Исходные данные'!$D$2:$D$964,DC$1,'Исходные данные'!$F$2:$F$964,$A7) -> 0 | DE7: 0 | DF7: 0 | DG7: =SUMIFS('Исходные данные'!$I$2:$I$964,'Исходные данные'!$D$2:$D$964,DG$1,'Исходные данные'!$F$2:$F$964,$A7) -> 0 | DH7: =SUMIFS('Исходные данные'!$J$2:$J$964,'Исходные данные'!$D$2:$D$964,DG$1,'Исходные данные'!$F$2:$F$964,$A7) -> 0 | DI7: 0 | DJ7: 0 | DK7: =SUMIFS('Исходные данные'!$I$2:$I$964,'Исходные данные'!$D$2:$D$964,DK$1,'Исходные данные'!$F$2:$F$964,$A7) -> 0 | DL7: =SUMIFS('Исходные данные'!$J$2:$J$964,'Исходные данные'!$D$2:$D$964,DK$1,'Исходные данные'!$F$2:$F$964,$A7) -> 0 | DM7: 0 | DN7: 0 | DO7: =SUMIFS('Исходные данные'!$I$2:$I$964,'Исходные данные'!$D$2:$D$964,DO$1,'Исходные данные'!$F$2:$F$964,$A7) -> 0 | DP7: =SUMIFS('Исходные данные'!$J$2:$J$964,'Исходные данные'!$D$2:$D$964,DO$1,'Исходные данные'!$F$2:$F$964,$A7) -> 0 | DQ7: 0 | DR7: 0 | DS7: =SUMIFS('Исходные данные'!$I$2:$I$964,'Исходные данные'!$D$2:$D$964,DS$1,'Исходные данные'!$F$2:$F$964,$A7) -> 0 | DT7: =SUMIFS('Исходные данные'!$J$2:$J$964,'Исходные данные'!$D$2:$D$964,DS$1,'Исходные данные'!$F$2:$F$964,$A7) -> 0 | DU7: 0 | DV7: 0 | DW7: =SUMIFS('Исходные данные'!$I$2:$I$964,'Исходные данные'!$D$2:$D$964,DW$1,'Исходные данные'!$F$2:$F$964,$A7) -> 0 | DX7: =SUMIFS('Исходные данные'!$J$2:$J$964,'Исходные данные'!$D$2:$D$964,DW$1,'Исходные данные'!$F$2:$F$964,$A7) -> 0 | DY7: 0 | DZ7: 0 | EA7: =SUMIFS('Исходные данные'!$I$2:$I$964,'Исходные данные'!$D$2:$D$964,EA$1,'Исходные данные'!$F$2:$F$964,$A7) -> 0 | EB7: =SUMIFS('Исходные данные'!$J$2:$J$964,'Исходные данные'!$D$2:$D$964,EA$1,'Исходные данные'!$F$2:$F$964,$A7) -> 0 | EC7: 0 | ED7: 0 | EE7: =SUMIFS('Исходные данные'!$I$2:$I$964,'Исходные данные'!$D$2:$D$964,EE$1,'Исходные данные'!$F$2:$F$964,$A7) -> 0 | EF7: =SUMIFS('Исходные данные'!$J$2:$J$964,'Исходные данные'!$D$2:$D$964,EE$1,'Исходные данные'!$F$2:$F$964,$A7) -> 0 | EG7: 0 | EH7: 0 | EI7: =SUMIFS('Исходные данные'!$I$2:$I$964,'Исходные данные'!$D$2:$D$964,EI$1,'Исходные данные'!$F$2:$F$964,$A7) -> 0 | EJ7: =SUMIFS('Исходные данные'!$J$2:$J$964,'Исходные данные'!$D$2:$D$964,EI$1,'Исходные данные'!$F$2:$F$964,$A7) -> 0 | EK7: 0 | EL7: 0 | EM7: =SUMIFS('Исходные данные'!$I$2:$I$964,'Исходные данные'!$D$2:$D$964,EM$1,'Исходные данные'!$F$2:$F$964,$A7) -> 0 | EN7: =SUMIFS('Исходные данные'!$J$2:$J$964,'Исходные данные'!$D$2:$D$964,EM$1,'Исходные данные'!$F$2:$F$964,$A7) -> 0 | EO7: 0 | EP7: 0 | EQ7: =SUMIFS('Исходные данные'!$I$2:$I$964,'Исходные данные'!$D$2:$D$964,EQ$1,'Исходные данные'!$F$2:$F$964,$A7) -> 0 | ER7: =SUMIFS('Исходные данные'!$J$2:$J$964,'Исходные данные'!$D$2:$D$964,EQ$1,'Исходные данные'!$F$2:$F$964,$A7) -> 0 | ES7: 0 | ET7: 0 | EU7: =SUMIFS('Исходные данные'!$I$2:$I$964,'Исходные данные'!$D$2:$D$964,EU$1,'Исходные данные'!$F$2:$F$964,$A7) -> 0 | EV7: =SUMIFS('Исходные данные'!$J$2:$J$964,'Исходные данные'!$D$2:$D$964,EU$1,'Исходные данные'!$F$2:$F$964,$A7) -> 0 | EW7: 0 | EX7: 0 | EY7: =SUMIFS('Исходные данные'!$I$2:$I$964,'Исходные данные'!$D$2:$D$964,EY$1,'Исходные данные'!$F$2:$F$964,$A7) -> 0 | EZ7: =SUMIFS('Исходные данные'!$J$2:$J$964,'Исходные данные'!$D$2:$D$964,EY$1,'Исходные данные'!$F$2:$F$964,$A7) -> 0 | FA7: 0 | FB7: 0 | FC7: =SUMIFS('Исходные данные'!$I$2:$I$964,'Исходные данные'!$D$2:$D$964,FC$1,'Исходные данные'!$F$2:$F$964,$A7) -> 0 | FD7: =SUMIFS('Исходные данные'!$J$2:$J$964,'Исходные данные'!$D$2:$D$964,FC$1,'Исходные данные'!$F$2:$F$964,$A7) -> 0 | FE7: 0 | FF7: 0 | FG7: =SUMIFS('Исходные данные'!$I$2:$I$964,'Исходные данные'!$D$2:$D$964,FG$1,'Исходные данные'!$F$2:$F$964,$A7) -> 0 | FH7: =SUMIFS('Исходные данные'!$J$2:$J$964,'Исходные данные'!$D$2:$D$964,FG$1,'Исходные данные'!$F$2:$F$964,$A7) -> 0
